Workbook

Sheet Read me
B2: Resources and prep, Years 7 and 8, Weeks 1 to 10
B3: All weeks: every resource for every Year 7 and Year 8 lesson on one sheet, grouped by kind (printing, card and stationery, equipment, food and consumables, things to make). Filter by week, year or group. Pink cells are the ones to check.
B4: Prep by week: every prep task with when it happens, how long it takes and who could do it, and a week-by-week total so you can see where the load falls.
B5: Cut the prep: the options for reducing the prep, with the minutes each one saves.
B6: Quantities are for one class of up to 24 students in 6 groups. Type the number of classes and the Year 7 freezer plan in the yellow cells at the top of the All weeks sheet. The "Got it" column is for your ticks.
B7: Checked against every lesson file (lesson plan, kit card, printables), the designed printables, the Teacher Guide prep calendar and the Year 8 Case Bible, and compared with the full requisition workbook. Items already made in an earlier week are listed with "Already have" and are not counted again in the printing totals.
B9: Items missing from the full requisition: 6 rows marked "No: add" on the All weeks sheet.

Sheet All weeks
A1: Years 7 and 8, Weeks 1 to 10: resources needed
A2: Every lesson on one sheet. Quantities are for one class of up to 24 students in 6 groups. Change the yellow cells; totals update. Use the filter arrows to show one week, one year or one group.
A3: Year 7 classes | C3: 1 | D3: Items per student, per group or per class are multiplied by the classes in that year. | J3: Printing, all weeks (sheets)
A4: Year 8 classes | C4: 1 | J4: A4 paper | L4: =SUMIFS($L$9:$L$721,$J$9:$J$721,J4) -> 1987 | M4: A4 card | O4: =SUMIFS($L$9:$L$721,$J$9:$J$721,M4) -> 176
A5: Year 7 freezer plan | C5: A and B | D5: A (freezer), B (no freezer) or "A and B". Items for the plan not chosen count as 0. Decide by Week 4. | J5: A3 paper | L5: =SUMIFS($L$9:$L$721,$J$9:$J$721,J5) -> 36 | M5: A4 90 gsm (booklet) | O5: =SUMIFS($L$9:$L$721,$J$9:$J$721,M5) -> 196
J6: A5 paper | L6: =SUMIFS($L$9:$L$721,$J$9:$J$721,J6) -> 160
A8: Week | B8: Year | C8: Group | D8: Item | E8: Quantity (one class) | F8: Unit or how to print | G8: Per | H8: Plan | I8: Total for your classes | J8: Paper or card | K8: Sheets per copy | L8: Sheets in total | M8: What it is for | N8: Optional? | O8: Already have (from an earlier week) | P8: On the requisition? | Q8: Check | R8: Got it
A9: 1 | B9: Year 7 | C9: Printing (paper copies) | D9: Skills Check paper, Year 7 (Week 1 baseline) | E9: 24 | F9: copies; 5 A4 portrait pages, double-sided (3 sheets each, last side blank) | G9: per student | I9: =IF(E9="","",IF(OR(AND(H9="Plan A",$C$5="B"),AND(H9="Plan B",$C$5="A")),0,IF(OR(G9="per student",G9="per group",G9="per class"),E9*IF(B9="Year 7",$C$3,$C$4),E9))) -> 24 | J9: A4 paper | K9: 3 | L9: =IF(OR(K9="",O9<>"",I9=""),"",ROUNDUP(I9*K9,0)) -> 72 | M9: 15-minute baseline skills check done alone in silence; marked out of 20, entered in the tracker and filed in the class assessment folder, not returned until after Week 10. | P9: No: paper printing | Q9: Skills_Check_Y7.md Section 1 says 'two sides of A4', but the designed paper is 5 pages ('Page 1 of 5' to 'Page 5 of 5'), so 3 sheets double-sided (or 5 single-sided). Decide whether to staple (no stapler is named). No spares stated. Print from the master that Week 10 will use again and do not change it in between.
A10: 1 | B10: Year 7 | C10: Printing (paper copies) | D10: Interest survey | E10: 24 | F10: copies; half-A4, 2 per A4 sheet, single-sided, cut in half (12 sheets) | G10: per student | I10: =IF(E10="","",IF(OR(AND(H10="Plan A",$C$5="B"),AND(H10="Plan B",$C$5="A")),0,IF(OR(G10="per student",G10="per group",G10="per class"),E10*IF(B10="Year 7",$C$3,$C$4),E10))) -> 24 | J10: A4 paper | K10: 0.5 | L10: =IF(OR(K10="",O10<>"",I10=""),"",ROUNDUP(I10*K10,0)) -> 12 | M10: 3-minute Week 1 baseline survey straight after the skills check; six scores per student go into the tracker. | P10: No: paper printing | Q10: Fresh copies are needed again in Week 10. No spares stated.
A11: 1 | B11: Year 7 | C11: Printing (paper copies) | D11: Student worksheet, What do scientists do? | E11: 24 | F11: copies; 4 A4 portrait pages, double-sided (2 sheets each) | G11: per student | I11: =IF(E11="","",IF(OR(AND(H11="Plan A",$C$5="B"),AND(H11="Plan B",$C$5="A")),0,IF(OR(G11="per student",G11="per group",G11="per class"),E11*IF(B11="Year 7",$C$3,$C$4),E11))) -> 24 | J11: A4 paper | K11: 2 | L11: =IF(OR(K11="",O11<>"",I11=""),"",ROUNDUP(I11*K11,0)) -> 48 | M11: Core A observation or inference sort, Core B footprint table, Stretch, Challenge, My thinking box, fold-under word bank and the exit ticket strip. | P11: No: paper printing | Q11: The exit ticket strip at the foot of page 4 sits below a cut line; printed double-sided, cutting it off also cuts the foot of page 3 (the My thinking box). Check the layout before printing. Print only from the design rebuilt after the language pass and discard any earlier copies. No spares stated.
A12: 1 | B12: Year 7 | C12: Printing (paper copies) | D12: Skills Check mark scheme (teacher copy) | E12: 1 | F12: teacher copy; 2 A4 pages (single-sided here; sides not stated) | G12: per once | I12: =IF(E12="","",IF(OR(AND(H12="Plan A",$C$5="B"),AND(H12="Plan B",$C$5="A")),0,IF(OR(G12="per student",G12="per group",G12="per class"),E12*IF(B12="Year 7",$C$3,$C$4),E12))) -> 1 | J12: A4 paper | K12: 2 | L12: =IF(OR(K12="",O12<>"",I12=""),"",ROUNDUP(I12*K12,0)) -> 2 | M12: Marking the skills checks out of 20 within Week 1; kept for Week 10. | P12: No: paper printing | Q12: Single- or double-sided is not stated (1 sheet if double-sided). One copy serves every class.
A13: 1 | B13: Year 7 | C13: Printing (paper copies) | D13: Kit card, Y7 Week 1 (teacher copy) | E13: 1 | F13: teacher copy; half-A4 (A5), single-sided, printed on A4 | G13: per once | I13: =IF(E13="","",IF(OR(AND(H13="Plan A",$C$5="B"),AND(H13="Plan B",$C$5="A")),0,IF(OR(G13="per student",G13="per group",G13="per class"),E13*IF(B13="Year 7",$C$3,$C$4),E13))) -> 1 | J13: A4 paper | K13: 1 | L13: =IF(OR(K13="",O13<>"",I13=""),"",ROUNDUP(I13*K13,0)) -> 1 | M13: Kit list per group and per student, teacher prep with times, hazards and clean-up. | P13: No: paper printing | Q13: It still says 'Group role cards: 1 set of 5'; the role card set now has 6 cards.
A14: 1 | B14: Year 7 | C14: Printing (paper copies) | D14: Group role cards with duties (including Language buddy) | E14: 6 | F14: sets; 1 A4 sheet per set (6 business-card size cards, 85 mm by 55 mm, with cut lines), single-sided | G14: per group | I14: =IF(E14="","",IF(OR(AND(H14="Plan A",$C$5="B"),AND(H14="Plan B",$C$5="A")),0,IF(OR(G14="per student",G14="per group",G14="per class"),E14*IF(B14="Year 7",$C$3,$C$4),E14))) -> 6 | J14: A4 paper | K14: 1 | L14: =IF(OR(K14="",O14<>"",I14=""),"",ROUNDUP(I14*K14,0)) -> 6 | M14: One set per table: Lead Scientist, Measurer, Recorder, Safety Officer, Reporter and Language buddy, duties in both languages; laminated, cut and kept all term. | P14: No: paper printing | Q14: The Week 1 kit card says '1 set of 5'; the language support pack, the design and the requisition use 6 cards per set. Paper or card is not stated. Lamination is the A4 pouch row.
A15: 1 | B15: Year 7 | C15: Printing (paper copies) | D15: Classroom language card (two-sided) | E15: 30 | F15: cards; A5 landscape, double-sided (1 per student plus 6 spares) | G15: per student | I15: =IF(E15="","",IF(OR(AND(H15="Plan A",$C$5="B"),AND(H15="Plan B",$C$5="A")),0,IF(OR(G15="per student",G15="per group",G15="per class"),E15*IF(B15="Year 7",$C$3,$C$4),E15))) -> 30 | J15: A5 paper | K15: 1 | L15: =IF(OR(K15="",O15<>"",I15=""),"",ROUNDUP(I15*K15,0)) -> 30 | M15: Side A teacher routine phrases, side B student help phrases; laminated, handed out with a two-minute walk-through and kept all term. | P15: No: paper printing | Q15: Paper to print on is not stated (30 A5 sheets, or 15 A4 sheets cut in half). The Week 1 timeline has no slot for the walk-through. Lamination is the A5 pouch row.
A16: 1 | B16: Year 7 | C16: Printing (paper copies) | D16: Language support A3 posters: Instruction words key, Classroom language (side B), Think in any language | E16: 3 | F16: posters; 1 of each, A3, single-sided | G16: per room | I16: =IF(E16="","",IF(OR(AND(H16="Plan A",$C$5="B"),AND(H16="Plan B",$C$5="A")),0,IF(OR(G16="per student",G16="per group",G16="per class"),E16*IF(B16="Year 7",$C$3,$C$4),E16))) -> 3 | J16: A3 paper | K16: 1 | L16: =IF(OR(K16="",O16<>"",I16=""),"",ROUNDUP(I16*K16,0)) -> 3 | M16: Wall posters kept up all term. | P16: Yes | Q16: No source says to laminate them. Covered by the requisition's 3 sheets of A3 paper.
A17: 1 | B17: Year 7 | C17: Printing (paper copies) | D17: Sentence frame bank poster, Ice Engineers | E17: 1 | F17: poster; A4 portrait, single-sided | G17: per room | I17: =IF(E17="","",IF(OR(AND(H17="Plan A",$C$5="B"),AND(H17="Plan B",$C$5="A")),0,IF(OR(G17="per student",G17="per group",G17="per class"),E17*IF(B17="Year 7",$C$3,$C$4),E17))) -> 1 | J17: A4 paper | K17: 1 | L17: =IF(OR(K17="",O17<>"",I17=""),"",ROUNDUP(I17*K17,0)) -> 1 | M17: Wall poster of every Year 7 frame with its Chinese and an example; Week 1 uses 'I observe ___.' and 'I infer ___ because ___.' | P17: No: paper printing | Q17: Teacher Guide Section 8 says print before Week 1; the Week 1 lesson file does not mention it.
A18: 1 | B18: Year 7 | C18: Printing (paper copies) | D18: Sentence frame bank cards, Ice Engineers | E18: 6 | F18: sets; 16 A6 cards per set, 4 cards per A4 sheet with cut lines (4 sheets per set) | G18: per group | I18: =IF(E18="","",IF(OR(AND(H18="Plan A",$C$5="B"),AND(H18="Plan B",$C$5="A")),0,IF(OR(G18="per student",G18="per group",G18="per class"),E18*IF(B18="Year 7",$C$3,$C$4),E18))) -> 6 | J18: A4 paper | K18: 4 | L18: =IF(OR(K18="",O18<>"",I18=""),"",ROUNDUP(I18*K18,0)) -> 24 | M18: One set per table so groups rehearse reports in English with the frame. | P18: No: paper printing | Q18: Paper or card is not stated (24 A4 sheets of card if card). The Week 1 lesson file does not mention them.
A19: 1 | B19: Year 7 | C19: Printing (paper copies) | D19: My Science Dictionary, Year 7 | E19: 28 | F19: booklets; A5 saddle-stitched, 24 pages (6 A4 sheets folded and stapled twice), 90 gsm (1 per student plus 4 spares) | G19: per student | I19: =IF(E19="","",IF(OR(AND(H19="Plan A",$C$5="B"),AND(H19="Plan B",$C$5="A")),0,IF(OR(G19="per student",G19="per group",G19="per class"),E19*IF(B19="Year 7",$C$3,$C$4),E19))) -> 28 | J19: Booklet (reprographics) | K19: 6 | L19: =IF(OR(K19="",O19<>"",I19=""),"",ROUNDUP(I19*K19,0)) -> 168 | M19: Handed out with the logbook; name and class on the cover; open in every lesson but closed and put away during the skills check; 4 spares kept with the logbook spares. | P19: Yes, see note | Q19: Goes to 28 pages (7 sheets each) if the entries need more room; the requisition row gives neither the page count nor 90 gsm. The dictionary file says hand out in Week 1 with the logbook; the language pack allows Week 1 or the next lesson.
A20: 1 | B20: Year 7 | C20: Printing (paper copies) | D20: Scientist's Logbook, Year 7 | E20: 24 | F20: booklets; A5, one page per week (page count not stated) | G20: per student | I20: =IF(E20="","",IF(OR(AND(H20="Plan A",$C$5="B"),AND(H20="Plan B",$C$5="A")),0,IF(OR(G20="per student",G20="per group",G20="per class"),E20*IF(B20="Year 7",$C$3,$C$4),E20))) -> 24 | J20: Booklet (reprographics) | L20: =IF(OR(K20="",O20<>"",I20=""),"",ROUNDUP(I20*K20,0)) | M20: First page written in Think and Reflect ('What I did', and 'New words' if time); collected into the class box at the end of every lesson. | P20: Yes | Q20: Page count, cover and binding are not stated; only one A5 page is designed. The dictionary file mentions 'logbook spares' but gives no number.
A21: 1 | B21: Year 7 | C21: Card, laminating and stationery | D21: Footprint puzzle stage cards (Stage 1, 2, 3) | E21: 6 | F21: sets of 3 A4 landscape cards; Cards 1 and 2 single-sided, Card 3 with the teacher note printed on the back | G21: per group | I21: =IF(E21="","",IF(OR(AND(H21="Plan A",$C$5="B"),AND(H21="Plan B",$C$5="A")),0,IF(OR(G21="per student",G21="per group",G21="per class"),E21*IF(B21="Year 7",$C$3,$C$4),E21))) -> 6 | J21: A4 card | K21: 3 | L21: =IF(OR(K21="",O21<>"",I21=""),"",ROUNDUP(I21*K21,0)) -> 18 | M21: Reveal cards for the 10-minute footprint puzzle, handed out stage by stage, returned in their envelopes and reused. | P21: Yes, see note | Q21: The requisition row (white card, 18 sheets) says single-sided, but the 6 copies of Card 3 carry the teacher note on the back. Card or laminated paper is allowed. Section 6a says 6 sets per class; as the cards come back to the teacher, one set might serve every class if lessons do not overlap (decide).
A22: 1 | B22: Year 7 | C22: Card, laminating and stationery | D22: Laminating pouches, A4, for puzzle cards (only if laminating paper instead of card) | E22: 18 | F22: pouches, A4 | G22: per group | I22: =IF(E22="","",IF(OR(AND(H22="Plan A",$C$5="B"),AND(H22="Plan B",$C$5="A")),0,IF(OR(G22="per student",G22="per group",G22="per class"),E22*IF(B22="Year 7",$C$3,$C$4),E22))) -> 18 | L22: =IF(OR(K22="",O22<>"",I22=""),"",ROUNDUP(I22*K22,0)) | M22: Alternative to card: print the 18 puzzle cards on paper and laminate them. | N22: Optional | P22: Yes, see note | Q22: Mentioned only inside the requisition's white card note, not counted as a row. Would also need 18 sheets of A4 paper in place of card.
A23: 1 | B23: Year 7 | C23: Card, laminating and stationery | D23: Laminating pouches, A4, for role cards | E23: 6 | F23: pouches, A4 | G23: per group | I23: =IF(E23="","",IF(OR(AND(H23="Plan A",$C$5="B"),AND(H23="Plan B",$C$5="A")),0,IF(OR(G23="per student",G23="per group",G23="per class"),E23*IF(B23="Year 7",$C$3,$C$4),E23))) -> 6 | L23: =IF(OR(K23="",O23<>"",I23=""),"",ROUNDUP(I23*K23,0)) | M23: Laminate the 6 role card sheets before cutting them into cards. | P23: Yes
A24: 1 | B24: Year 7 | C24: Card, laminating and stationery | D24: Laminating pouches, A5, for classroom language cards | E24: 30 | F24: pouches, A5 | G24: per student | I24: =IF(E24="","",IF(OR(AND(H24="Plan A",$C$5="B"),AND(H24="Plan B",$C$5="A")),0,IF(OR(G24="per student",G24="per group",G24="per class"),E24*IF(B24="Year 7",$C$3,$C$4),E24))) -> 30 | L24: =IF(OR(K24="",O24<>"",I24=""),"",ROUNDUP(I24*K24,0)) | M24: Laminate the 30 two-sided classroom language cards. | P24: Yes
A25: 1 | B25: Year 7 | C25: Card, laminating and stationery | D25: Envelopes for the puzzle stages | E25: 18 | F25: envelopes, A4 size (C4, hold an A4 card flat) | G25: per group | I25: =IF(E25="","",IF(OR(AND(H25="Plan A",$C$5="B"),AND(H25="Plan B",$C$5="A")),0,IF(OR(G25="per student",G25="per group",G25="per class"),E25*IF(B25="Year 7",$C$3,$C$4),E25))) -> 18 | L25: =IF(OR(K25="",O25<>"",I25=""),"",ROUNDUP(I25*K25,0)) | M25: 3 per group labelled Stage 1, Stage 2, Stage 3; Stage 2 and 3 kept on the teacher desk; returned at clean-up and reused. | P25: Yes | Q25: The lesson file gives no size; the requisition lists A4 (C4) envelopes.
A26: 1 | B26: Year 7 | C26: Card, laminating and stationery | D26: Name cards | E26: 24 | F26: cards | G26: per student | I26: =IF(E26="","",IF(OR(AND(H26="Plan A",$C$5="B"),AND(H26="Plan B",$C$5="A")),0,IF(OR(G26="per student",G26="per group",G26="per class"),E26*IF(B26="Year 7",$C$3,$C$4),E26))) -> 24 | L26: =IF(OR(K26="",O26<>"",I26=""),"",ROUNDUP(I26*K26,0)) | M26: One per student, set out on the tables by the group seating plan before students arrive (Slide 1: 'Find your name card'). | P26: Yes | Q26: No design, size or material is given.
A27: 1 | B27: Year 7 | C27: Card, laminating and stationery | D27: Pencils | E27: 24 | F27: pencils, HB | G27: per student | I27: =IF(E27="","",IF(OR(AND(H27="Plan A",$C$5="B"),AND(H27="Plan B",$C$5="A")),0,IF(OR(G27="per student",G27="per group",G27="per class"),E27*IF(B27="Year 7",$C$3,$C$4),E27))) -> 24 | L27: =IF(OR(K27="",O27<>"",I27=""),"",ROUNDUP(I27*K27,0)) | M27: One per student for the skills check, survey, worksheet and logbook. | P27: Yes, see note | Q27: The requisition counts 24 HB; the teacher-desk spares have no number.
A28: 1 | B28: Year 7 | C28: Equipment and materials | D28: Class box | E28: 1 | F28: box with lid | G28: per class | I28: =IF(E28="","",IF(OR(AND(H28="Plan A",$C$5="B"),AND(H28="Plan B",$C$5="A")),0,IF(OR(G28="per student",G28="per group",G28="per class"),E28*IF(B28="Year 7",$C$3,$C$4),E28))) -> 1 | L28: =IF(OR(K28="",O28<>"",I28=""),"",ROUNDUP(I28*K28,0)) | M28: Logbooks are collected into it at the end of every lesson and kept there all term. | P28: Yes | Q28: The kind of box is not stated; the requisition chooses a plastic storage box with lid.
A29: 1 | B29: Year 7 | C29: Equipment and materials | D29: Class assessment folder | E29: 1 | F29: folder | G29: per class | I29: =IF(E29="","",IF(OR(AND(H29="Plan A",$C$5="B"),AND(H29="Plan B",$C$5="A")),0,IF(OR(G29="per student",G29="per group",G29="per class"),E29*IF(B29="Year 7",$C$3,$C$4),E29))) -> 1 | L29: =IF(OR(K29="",O29<>"",I29=""),"",ROUNDUP(I29*K29,0)) | M29: Marked Week 1 skills check papers are filed here and not returned until after Week 10. | P29: No: may already exist | Q29: Not in the requisition; check whether each class already has one.
A30: 1 | B30: Year 7 | C30: Equipment and materials | D30: Laminator and guillotine (or scissors) | F30: not stated (access needed); access to equipment | G30: per once | I30: =IF(E30="","",IF(OR(AND(H30="Plan A",$C$5="B"),AND(H30="Plan B",$C$5="A")),0,IF(OR(G30="per student",G30="per group",G30="per class"),E30*IF(B30="Year 7",$C$3,$C$4),E30))) | L30: =IF(OR(K30="",O30<>"",I30=""),"",ROUNDUP(I30*K30,0)) | M30: Laminate the role cards and classroom language cards; cut the role cards, frame cards and surveys. | P30: No: tool | Q30: Named nowhere; the specs only say laminate and cut.
A31: 1 | B31: Year 7 | C31: Equipment and materials | D31: Rulers (to measure against the 10 cm scale bar on the puzzle cards) | F31: not stated; rulers | G31: per group | I31: =IF(E31="","",IF(OR(AND(H31="Plan A",$C$5="B"),AND(H31="Plan B",$C$5="A")),0,IF(OR(G31="per student",G31="per group",G31="per class"),E31*IF(B31="Year 7",$C$3,$C$4),E31))) | L31: =IF(OR(K31="",O31<>"",I31=""),"",ROUNDUP(I31*K31,0)) | M31: Card 1 asks students to 'Count and measure'; every card has a 10 cm scale bar and the model answers give distances in cm. | N31: Optional | P31: No: may already exist | Q31: Not on the kit card; students can estimate by eye against the scale bar. Decide whether to put one on each table.
A32: 1 | B32: Year 7 | C32: Make beforehand | D32: Footprint puzzle envelope sets | E32: 6 | F32: sets of 3 labelled envelopes, one stage card in each | G32: per group | I32: =IF(E32="","",IF(OR(AND(H32="Plan A",$C$5="B"),AND(H32="Plan B",$C$5="A")),0,IF(OR(G32="per student",G32="per group",G32="per class"),E32*IF(B32="Year 7",$C$3,$C$4),E32))) -> 6 | L32: =IF(OR(K32="",O32<>"",I32=""),"",ROUNDUP(I32*K32,0)) | M32: Lead Scientists collect Stage 1; the 12 Stage 2 and 3 envelopes stay on the teacher desk until about 3 and 6 minutes into Do. | P32: Yes, see note | Q32: Made from the puzzle card and envelope rows; nothing extra to order.
A33: 1 | B33: Year 7 | C33: Make beforehand | D33: Group seating plan (with starting roles) | E33: 1 | F33: plan | G33: per class | I33: =IF(E33="","",IF(OR(AND(H33="Plan A",$C$5="B"),AND(H33="Plan B",$C$5="A")),0,IF(OR(G33="per student",G33="per group",G33="per class"),E33*IF(B33="Year 7",$C$3,$C$4),E33))) -> 1 | L33: =IF(OR(K33="",O33<>"",I33=""),"",ROUNDUP(I33*K33,0)) | M33: Six groups of 3 or 4 seated from the first minute; each Band 1 student beside a Band 3 language buddy; groups stay the same for Weeks 1 to 5. | P33: No: paper printing | Q33: Teacher-made; nothing to order. Language bands are only recorded after Weeks 1 to 2; decide how Band 1 students are identified for the Week 1 plan.
A34: 1 | B34: Year 8 | C34: Printing (paper copies) | D34: Skills Check paper, Year 8 (The Missing Trophy), Week 1 baseline | E34: 24 | F34: copies; 5 A4 portrait pages, double-sided (last side blank) | G34: per student | I34: =IF(E34="","",IF(OR(AND(H34="Plan A",$C$5="B"),AND(H34="Plan B",$C$5="A")),0,IF(OR(G34="per student",G34="per group",G34="per class"),E34*IF(B34="Year 7",$C$3,$C$4),E34))) -> 24 | J34: A4 paper | K34: 3 | L34: =IF(OR(K34="",O34<>"",I34=""),"",ROUNDUP(I34*K34,0)) -> 72 | M34: 15-minute baseline done alone; collected at once, marked, entered in the tracker and filed, never returned before Week 10. | P34: No: paper printing | Q34: The written spec says two sides of A4 (1 sheet), but the designed paper has 5 pages ('Page 1 of 5'). Confirm which is final before printing (24 or 72 sheets). Print from the same frozen master that Week 10 will use.
A35: 1 | B35: Year 8 | C35: Printing (paper copies) | D35: Interest survey (half A4, two copies per A4 sheet with a cut line) | E35: 24 | F35: copies; half A4, 2 per A4 sheet, single-sided, cut in half | G35: per student | I35: =IF(E35="","",IF(OR(AND(H35="Plan A",$C$5="B"),AND(H35="Plan B",$C$5="A")),0,IF(OR(G35="per student",G35="per group",G35="per class"),E35*IF(B35="Year 7",$C$3,$C$4),E35))) -> 24 | J35: A4 paper | K35: 0.5 | L35: =IF(OR(K35="",O35<>"",I35=""),"",ROUNDUP(I35*K35,0)) -> 12 | M35: 3-minute six-statement smiley survey straight after the skills check; scores go into tracker W1 S1 to S6. | P35: No: paper printing
A36: 1 | B36: Year 8 | C36: Printing (paper copies) | D36: Worksheet: Think like a detective | E36: 24 | F36: copies; 3 A4 portrait pages: pages 1 and 2 double-sided, page 3 single-sided | G36: per student | I36: =IF(E36="","",IF(OR(AND(H36="Plan A",$C$5="B"),AND(H36="Plan B",$C$5="A")),0,IF(OR(G36="per student",G36="per group",G36="per class"),E36*IF(B36="Year 7",$C$3,$C$4),E36))) -> 24 | J36: A4 paper | K36: 2 | L36: =IF(OR(K36="",O36<>"",I36=""),"",ROUNDUP(I36*K36,0)) -> 48 | M36: Core O or I sort, Stretch, Challenge, My thinking, fold-under word bank and exit ticket strip; goes into the case file and the exit ticket is cut off and collected. | P36: No: paper printing | Q36: Sidedness not stated. Keep page 3 (exit ticket strip and fold-under word bank) on its own sheet so cutting off the strip does not cut page 2.
A37: 1 | B37: Year 8 | C37: Printing (paper copies) | D37: Case briefing and Lab 3 sign-in sheet | E37: 24 | F37: copies; 2 A4 portrait pages, double-sided | G37: per student | I37: =IF(E37="","",IF(OR(AND(H37="Plan A",$C$5="B"),AND(H37="Plan B",$C$5="A")),0,IF(OR(G37="per student",G37="per group",G37="per class"),E37*IF(B37="Year 7",$C$3,$C$4),E37))) -> 24 | J37: A4 paper | K37: 1 | L37: =IF(OR(K37="",O37<>"",I37=""),"",ROUNDUP(I37*K37,0)) -> 24 | M37: What happened, the note, the five evidence items and the sign-in sheet; second item in the case file. | P37: No: paper printing | Q37: Lesson file 6.2 describes one page, but the design has two ('Page 1 of 2, turn over'). Double-sided keeps it to one sheet.
A38: 1 | B38: Year 8 | C38: Printing (paper copies) | D38: Scene map, Lab 3 (A4 landscape) | E38: 24 | F38: copies; 1 A4 landscape page, single-sided | G38: per student | I38: =IF(E38="","",IF(OR(AND(H38="Plan A",$C$5="B"),AND(H38="Plan B",$C$5="A")),0,IF(OR(G38="per student",G38="per group",G38="per class"),E38*IF(B38="Year 7",$C$3,$C$4),E38))) -> 24 | J38: A4 paper | K38: 1 | L38: =IF(OR(K38="",O38<>"",I38=""),"",ROUNDUP(I38*K38,0)) -> 24 | M38: Top-down plan of Lab 3 on the lettered grid for the Do task; third item in the case file. | P38: No: paper printing
A39: 1 | B39: Year 8 | C39: Printing (paper copies) | D39: Scene map, enlarged wall copy | E39: 1 | F39: copy; A3, single-sided | G39: per room | I39: =IF(E39="","",IF(OR(AND(H39="Plan A",$C$5="B"),AND(H39="Plan B",$C$5="A")),0,IF(OR(G39="per student",G39="per group",G39="per class"),E39*IF(B39="Year 7",$C$3,$C$4),E39))) -> 1 | J39: A3 paper | K39: 1 | L39: =IF(OR(K39="",O39<>"",I39=""),"",ROUNDUP(I39*K39,0)) -> 1 | M39: Wall copy; Band 1 students point to a square on it for the exit ticket. | P39: Yes | Q39: 1 of the 4 sheets in the 'A3 printing' row.
A40: 1 | B40: Year 8 | C40: Printing (paper copies) | D40: Suspect profile cards (four A6 cards on one A4 sheet, cut lines) | E40: 24 | F40: copies; 1 A4 portrait sheet, single-sided | G40: per student | I40: =IF(E40="","",IF(OR(AND(H40="Plan A",$C$5="B"),AND(H40="Plan B",$C$5="A")),0,IF(OR(G40="per student",G40="per group",G40="per class"),E40*IF(B40="Year 7",$C$3,$C$4),E40))) -> 24 | J40: A4 paper | K40: 1 | L40: =IF(OR(K40="",O40<>"",I40=""),"",ROUNDUP(I40*K40,0)) -> 24 | M40: Meet the suspects; the Week 2 Do Now uses them, so every case file needs a set; students may cut them out. | P40: No: paper printing
A41: 1 | B41: Year 8 | C41: Printing (paper copies) | D41: Kit card, teacher copy | E41: 1 | F41: copy; A5 (half A4), single-sided | G41: per once | I41: =IF(E41="","",IF(OR(AND(H41="Plan A",$C$5="B"),AND(H41="Plan B",$C$5="A")),0,IF(OR(G41="per student",G41="per group",G41="per class"),E41*IF(B41="Year 7",$C$3,$C$4),E41))) -> 1 | J41: A5 paper | K41: 1 | L41: =IF(OR(K41="",O41<>"",I41=""),"",ROUNDUP(I41*K41,0)) -> 1 | M41: Kit, prep, hazards and clean-up checklist for the teacher. | P41: No: paper printing
...

Sheet Prep by week
A1: Prep by week: how much time each lesson takes to get ready
A2: Minutes come from the kit cards where they give them; the rest are estimates (marked). "After" is marking, the tracker and putting kit away. "Could be done by someone else" means a technician, assistant, reprographics or the students. Uses the classes and freezer plan on the All weeks sheet: until a Year 7 freezer plan is chosen, Weeks 5 to 8 count the prep for both plans.
A4: Week | B4: Year 7: before the lesson (min) | C4: Year 7: after (marking, admin) | D4: Year 7: could be done by someone else | E4: Year 8: before the lesson (min) | F4: Year 8: after (marking, admin) | G4: Year 8: could be done by someone else | H4: Both years, before and after (hours) | I4: Optional extras (min, not counted)
A5: 1 | B5: =SUMIFS($L$19:$L$380,$A$19:$A$380,$A5,$B$19:$B$380,"Year 7",$J$19:$J$380,"No",$C$19:$C$380,"<>After the lesson") -> 187 | C5: =SUMIFS($L$19:$L$380,$A$19:$A$380,$A5,$B$19:$B$380,"Year 7",$J$19:$J$380,"No",$C$19:$C$380,"After the lesson") -> 108 | D5: =SUMIFS($L$19:$L$380,$A$19:$A$380,$A5,$B$19:$B$380,"Year 7",$J$19:$J$380,"No",$G$19:$G$380,"<>Teacher") -> 182 | E5: =SUMIFS($L$19:$L$380,$A$19:$A$380,$A5,$B$19:$B$380,"Year 8",$J$19:$J$380,"No",$C$19:$C$380,"<>After the lesson") -> 220 | F5: =SUMIFS($L$19:$L$380,$A$19:$A$380,$A5,$B$19:$B$380,"Year 8",$J$19:$J$380,"No",$C$19:$C$380,"After the lesson") -> 105 | G5: =SUMIFS($L$19:$L$380,$A$19:$A$380,$A5,$B$19:$B$380,"Year 8",$J$19:$J$380,"No",$G$19:$G$380,"<>Teacher") -> 155 | H5: =ROUND((B5+C5+E5+F5)/60,1) -> 10.3 | I5: =SUMIFS($L$19:$L$380,$A$19:$A$380,$A5,$J$19:$J$380,"Optional") -> 60
A6: 2 | B6: =SUMIFS($L$19:$L$380,$A$19:$A$380,$A6,$B$19:$B$380,"Year 7",$J$19:$J$380,"No",$C$19:$C$380,"<>After the lesson") -> 67 | C6: =SUMIFS($L$19:$L$380,$A$19:$A$380,$A6,$B$19:$B$380,"Year 7",$J$19:$J$380,"No",$C$19:$C$380,"After the lesson") -> 26 | D6: =SUMIFS($L$19:$L$380,$A$19:$A$380,$A6,$B$19:$B$380,"Year 7",$J$19:$J$380,"No",$G$19:$G$380,"<>Teacher") -> 63 | E6: =SUMIFS($L$19:$L$380,$A$19:$A$380,$A6,$B$19:$B$380,"Year 8",$J$19:$J$380,"No",$C$19:$C$380,"<>After the lesson") -> 50 | F6: =SUMIFS($L$19:$L$380,$A$19:$A$380,$A6,$B$19:$B$380,"Year 8",$J$19:$J$380,"No",$C$19:$C$380,"After the lesson") -> 21 | G6: =SUMIFS($L$19:$L$380,$A$19:$A$380,$A6,$B$19:$B$380,"Year 8",$J$19:$J$380,"No",$G$19:$G$380,"<>Teacher") -> 46 | H6: =ROUND((B6+C6+E6+F6)/60,1) -> 2.7 | I6: =SUMIFS($L$19:$L$380,$A$19:$A$380,$A6,$J$19:$J$380,"Optional") -> 7
A7: 3 | B7: =SUMIFS($L$19:$L$380,$A$19:$A$380,$A7,$B$19:$B$380,"Year 7",$J$19:$J$380,"No",$C$19:$C$380,"<>After the lesson") -> 57 | C7: =SUMIFS($L$19:$L$380,$A$19:$A$380,$A7,$B$19:$B$380,"Year 7",$J$19:$J$380,"No",$C$19:$C$380,"After the lesson") -> 20 | D7: =SUMIFS($L$19:$L$380,$A$19:$A$380,$A7,$B$19:$B$380,"Year 7",$J$19:$J$380,"No",$G$19:$G$380,"<>Teacher") -> 50 | E7: =SUMIFS($L$19:$L$380,$A$19:$A$380,$A7,$B$19:$B$380,"Year 8",$J$19:$J$380,"No",$C$19:$C$380,"<>After the lesson") -> 82 | F7: =SUMIFS($L$19:$L$380,$A$19:$A$380,$A7,$B$19:$B$380,"Year 8",$J$19:$J$380,"No",$C$19:$C$380,"After the lesson") -> 23 | G7: =SUMIFS($L$19:$L$380,$A$19:$A$380,$A7,$B$19:$B$380,"Year 8",$J$19:$J$380,"No",$G$19:$G$380,"<>Teacher") -> 73 | H7: =ROUND((B7+C7+E7+F7)/60,1) -> 3 | I7: =SUMIFS($L$19:$L$380,$A$19:$A$380,$A7,$J$19:$J$380,"Optional") -> 10
A8: 4 | B8: =SUMIFS($L$19:$L$380,$A$19:$A$380,$A8,$B$19:$B$380,"Year 7",$J$19:$J$380,"No",$C$19:$C$380,"<>After the lesson") -> 40 | C8: =SUMIFS($L$19:$L$380,$A$19:$A$380,$A8,$B$19:$B$380,"Year 7",$J$19:$J$380,"No",$C$19:$C$380,"After the lesson") -> 18 | D8: =SUMIFS($L$19:$L$380,$A$19:$A$380,$A8,$B$19:$B$380,"Year 7",$J$19:$J$380,"No",$G$19:$G$380,"<>Teacher") -> 31 | E8: =SUMIFS($L$19:$L$380,$A$19:$A$380,$A8,$B$19:$B$380,"Year 8",$J$19:$J$380,"No",$C$19:$C$380,"<>After the lesson") -> 70 | F8: =SUMIFS($L$19:$L$380,$A$19:$A$380,$A8,$B$19:$B$380,"Year 8",$J$19:$J$380,"No",$C$19:$C$380,"After the lesson") -> 34 | G8: =SUMIFS($L$19:$L$380,$A$19:$A$380,$A8,$B$19:$B$380,"Year 8",$J$19:$J$380,"No",$G$19:$G$380,"<>Teacher") -> 54 | H8: =ROUND((B8+C8+E8+F8)/60,1) -> 2.7 | I8: =SUMIFS($L$19:$L$380,$A$19:$A$380,$A8,$J$19:$J$380,"Optional") -> 7
A9: 5 | B9: =SUMIFS($L$19:$L$380,$A$19:$A$380,$A9,$B$19:$B$380,"Year 7",$J$19:$J$380,"No",$C$19:$C$380,"<>After the lesson") -> 40 | C9: =SUMIFS($L$19:$L$380,$A$19:$A$380,$A9,$B$19:$B$380,"Year 7",$J$19:$J$380,"No",$C$19:$C$380,"After the lesson") -> 144 | D9: =SUMIFS($L$19:$L$380,$A$19:$A$380,$A9,$B$19:$B$380,"Year 7",$J$19:$J$380,"No",$G$19:$G$380,"<>Teacher") -> 60 | E9: =SUMIFS($L$19:$L$380,$A$19:$A$380,$A9,$B$19:$B$380,"Year 8",$J$19:$J$380,"No",$C$19:$C$380,"<>After the lesson") -> 84 | F9: =SUMIFS($L$19:$L$380,$A$19:$A$380,$A9,$B$19:$B$380,"Year 8",$J$19:$J$380,"No",$C$19:$C$380,"After the lesson") -> 75 | G9: =SUMIFS($L$19:$L$380,$A$19:$A$380,$A9,$B$19:$B$380,"Year 8",$J$19:$J$380,"No",$G$19:$G$380,"<>Teacher") -> 43 | H9: =ROUND((B9+C9+E9+F9)/60,1) -> 5.7 | I9: =SUMIFS($L$19:$L$380,$A$19:$A$380,$A9,$J$19:$J$380,"Optional") -> 15
A10: 6 | B10: =SUMIFS($L$19:$L$380,$A$19:$A$380,$A10,$B$19:$B$380,"Year 7",$J$19:$J$380,"No",$C$19:$C$380,"<>After the lesson") -> 110 | C10: =SUMIFS($L$19:$L$380,$A$19:$A$380,$A10,$B$19:$B$380,"Year 7",$J$19:$J$380,"No",$C$19:$C$380,"After the lesson") -> 33 | D10: =SUMIFS($L$19:$L$380,$A$19:$A$380,$A10,$B$19:$B$380,"Year 7",$J$19:$J$380,"No",$G$19:$G$380,"<>Teacher") -> 101 | E10: =SUMIFS($L$19:$L$380,$A$19:$A$380,$A10,$B$19:$B$380,"Year 8",$J$19:$J$380,"No",$C$19:$C$380,"<>After the lesson") -> 103 | F10: =SUMIFS($L$19:$L$380,$A$19:$A$380,$A10,$B$19:$B$380,"Year 8",$J$19:$J$380,"No",$C$19:$C$380,"After the lesson") -> 28 | G10: =SUMIFS($L$19:$L$380,$A$19:$A$380,$A10,$B$19:$B$380,"Year 8",$J$19:$J$380,"No",$G$19:$G$380,"<>Teacher") -> 56 | H10: =ROUND((B10+C10+E10+F10)/60,1) -> 4.6 | I10: =SUMIFS($L$19:$L$380,$A$19:$A$380,$A10,$J$19:$J$380,"Optional") -> 10
A11: 7 | B11: =SUMIFS($L$19:$L$380,$A$19:$A$380,$A11,$B$19:$B$380,"Year 7",$J$19:$J$380,"No",$C$19:$C$380,"<>After the lesson") -> 170 | C11: =SUMIFS($L$19:$L$380,$A$19:$A$380,$A11,$B$19:$B$380,"Year 7",$J$19:$J$380,"No",$C$19:$C$380,"After the lesson") -> 40 | D11: =SUMIFS($L$19:$L$380,$A$19:$A$380,$A11,$B$19:$B$380,"Year 7",$J$19:$J$380,"No",$G$19:$G$380,"<>Teacher") -> 147 | E11: =SUMIFS($L$19:$L$380,$A$19:$A$380,$A11,$B$19:$B$380,"Year 8",$J$19:$J$380,"No",$C$19:$C$380,"<>After the lesson") -> 50 | F11: =SUMIFS($L$19:$L$380,$A$19:$A$380,$A11,$B$19:$B$380,"Year 8",$J$19:$J$380,"No",$C$19:$C$380,"After the lesson") -> 43 | G11: =SUMIFS($L$19:$L$380,$A$19:$A$380,$A11,$B$19:$B$380,"Year 8",$J$19:$J$380,"No",$G$19:$G$380,"<>Teacher") -> 13 | H11: =ROUND((B11+C11+E11+F11)/60,1) -> 5.1 | I11: =SUMIFS($L$19:$L$380,$A$19:$A$380,$A11,$J$19:$J$380,"Optional") -> 60
A12: 8 | B12: =SUMIFS($L$19:$L$380,$A$19:$A$380,$A12,$B$19:$B$380,"Year 7",$J$19:$J$380,"No",$C$19:$C$380,"<>After the lesson") -> 146 | C12: =SUMIFS($L$19:$L$380,$A$19:$A$380,$A12,$B$19:$B$380,"Year 7",$J$19:$J$380,"No",$C$19:$C$380,"After the lesson") -> 27 | D12: =SUMIFS($L$19:$L$380,$A$19:$A$380,$A12,$B$19:$B$380,"Year 7",$J$19:$J$380,"No",$G$19:$G$380,"<>Teacher") -> 130 | E12: =SUMIFS($L$19:$L$380,$A$19:$A$380,$A12,$B$19:$B$380,"Year 8",$J$19:$J$380,"No",$C$19:$C$380,"<>After the lesson") -> 205 | F12: =SUMIFS($L$19:$L$380,$A$19:$A$380,$A12,$B$19:$B$380,"Year 8",$J$19:$J$380,"No",$C$19:$C$380,"After the lesson") -> 78 | G12: =SUMIFS($L$19:$L$380,$A$19:$A$380,$A12,$B$19:$B$380,"Year 8",$J$19:$J$380,"No",$G$19:$G$380,"<>Teacher") -> 148 | H12: =ROUND((B12+C12+E12+F12)/60,1) -> 7.6 | I12: =SUMIFS($L$19:$L$380,$A$19:$A$380,$A12,$J$19:$J$380,"Optional") -> 30
A13: 9 | B13: =SUMIFS($L$19:$L$380,$A$19:$A$380,$A13,$B$19:$B$380,"Year 7",$J$19:$J$380,"No",$C$19:$C$380,"<>After the lesson") -> 75 | C13: =SUMIFS($L$19:$L$380,$A$19:$A$380,$A13,$B$19:$B$380,"Year 7",$J$19:$J$380,"No",$C$19:$C$380,"After the lesson") -> 51 | D13: =SUMIFS($L$19:$L$380,$A$19:$A$380,$A13,$B$19:$B$380,"Year 7",$J$19:$J$380,"No",$G$19:$G$380,"<>Teacher") -> 48 | E13: =SUMIFS($L$19:$L$380,$A$19:$A$380,$A13,$B$19:$B$380,"Year 8",$J$19:$J$380,"No",$C$19:$C$380,"<>After the lesson") -> 68 | F13: =SUMIFS($L$19:$L$380,$A$19:$A$380,$A13,$B$19:$B$380,"Year 8",$J$19:$J$380,"No",$C$19:$C$380,"After the lesson") -> 108 | G13: =SUMIFS($L$19:$L$380,$A$19:$A$380,$A13,$B$19:$B$380,"Year 8",$J$19:$J$380,"No",$G$19:$G$380,"<>Teacher") -> 36 | H13: =ROUND((B13+C13+E13+F13)/60,1) -> 5 | I13: =SUMIFS($L$19:$L$380,$A$19:$A$380,$A13,$J$19:$J$380,"Optional") -> 18
A14: 10 | B14: =SUMIFS($L$19:$L$380,$A$19:$A$380,$A14,$B$19:$B$380,"Year 7",$J$19:$J$380,"No",$C$19:$C$380,"<>After the lesson") -> 66 | C14: =SUMIFS($L$19:$L$380,$A$19:$A$380,$A14,$B$19:$B$380,"Year 7",$J$19:$J$380,"No",$C$19:$C$380,"After the lesson") -> 315 | D14: =SUMIFS($L$19:$L$380,$A$19:$A$380,$A14,$B$19:$B$380,"Year 7",$J$19:$J$380,"No",$G$19:$G$380,"<>Teacher") -> 81 | E14: =SUMIFS($L$19:$L$380,$A$19:$A$380,$A14,$B$19:$B$380,"Year 8",$J$19:$J$380,"No",$C$19:$C$380,"<>After the lesson") -> 62 | F14: =SUMIFS($L$19:$L$380,$A$19:$A$380,$A14,$B$19:$B$380,"Year 8",$J$19:$J$380,"No",$C$19:$C$380,"After the lesson") -> 333 | G14: =SUMIFS($L$19:$L$380,$A$19:$A$380,$A14,$B$19:$B$380,"Year 8",$J$19:$J$380,"No",$G$19:$G$380,"<>Teacher") -> 41 | H14: =ROUND((B14+C14+E14+F14)/60,1) -> 12.9 | I14: =SUMIFS($L$19:$L$380,$A$19:$A$380,$A14,$J$19:$J$380,"Optional") -> 63
A15: Total | B15: =SUM(B5:B14) -> 958 | C15: =SUM(C5:C14) -> 782 | D15: =SUM(D5:D14) -> 893 | E15: =SUM(E5:E14) -> 994 | F15: =SUM(F5:F14) -> 848 | G15: =SUM(G5:G14) -> 665 | H15: =SUM(H5:H14) -> 59.6 | I15: =SUM(I5:I14) -> 280
A17: All prep tasks
A18: Week | B18: Year | C18: When | D18: Task | E18: Minutes (one class) | F18: Minutes from | G18: Who could do it | H18: Once for all classes? | I18: Reused later | J18: Optional? | K18: Plan | L18: Minutes for your classes
A19: 1 | B19: Year 7 | C19: 2 or more weeks before | D19: Order the Week 1 kit from the requisition: A4 card, A4 (C4) envelopes, A4 and A5 laminating pouches, A3 paper, name cards, HB pencils and the class box. | E19: 15 | F19: estimate | G19: Technician or assistant | H19: Yes | J19: No | L19: =IF(E19="","",IF(OR(AND(K19="Plan A",'All weeks'!$C$5="B"),AND(K19="Plan B",'All weeks'!$C$5="A")),0,IF(H19="Yes",E19,E19*IF(B19="Year 7",'All weeks'!$C$3,'All weeks'!$C$4)))) -> 15
A20: 1 | B20: Year 7 | C20: 2 or more weeks before | D20: Send the booklet jobs to reprographics: Scientist's Logbook (24 per class) and My Science Dictionary (28 per class, A5 saddle-stitched, 24 or 28 pages, 90 gsm). | E20: 10 | F20: estimate | G20: Teacher | H20: Yes | I20: Weeks 2 to 10 | J20: No | L20: =IF(E20="","",IF(OR(AND(K20="Plan A",'All weeks'!$C$5="B"),AND(K20="Plan B",'All weeks'!$C$5="A")),0,IF(H20="Yes",E20,E20*IF(B20="Year 7",'All weeks'!$C$3,'All weeks'!$C$4)))) -> 10
A21: 1 | B21: Year 7 | C21: The week before | D21: Print the group role cards (6 A4 sheets), laminate them (6 A4 pouches), cut into 36 cards and sort into 6 sets of 6. | E21: 25 | F21: estimate | G21: Technician or assistant | H21: No | I21: Weeks 2 to 10 | J21: No | L21: =IF(E21="","",IF(OR(AND(K21="Plan A",'All weeks'!$C$5="B"),AND(K21="Plan B",'All weeks'!$C$5="A")),0,IF(H21="Yes",E21,E21*IF(B21="Year 7",'All weeks'!$C$3,'All weeks'!$C$4)))) -> 25
A22: 1 | B22: Year 7 | C22: The week before | D22: Print the classroom language cards double-sided (30 A5, or 15 A4 sheets cut in half) and laminate them (30 A5 pouches). | E22: 30 | F22: estimate | G22: Technician or assistant | H22: No | I22: Weeks 2 to 10 | J22: No | L22: =IF(E22="","",IF(OR(AND(K22="Plan A",'All weeks'!$C$5="B"),AND(K22="Plan B",'All weeks'!$C$5="A")),0,IF(H22="Yes",E22,E22*IF(B22="Year 7",'All weeks'!$C$3,'All weeks'!$C$4)))) -> 30
A23: 1 | B23: Year 7 | C23: The week before | D23: Print the footprint puzzle cards on A4 card: 6 sets of Stage 1, 2 and 3 (18 sheets), with the teacher note on the back of each Card 3. | E23: 10 | F23: estimate | G23: Technician or assistant | H23: No | J23: No | L23: =IF(E23="","",IF(OR(AND(K23="Plan A",'All weeks'!$C$5="B"),AND(K23="Plan B",'All weeks'!$C$5="A")),0,IF(H23="Yes",E23,E23*IF(B23="Year 7",'All weeks'!$C$3,'All weeks'!$C$4)))) -> 10
A24: 1 | B24: Year 7 | C24: The week before | D24: Only if not using card: print the 18 puzzle cards on paper and laminate them (18 A4 pouches). | E24: 20 | F24: estimate | G24: Technician or assistant | H24: No | J24: Optional | L24: =IF(E24="","",IF(OR(AND(K24="Plan A",'All weeks'!$C$5="B"),AND(K24="Plan B",'All weeks'!$C$5="A")),0,IF(H24="Yes",E24,E24*IF(B24="Year 7",'All weeks'!$C$3,'All weeks'!$C$4)))) -> 20
A25: 1 | B25: Year 7 | C25: The week before | D25: Print the worksheets: 24 copies, 4 pages double-sided (48 sheets), from the design rebuilt after the language pass (discard any earlier copies). First check the exit ticket cut line against the My thinking box on the back. | E25: 5 | F25: estimate | G25: Reprographics | H25: No | J25: No | L25: =IF(E25="","",IF(OR(AND(K25="Plan A",'All weeks'!$C$5="B"),AND(K25="Plan B",'All weeks'!$C$5="A")),0,IF(H25="Yes",E25,E25*IF(B25="Year 7",'All weeks'!$C$3,'All weeks'!$C$4)))) -> 5
A26: 1 | B26: Year 7 | C26: The week before | D26: Print and sort the skills check papers (3 sheets each, double-sided) and survey papers (2 per A4, cut in half) in class order. | E26: 10 | F26: kit card | G26: Technician or assistant | H26: No | J26: No | L26: =IF(E26="","",IF(OR(AND(K26="Plan A",'All weeks'!$C$5="B"),AND(K26="Plan B",'All weeks'!$C$5="A")),0,IF(H26="Yes",E26,E26*IF(B26="Year 7",'All weeks'!$C$3,'All weeks'!$C$4)))) -> 10
A27: 1 | B27: Year 7 | C27: The week before | D27: Print the teacher copies: skills check mark scheme (2 pages) and the Week 1 kit card. | E27: 3 | F27: estimate | G27: Teacher | H27: Yes | J27: No | L27: =IF(E27="","",IF(OR(AND(K27="Plan A",'All weeks'!$C$5="B"),AND(K27="Plan B",'All weeks'!$C$5="A")),0,IF(H27="Yes",E27,E27*IF(B27="Year 7",'All weeks'!$C$3,'All weeks'!$C$4)))) -> 3
A28: 1 | B28: Year 7 | C28: The week before | D28: Print the three A3 posters (Instruction words, Classroom language side B, Think in any language) and the A4 sentence frame poster; put them up on the wall. | E28: 15 | F28: estimate | G28: Technician or assistant | H28: Yes | I28: Weeks 2 to 10 | J28: No | L28: =IF(E28="","",IF(OR(AND(K28="Plan A",'All weeks'!$C$5="B"),AND(K28="Plan B",'All weeks'!$C$5="A")),0,IF(H28="Yes",E28,E28*IF(B28="Year 7",'All weeks'!$C$3,'All weeks'!$C$4)))) -> 15
A29: 1 | B29: Year 7 | C29: The week before | D29: Print and cut the sentence frame bank cards: 24 A4 sheets into 6 sets of 16 A6 cards. | E29: 20 | F29: estimate | G29: Technician or assistant | H29: No | I29: Weeks 2 to 10 | J29: No | L29: =IF(E29="","",IF(OR(AND(K29="Plan A",'All weeks'!$C$5="B"),AND(K29="Plan B",'All weeks'!$C$5="A")),0,IF(H29="Yes",E29,E29*IF(B29="Year 7",'All weeks'!$C$3,'All weeks'!$C$4)))) -> 20
A30: 1 | B30: Year 7 | C30: The week before | D30: Write the group seating plan: six groups of 3 or 4, each Band 1 student beside a Band 3 language buddy, with a starting role for each student. | E30: 10 | F30: estimate | G30: Teacher | H30: No | I30: Weeks 2 to 5 | J30: No | L30: =IF(E30="","",IF(OR(AND(K30="Plan A",'All weeks'!$C$5="B"),AND(K30="Plan B",'All weeks'!$C$5="A")),0,IF(H30="Yes",E30,E30*IF(B30="Year 7",'All weeks'!$C$3,'All weeks'!$C$4)))) -> 10
A31: 1 | B31: Year 7 | C31: The week before | D31: Set up the class tab in the tracker: columns A to E (number, names, group, starting role) from the class list and seating plan. | E31: 10 | F31: estimate | G31: Teacher | H31: No | J31: No | L31: =IF(E31="","",IF(OR(AND(K31="Plan A",'All weeks'!$C$5="B"),AND(K31="Plan B",'All weeks'!$C$5="A")),0,IF(H31="Yes",E31,E31*IF(B31="Year 7",'All weeks'!$C$3,'All weeks'!$C$4)))) -> 10
A32: 1 | B32: Year 7 | C32: The week before | D32: Make 24 name cards from the class list and seating plan. | E32: 10 | F32: estimate | G32: Technician or assistant | H32: No | J32: No | L32: =IF(E32="","",IF(OR(AND(K32="Plan A",'All weeks'!$C$5="B"),AND(K32="Plan B",'All weeks'!$C$5="A")),0,IF(H32="Yes",E32,E32*IF(B32="Year 7",'All weeks'!$C$3,'All weeks'!$C$4)))) -> 10
A33: 1 | B33: Year 7 | C33: The day before | D33: Label 18 envelopes Stage 1, Stage 2, Stage 3 (3 per group) and put one puzzle card in each; keep the Stage 2 and 3 envelopes for the teacher desk. | E33: 5 | F33: kit card | G33: Technician or assistant | H33: No | J33: No | L33: =IF(E33="","",IF(OR(AND(K33="Plan A",'All weeks'!$C$5="B"),AND(K33="Plan B",'All weeks'!$C$5="A")),0,IF(H33="Yes",E33,E33*IF(B33="Year 7",'All weeks'!$C$3,'All weeks'!$C$4)))) -> 5
A34: 1 | B34: Year 7 | C34: On the day, before the lesson | D34: Set out name cards by the group seating plan and one set of role cards per table. | E34: 5 | F34: kit card | G34: Technician or assistant | H34: No | J34: No | L34: =IF(E34="","",IF(OR(AND(K34="Plan A",'All weeks'!$C$5="B"),AND(K34="Plan B",'All weeks'!$C$5="A")),0,IF(H34="Yes",E34,E34*IF(B34="Year 7",'All weeks'!$C$3,'All weeks'!$C$4)))) -> 5
A35: 1 | B35: Year 7 | C35: On the day, before the lesson | D35: Put out pencils (1 per student, spares on the teacher desk); place the sorted skills checks and surveys, logbooks, dictionaries and the 18 envelopes on the teacher desk. | E35: 3 | F35: estimate | G35: Technician or assistant | H35: No | J35: No | L35: =IF(E35="","",IF(OR(AND(K35="Plan A",'All weeks'!$C$5="B"),AND(K35="Plan B",'All weeks'!$C$5="A")),0,IF(H35="Yes",E35,E35*IF(B35="Year 7",'All weeks'!$C$3,'All weeks'!$C$4)))) -> 3
A36: 1 | B36: Year 7 | C36: Set-up by students in the lesson | D36: Clean-up led by the Safety Officer: puzzle cards back into their envelopes in stage order and returned to the teacher; logbooks collected into the class box. | E36: 1 | F36: estimate | G36: Students (roles) | H36: No | J36: No | L36: =IF(E36="","",IF(OR(AND(K36="Plan A",'All weeks'!$C$5="B"),AND(K36="Plan B",'All weeks'!$C$5="A")),0,IF(H36="Yes",E36,E36*IF(B36="Year 7",'All weeks'!$C$3,'All weeks'!$C$4)))) -> 1
A37: 1 | B37: Year 7 | C37: After the lesson | D37: Check the six envelope sets are complete and in stage order; put the class box of logbooks away. | E37: 3 | F37: estimate | G37: Technician or assistant | H37: No | J37: No | L37: =IF(E37="","",IF(OR(AND(K37="Plan A",'All weeks'!$C$5="B"),AND(K37="Plan B",'All weeks'!$C$5="A")),0,IF(H37="Yes",E37,E37*IF(B37="Year 7",'All weeks'!$C$3,'All weeks'!$C$4)))) -> 3
A38: 1 | B38: Year 7 | C38: After the lesson | D38: Read the exit tickets before Week 2; note who needs the Do Now recap and who is ready for Stretch. | E38: 10 | F38: estimate | G38: Teacher | H38: No | J38: No | L38: =IF(E38="","",IF(OR(AND(K38="Plan A",'All weeks'!$C$5="B"),AND(K38="Plan B",'All weeks'!$C$5="A")),0,IF(H38="Yes",E38,E38*IF(B38="Year 7",'All weeks'!$C$3,'All weeks'!$C$4)))) -> 10
A39: 1 | B39: Year 7 | C39: After the lesson | D39: Mark the skills checks out of 20 with the mark scheme within the week (no half marks; accept Chinese). | E39: 70 | F39: estimate | G39: Teacher | H39: No | J39: No | L39: =IF(E39="","",IF(OR(AND(K39="Plan A",'All weeks'!$C$5="B"),AND(K39="Plan B",'All weeks'!$C$5="A")),0,IF(H39="Yes",E39,E39*IF(B39="Year 7",'All weeks'!$C$3,'All weeks'!$C$4)))) -> 70
A40: 1 | B40: Year 7 | C40: After the lesson | D40: Enter skills check totals and the six survey scores per student in the tracker (columns I to O) and any access arrangements (column H); file the papers in the class assessment folder and do not return them. | E40: 25 | F40: estimate | G40: Technician or assistant | H40: No | J40: No | L40: =IF(E40="","",IF(OR(AND(K40="Plan A",'All weeks'!$C$5="B"),AND(K40="Plan B",'All weeks'!$C$5="A")),0,IF(H40="Yes",E40,E40*IF(B40="Year 7",'All weeks'!$C$3,'All weeks'!$C$4)))) -> 25
A41: 1 | B41: Year 7 | C41: After the lesson | D41: Enter question-by-question skills check marks on the tracker's Question_analysis tab. | E41: 15 | F41: estimate | G41: Technician or assistant | H41: No | J41: Optional | L41: =IF(E41="","",IF(OR(AND(K41="Plan A",'All weeks'!$C$5="B"),AND(K41="Plan B",'All weeks'!$C$5="A")),0,IF(H41="Yes",E41,E41*IF(B41="Year 7",'All weeks'!$C$3,'All weeks'!$C$4)))) -> 15
A42: 1 | B42: Year 8 | C42: 2 or more weeks before | D42: Order the kit: 8 black washable felt-tip pens (four brands, two of each), coffee filters, masking tape, 24 A4 folders, 49 sheets of white A4 card, A3 paper, laminating pouches (6 A4, 30 A5), 24 pencils and a class box; plain bar soap and baking soda if using the scene table. | E42: 15 | F42: estimate | G42: Technician or assistant | H42: Yes | I42: Pens: Week 3; folders and class box: Weeks 2 to 10 | J42: No | L42: =IF(E42="","",IF(OR(AND(K42="Plan A",'All weeks'!$C$5="B"),AND(K42="Plan B",'All weeks'!$C$5="A")),0,IF(H42="Yes",E42,E42*IF(B42="Year 7",'All weeks'!$C$3,'All weeks'!$C$4)))) -> 15
...

Sheet Cut the prep
A1: Cutting the prep
A2: Where the prep time goes for one class, and the options for reducing it. Minutes link to the Prep by week sheet; the lessons themselves are unchanged.
A4: 1. Do all the printing in one request before Week 1
A5: Send the whole term's printing to reprographics at once (sheet totals below, from the All weeks sheet). Printing and sorting then stops being a weekly job.
C6: Printing tasks in the prep list (min, one class) | D6: =SUMIFS('Prep by week'!$E$19:$E$380,'Prep by week'!$G$19:$G$380,"Reprographics",'Prep by week'!$J$19:$J$380,"No") -> 196
C7: A4 paper (sheets, all weeks) | D7: =SUMIFS('All weeks'!$L$9:$L$721,'All weeks'!$J$9:$J$721,"A4 paper") -> 1987
C8: A3 paper (sheets, all weeks) | D8: =SUMIFS('All weeks'!$L$9:$L$721,'All weeks'!$J$9:$J$721,"A3 paper") -> 36
C9: A5 paper (sheets, all weeks) | D9: =SUMIFS('All weeks'!$L$9:$L$721,'All weeks'!$J$9:$J$721,"A5 paper") -> 160
C10: A4 card (sheets, all weeks) | D10: =SUMIFS('All weeks'!$L$9:$L$721,'All weeks'!$J$9:$J$721,"A4 card") -> 176
C11: A4 90 gsm (booklet) (sheets, all weeks) | D11: =SUMIFS('All weeks'!$L$9:$L$721,'All weeks'!$J$9:$J$721,"A4 90 gsm (booklet)") -> 196
A13: 2. Hand tasks to a technician, an assistant or the students
A14: Tasks marked as something someone else could do: buying, cutting, counting out kit, setting out trays, clean-up roles.
C15: Technician or assistant (min, one class) | D15: =SUMIFS('Prep by week'!$E$19:$E$380,'Prep by week'!$G$19:$G$380,"Technician or assistant",'Prep by week'!$J$19:$J$380,"No") -> 1306
C16: Students in the lesson (min, one class) | D16: =SUMIFS('Prep by week'!$E$19:$E$380,'Prep by week'!$G$19:$G$380,"Students (roles)",'Prep by week'!$J$19:$J$380,"No") -> 56
C17: Teacher only (min, one class) | D17: =SUMIFS('Prep by week'!$E$19:$E$380,'Prep by week'!$G$19:$G$380,"Teacher",'Prep by week'!$J$19:$J$380,"No") -> 2024
A19: 3. Make the reusable sets once, in one session before Week 1
A20: These are made once and reused in later weeks and by every class. Doing them together saves setting up and packing away each time.
A21: Week | B21: Year | C21: Task | D21: Minutes | E21: Reused
A22: 1 | B22: Year 7 | C22: Send the booklet jobs to reprographics: Scientist's Logbook (24 per class) and My Science Dictionary (28 per class, A5 saddle-stitched, 24 or 28 pages, 90 gsm). | D22: 10 | E22: Weeks 2 to 10
A23: 1 | B23: Year 7 | C23: Print the three A3 posters (Instruction words, Classroom language side B, Think in any language) and the A4 sentence frame poster; put them up on the wall. | D23: 15 | E23: Weeks 2 to 10
A24: 1 | B24: Year 8 | C24: Order the kit: 8 black washable felt-tip pens (four brands, two of each), coffee filters, masking tape, 24 A4 folders, 49 sheets of white A4 card, A3 paper, laminating pouches (6 A4, 30 A5), 24 pencils and a class box; plain bar soap and baking soda if using the scene table. | D24: 15 | E24: Pens: Week 3; folders and class box: Weeks 2 to 10
A25: 1 | B25: Year 8 | C25: Check the Skills Check master is final (native-speaker fixes made) before the print run, then freeze it unchanged until Week 10. | D25: 5 | E25: Week 10 (same master)
A26: 1 | B26: Year 8 | C26: Ask the school nurse or form tutors for the allergy list (needed for the Week 4 powders). | D26: 5 | E26: Weeks 4 and 5
A27: 1 | B27: Year 8 | C27: Run the pen pre-test (Case Bible Section 11): cut 4 coffee-filter strips 2 cm by 10 cm, pencil line 2 cm up, one dot per pen, stand in cups of water 1 cm deep for 6 to 8 minutes; check four clearly different patterns; choose pen B; cover brand names with masking tape and label A to D; record on the Teacher Pre-test Record; keep the dried strips. The Teacher Guide puts this in the Week 1 week; do it before the lesson if the pen-B note is wanted for the scene table or a slide photo. | D27: 20 | E27: Week 3 (pens, answer key)
A28: 1 | B28: Year 8 | C28: Write the display note with pen B on plain white card (exact text, snowflake doodle after 'Sorry!'); photograph it for Slide 5 if wanted. | D28: 5 | E28: Week 3 Hook
A29: 1 | B29: Year 8 | C29: Put up the three A3 language posters, the A4 frame poster and the A3 scene map; put a frame card set and a role card set on each group table. | D29: 10 | E29: All term
A30: 2 | B30: Year 7 | C30: Make 12 mystery cups: one object in each opaque cup, second cup upside down on top (rim to rim), tape all round with masking tape, label A to L underneath; keep the key on the teacher desk | D30: 15 | E30: Kept in the teacher box for future years
A31: 2 | B31: Year 8 | C31: Order the kit on the outline's Buy list (Teacher Guide prep calendar, before Week 1): soft pencils 2B to 4B (24), clear sticky tape (6 rolls), A4 white card (12 sheets per class for the record cards) | D31: 10 | E31: Tape rolls reused in Week 3
A32: 2 | B32: Year 8 | C32: Kit card teacher prep, printing (Teacher Guide prep calendar, Week 1 row): print the fingerprint record cards on A4 white card, 2 per sheet (A5 landscape, single-sided), and cut in half: 12 sheets = 24 cards per class; print the Fingerprint File, 7 A4 single-sided copies per class (6 groups + 1 display). Check the scene print is clearly a loop but smudged at the centre and no pattern names are on the sheet (Case Bible Section 12: 10 minutes) | D32: 10 | E32: Record cards stay in the case files
A33: 2 | B33: Year 8 | C33: After the last class: return the magnifying glasses, trays and cloths to the prep room; keep the 6 tape rolls for Week 3 | D33: 3 | E33: Tape rolls reused in Week 3
... A65: 10 | B65: Year 7 | C65: Write three lines for next year's teacher: what worked, what to change (for example the trial result and sample thickness) and anything to buy earlier | D65: 10 | E65: Next year's Ice Engineers series
A67: 4. Separate the marking and admin from the prep
A68: Much of the time in Weeks 1, 5 and 10 is marking the skills checks and checkpoints, entering the tracker and putting kit away after the lesson, not getting ready for it.
C69: After the lesson (min, one class) | D69: =SUMIFS('Prep by week'!$E$19:$E$380,'Prep by week'!$C$19:$C$380,"After the lesson",'Prep by week'!$J$19:$J$380,"No") -> 1630
C70: Before the lesson (min, one class) | D70: =SUMIFS('Prep by week'!$E$19:$E$380,'Prep by week'!$C$19:$C$380,"<>After the lesson",'Prep by week'!$J$19:$J$380,"No") -> 1952
A72: 5. Drop or simplify the optional extras
A73: Optional tasks are not counted in the totals; skipping them costs nothing in the lesson plan.
C74: Optional extras (min, one class) | D74: =SUMIFS('Prep by week'!$E$19:$E$380,'Prep by week'!$J$19:$J$380,"Optional") -> 280
A76: 6. The heaviest lessons (one class, before and after the lesson, both freezer plans counted)
A77: Week | B77: Year | C77: Lesson | D77: Minutes
...
