Workbook

Sheet Read me
B1: Think Like a Scientist: science requisition, Weeks 1 to 10
B2: Years 7, 8 and 9. Quantities come from the kit card in every lesson file (Section 5), checked against the Teacher Guide prep calendar.
B4: Inputs (yellow cells: change these)
B5: Year 7 classes | C5: 1 | D5: Number of Year 7 classes taking the programme. Used-up items are multiplied by this.
B6: Year 8 classes | C6: 1 | D6: Number of Year 8 classes. Used-up items are multiplied by this.
B7: Year 9 classes | C7: 1 | D7: Number of Year 9 classes. Type 0 if Year 9 is not running this term.
B9: Freezer plan | C9: A and B | D9: Type A (freezer available), B (no freezer) or "A and B". Decide by Week 4. Leave "A and B" until then so both are costed; no Plan A or Plan B item is needed before Week 5.
B10: Other cells to fill in | D10: "Already have" on the Prep room check sheet (for example, type 6 if the prep room has 6 stopwatches; the shortfall updates), and the "Ordered" and "Received" columns on the Order list.
B12: How the quantities work
B13: • Quantities are for one class of up to 24 students in 6 groups, including the teacher demonstration and the spares the kit cards name.
B14: • Used-up items (salt, filter paper, card, tape) are added up across all ten weeks and multiplied by the number of classes, then rounded up.
B15: • Reusable items (stopwatches, measuring cylinders, goggles) show the most any one class needs at once. The year groups are taught at different times, so they share them. If two classes are ever taught at the same time, add their columns together.
B16: • Kept by class items (name cards, group folders, Year 9 role cards, Year 7 spinner envelopes) belong to one class for the series, so they are multiplied by the number of classes.
B17: • Weeks, not dates. "First needed" is the week an item must be in school; order it at least a week earlier.
B18: • Print jobs are not on the order list: worksheets, the Scientist's Logbook and the My Science Dictionary booklets go to reprographics (they are listed on the By week sheet). Card, laminating pouches, A3 and colour prints are included because they are stock to buy.
B19: • Weeks 7 and 8 depend on what each group chooses (Year 7 test plans, Year 8 test options, Year 9 claims). The list costs the maximum the kit cards allow; trim it once the choices are made in Week 7.
B20: • Chinese names are drafts for the purchasing team. Ask a colleague to check them before sending.
B22: The sheets
B23: • Order list: everything to buy (consumables, reusable items a science prep room would not usually have, stationery and card). This is the requisition.
B24: • Prep room check: standard school science equipment. Ask the technician to fill in "Already have"; add any shortfall to the requisition.
... B38: • Not on the kit cards but likely useful: reusable adhesive (Blu Tack) for posters, permanent markers and labels, a guillotine for cutting card sets, badge holders for the Year 8 expert witnesses.

Sheet Order list
A1: Item | B1: 中文名称（草稿） | C1: Specification | D1: Category | E1: Type | F1: Year 7 per class | G1: Year 8 per class | H1: Year 9 per class | I1: Quantity to order | J1: Unit | K1: First needed | L1: Weeks used | M1: Plan | N1: Safety and notes | O1: Ordered | P1: Received
A2: Plain bar soap | B2: 普通块状肥皂 | C2: Plain bar soap, not washing-up liquid (which is often close to neutral); 1 bar. | D2: Buy: used up | E2: Used up | F2: =ROUND('Data by week'!$AW$2*'Data by week'!$H$2,2) | G2: =ROUND('Data by week'!$AX$2*'Data by week'!$H$2,2) | H2: =ROUND('Data by week'!$AY$2*'Data by week'!$H$2,2) | I2: =ROUNDUP(F2*'Read me'!$C$5+G2*'Read me'!$C$6+H2*'Read me'!$C$7,0) | J2: teaspoon, grated | K2: Week 1 | L2: Year 8: W1, W5 | M2: Both plans | N2: Soap solution stings eyes: goggles when using it.
A3: White coffee filters (for chromatography strips) | B3: 白色咖啡滤纸（用于色谱滤纸条） | C3: White coffee-filter paper, cut into strips 2 cm x 10 cm. | D3: Buy: used up | E3: Used up | F3: =ROUND('Data by week'!$AW$3*'Data by week'!$H$3,2) | G3: =ROUND('Data by week'!$AX$3*'Data by week'!$H$3,2) | H3: =ROUND('Data by week'!$AY$3*'Data by week'!$H$3,2) | I3: =ROUNDUP(F3*'Read me'!$C$5+G3*'Read me'!$C$6+H3*'Read me'!$C$7,0) | J3: strips (2 cm x 10 cm) | K3: Week 1 | L3: Year 8: W1, W3, W7, W8 | M3: Both plans
A4: Cotton wool | B4: 棉花（脱脂棉） | C4: Sheet form for insulation squares; loose cotton wool or a cotton ball for the mystery cup and fibre. | D4: Buy: used up | E4: Used up | F4: =ROUND('Data by week'!$AW$4*'Data by week'!$H$4,2) | G4: =ROUND('Data by week'!$AX$4*'Data by week'!$H$4,2) | H4: =ROUND('Data by week'!$AY$4*'Data by week'!$H$4,2) | I4: =ROUNDUP(F4*'Read me'!$C$5+G4*'Read me'!$C$6+H4*'Read me'!$C$7,0) | J4: cotton ball | K4: Week 2 | L4: Year 7: W2 | M4: Both plans
A5: Paper cups, opaque | B5: 纸杯（不透明） | C5: Opaque paper cups for the mystery cups; small paper cups also hold pre-portioned fibre. | D5: Buy: used up | E5: Used up | F5: =ROUND('Data by week'!$AW$5*'Data by week'!$H$5,2) | G5: =ROUND('Data by week'!$AX$5*'Data by week'!$H$5,2) | H5: =ROUND('Data by week'!$AY$5*'Data by week'!$H$5,2) | I5: =ROUNDUP(F5*'Read me'!$C$5+G5*'Read me'!$C$6+H5*'Read me'!$C$7,0) | J5: cups | K5: Week 2 | L5: Year 7: W2, W7 | M5: Both plans
A6: Stirring sticks | B6: 搅拌棒（一次性） | C6: Disposable stirring sticks. | D6: Buy: used up | E6: Used up | F6: =ROUND('Data by week'!$AW$6*'Data by week'!$H$6,2) | G6: =ROUND('Data by week'!$AX$6*'Data by week'!$H$6,2) | H6: =ROUND('Data by week'!$AY$6*'Data by week'!$H$6,2) | I6: =ROUNDUP(F6*'Read me'!$C$5+G6*'Read me'!$C$6+H6*'Read me'!$C$7,0) | J6: sticks | K6: Week 4 | L6: Year 8: W4, W8 | M6: Both plans
A7: Zip-lock bags, small (sandwich size) | B7: 小号自封袋（三明治袋大小） | C7: Small resealable bags, sandwich size, that seal watertight; used for ice cubes, dough balls, spare fibre and as evidence bags. | D7: Buy: used up | E7: Used up | F7: =ROUND('Data by week'!$AW$7*'Data by week'!$H$7,2) | G7: =ROUND('Data by week'!$AX$7*'Data by week'!$H$7,2) | H7: =ROUND('Data by week'!$AY$7*'Data by week'!$H$7,2) | I7: =ROUNDUP(F7*'Read me'!$C$5+G7*'Read me'!$C$6+H7*'Read me'!$C$7,0) | J7: bags | K7: Week 4 | L7: Year 7: W6, W7; Year 8: W4, W7 | M7: Both plans | N7: Evidence bags stay sealed in Week 7: do not open, smell or taste. Plan B: knead dough inside the closed bag so flour dust stays in.
A8: Aluminium foil, kitchen roll | B8: 铝箔纸（厨房用） | C8: Kitchen foil roll; each trough uses a piece about 20 x 10 cm folded to double thickness. | D8: Buy: used up | E8: Used up | F8: =ROUND('Data by week'!$AW$8*'Data by week'!$H$8,2) | G8: =ROUND('Data by week'!$AX$8*'Data by week'!$H$8,2) | H8: =ROUND('Data by week'!$AY$8*'Data by week'!$H$8,2) | I8: =ROUNDUP(F8*'Read me'!$C$5+G8*'Read me'!$C$6+H8*'Read me'!$C$7,0) | J8: pieces | K8: Week 5 | L8: Year 7: W5, W6, W7 | M8: Both plans
A9: Bottled or purified water | B9: 纯净水（瓶装） | C9: Bottled or purified, not tap (tap water can be slightly alkaline). | D9: Buy: used up | E9: Used up | F9: =ROUND('Data by week'!$AW$9*'Data by week'!$H$9,2) | G9: =ROUND('Data by week'!$AX$9*'Data by week'!$H$9,2) | H9: =ROUND('Data by week'!$AY$9*'Data by week'!$H$9,2) | I9: =ROUNDUP(F9*'Read me'!$C$5+G9*'Read me'!$C$6+H9*'Read me'!$C$7,0) | J9: ml | K9: Week 5 | L9: Year 8: W5 | M9: Both plans | N9: No drinking any liquid in the practical.
A10: Cotton wool | B10: 棉花（脱脂棉） | C10: Sheet form for insulation squares; loose cotton wool or a cotton ball for the mystery cup and fibre. | D10: Buy: used up | E10: Used up | F10: =ROUND('Data by week'!$AW$10*'Data by week'!$H$10,2) | G10: =ROUND('Data by week'!$AX$10*'Data by week'!$H$10,2) | H10: =ROUND('Data by week'!$AY$10*'Data by week'!$H$10,2) | I10: =ROUNDUP(F10*'Read me'!$C$5+G10*'Read me'!$C$6+H10*'Read me'!$C$7,0) | J10: pieces | K10: Week 6 | L10: Year 7: W6 | M10: Both plans
A11: Disposable gloves | B11: 一次性手套 | C11: Disposable gloves, boxed (latex-free nitrile suggested); for handling ice, ice and salt mixture, and soil. | D11: Buy: used up | E11: Used up | F11: =ROUND('Data by week'!$AW$11*'Data by week'!$H$11+'Data by week'!$AW$18*'Data by week'!$H$18,2) | G11: =ROUND('Data by week'!$AX$11*'Data by week'!$H$11+'Data by week'!$AX$18*'Data by week'!$H$18,2) | H11: =ROUND('Data by week'!$AY$11*'Data by week'!$H$11+'Data by week'!$AY$18*'Data by week'!$H$18,2) | I11: =ROUNDUP(F11*'Read me'!$C$5+G11*'Read me'!$C$6+H11*'Read me'!$C$7,0) | J11: pairs | K11: Week 6 | L11: Year 7: W6, W8; Year 8: W8; Year 9: W6, W8 | M11: Both plans, Plan A (freezer) | N11: Soil can carry germs: cover cuts or wear gloves; do not touch face or mouth; wash hands with soap after. Wear gloves if you hold ice for more than a minute; peel strips with gloves on. Gloves go in the bin. Wear gloves whenever you handle the ice and salt mixture or salted ice. They are cold enough to hurt skin
A12: Freezer bags, strong | B12: 冷冻袋（加厚） | C12: Strong, clean freezer bags; one holds the notebook prop in the freezer, one is used to crush ice with a rolling pin. | D12: Buy: used up | E12: Used up | F12: =ROUND('Data by week'!$AW$12*'Data by week'!$H$12+'Data by week'!$AW$23*'Data by week'!$H$23,2) | G12: =ROUND('Data by week'!$AX$12*'Data by week'!$H$12+'Data by week'!$AX$23*'Data by week'!$H$23,2) | H12: =ROUND('Data by week'!$AY$12*'Data by week'!$H$12+'Data by week'!$AY$23*'Data by week'!$H$23,2) | I12: =ROUNDUP(F12*'Read me'!$C$5+G12*'Read me'!$C$6+H12*'Read me'!$C$7,0) | J12: bag | K12: Week 6 | L12: Year 8: W10; Year 9: W6, W8 | M12: Both plans, Plan A (freezer)
A13: Kitchen roll (shop-bought paper towels) | B13: 厨房纸（卷筒） | C13: Shop-bought kitchen roll, not the lab dispenser towels; for spills, and one sheet is Y8 paper reference P4. | D13: Buy: used up | E13: Used up | F13: =ROUND('Data by week'!$AW$13*'Data by week'!$H$13,2) | G13: =ROUND('Data by week'!$AX$13*'Data by week'!$H$13,2) | H13: =ROUND('Data by week'!$AY$13*'Data by week'!$H$13,2) | I13: =ROUNDUP(F13*'Read me'!$C$5+G13*'Read me'!$C$6+H13*'Read me'!$C$7,0) | J13: rolls | K13: Week 6 | L13: Year 7: W6, W7, W8; Year 8: W8; Year 9: W6, W8 | M13: Both plans | N13: Mop up spills straight away so no one slips. Wipe up spills at once: a wet floor is slippery
A14: Cotton wool | B14: 棉花（脱脂棉） | C14: Sheet form for insulation squares; loose cotton wool or a cotton ball for the mystery cup and fibre. | D14: Buy: used up | E14: Used up | F14: =ROUND('Data by week'!$AW$14*'Data by week'!$H$14,2) | G14: =ROUND('Data by week'!$AX$14*'Data by week'!$H$14,2) | H14: =ROUND('Data by week'!$AY$14*'Data by week'!$H$14,2) | I14: =ROUNDUP(F14*'Read me'!$C$5+G14*'Read me'!$C$6+H14*'Read me'!$C$7,0) | J14: g | K14: Week 7 | L14: Year 7: W7 | M14: Both plans
A15: Paper tissues (facial tissues) | B15: 面巾纸 | C15: Plain facial tissues; Y7 fibre (torn into 5 mm pieces) and Y8 paper reference P3. | D15: Buy: used up | E15: Used up | F15: =ROUND('Data by week'!$AW$15*'Data by week'!$H$15,2) | G15: =ROUND('Data by week'!$AX$15*'Data by week'!$H$15,2) | H15: =ROUND('Data by week'!$AY$15*'Data by week'!$H$15,2) | I15: =ROUNDUP(F15*'Read me'!$C$5+G15*'Read me'!$C$6+H15*'Read me'!$C$7,0) | J15: g | K15: Week 7 | L15: Year 7: W7 | M15: Both plans
A16: Sawdust, untreated natural wood | B16: 未经处理的木屑 | C16: Untreated natural wood sawdust or pet-bedding wood shavings only; never MDF dust (resin glues). One small bag. | D16: Buy: used up | E16: Used up | F16: =ROUND('Data by week'!$AW$16*'Data by week'!$H$16,2) | G16: =ROUND('Data by week'!$AX$16*'Data by week'!$H$16,2) | H16: =ROUND('Data by week'!$AY$16*'Data by week'!$H$16,2) | I16: =ROUNDUP(F16*'Read me'!$C$5+G16*'Read me'!$C$6+H16*'Read me'!$C$7,0) | J16: g | K16: Week 7 | L16: Year 7: W7 | M16: Both plans | N16: Untreated natural wood sawdust or pet-bedding shavings only, never MDF dust (contains resin glues). Keep it damp in a sealed bag; do not blow it or tip it from a height. Broken ice and sawdust go in the bin, not the sink (blocks drains). Store leftovers sealed and labelled 'untreated, not MDF'.
A17: Bags for soil samples, about 1 litre (holds about 2 cups of soil) | B17: 土壤采样袋（约1升） | C17: Labelled bags, each holding about 2 cups (about 500 ml) of soil with room to close the top. | D17: Buy: used up | E17: Used up | F17: =ROUND('Data by week'!$AW$17*'Data by week'!$H$17,2) | G17: =ROUND('Data by week'!$AX$17*'Data by week'!$H$17,2) | H17: =ROUND('Data by week'!$AY$17*'Data by week'!$H$17,2) | I17: =ROUNDUP(F17*'Read me'!$C$5+G17*'Read me'!$C$6+H17*'Read me'!$C$7,0) | J17: bags | K17: Week 8 | L17: Year 8: W8 | M17: Both plans
A18: Fizzy drink, small bottles | B18: 碳酸饮料（小瓶装） | C18: 4 identical small bottles of the same drink; bring to room temperature; never drunk. | D18: Buy: used up | E18: Used up | F18: =ROUND('Data by week'!$AW$19*'Data by week'!$H$19,2) | G18: =ROUND('Data by week'!$AX$19*'Data by week'!$H$19,2) | H18: =ROUND('Data by week'!$AY$19*'Data by week'!$H$19,2) | I18: =ROUNDUP(F18*'Read me'!$C$5+G18*'Read me'!$C$6+H18*'Read me'!$C$7,0) | J18: bottles | K18: Week 8 | L18: Year 9: W8 | M18: Both plans | N18: Never drink it and do not shake it. The teacher pours it away; the bottles go into recycling
A19: Flat sticks for levelling spoonfuls | B19: 刮平用扁木棒 | C19: Any flat stick that levels a tablespoon of soil. | D19: Buy: used up | E19: Used up | F19: =ROUND('Data by week'!$AW$20*'Data by week'!$H$20,2) | G19: =ROUND('Data by week'!$AX$20*'Data by week'!$H$20,2) | H19: =ROUND('Data by week'!$AY$20*'Data by week'!$H$20,2) | I19: =ROUNDUP(F19*'Read me'!$C$5+G19*'Read me'!$C$6+H19*'Read me'!$C$7,0) | J19: sticks | K19: Week 8 | L19: Year 8: W8 | M19: Both plans
A20: Paper tissues (facial tissues) | B20: 面巾纸 | C20: Plain facial tissues; Y7 fibre (torn into 5 mm pieces) and Y8 paper reference P3. | D20: Buy: used up | E20: Used up | F20: =ROUND('Data by week'!$AW$21*'Data by week'!$H$21,2) | G20: =ROUND('Data by week'!$AX$21*'Data by week'!$H$21,2) | H20: =ROUND('Data by week'!$AY$21*'Data by week'!$H$21,2) | I20: =ROUNDUP(F20*'Read me'!$C$5+G20*'Read me'!$C$6+H20*'Read me'!$C$7,0) | J20: tissues | K20: Week 8 | L20: Year 8: W8 | M20: Both plans
A21: Paper towels, three different brands | B21: 纸巾（3个不同品牌，各1卷或1包） | C21: One roll or pack of each of 3 brands; the teacher relabels them A, B and C and keeps the key. | D21: Buy: used up | E21: Used up | F21: =ROUND('Data by week'!$AW$22*'Data by week'!$H$22,2) | G21: =ROUND('Data by week'!$AX$22*'Data by week'!$H$22,2) | H21: =ROUND('Data by week'!$AY$22*'Data by week'!$H$22,2) | I21: =ROUNDUP(F21*'Read me'!$C$5+G21*'Read me'!$C$6+H21*'Read me'!$C$7,0) | J21: rolls (1 per brand) | K21: Week 8 | L21: Year 9: W8 | M21: Both plans | N21: Wipe up drips at once
A22: Black washable felt-tip pens, four different brands | B22: 黑色可水洗水彩笔（水性墨水，4个不同品牌） | C22: Black, washable (water-based) felt-tip pens from four different brands; not permanent markers. Cover brand names with masking tape and label A to D after the pre-test. | D22: Buy: reusable | E22: Reusable | F22: =ROUND(MAX(N('Data by week'!$I$24)*'Data by week'!$H$24,N('Data by week'!$J$24)*'Data by week'!$H$24,N('Data by week'!$K$24)*'Data by week'!$H$24,N('Data by week'!$L$24)*'Data by week'!$H$24,N('Data by week'!$M$24)*'Data by week'!$H$24,N('Data by week'!$N$24)*'Data by week'!$H$24,N('Data by week'!$O$24)*'Data by week'!$H$24,N('Data by week'!$P$24)*'Data by week'!$H$24,N('Data by week'!$Q$24)*'Data by week'!$H$24,N('Data by week'!$R$24)*'Data by week'!$H$24),2) | G22: =ROUND(MAX(N('Data by week'!$S$24)*'Data by week'!$H$24,N('Data by week'!$T$24)*'Data by week'!$H$24,N('Data by week'!$U$24)*'Data by week'!$H$24,N('Data by week'!$V$24)*'Data by week'!$H$24,N('Data by week'!$W$24)*'Data by week'!$H$24,N('Data by week'!$X$24)*'Data by week'!$H$24,N('Data by week'!$Y$24)*'Data by week'!$H$24,N('Data by week'!$Z$24)*'Data by week'!$H$24,N('Data by week'!$AA$24)*'Data by week'!$H$24,N('Data by week'!$AB$24)*'Data by week'!$H$24),2) | H22: =ROUND(MAX(N('Data by week'!$AC$24)*'Data by week'!$H$24,N('Data by week'!$AD$24)*'Data by week'!$H$24,N('Data by week'!$AE$24)*'Data by week'!$H$24,N('Data by week'!$AF$24)*'Data by week'!$H$24,N('Data by week'!$AG$24)*'Data by week'!$H$24,N('Data by week'!$AH$24)*'Data by week'!$H$24,N('Data by week'!$AI$24)*'Data by week'!$H$24,N('Data by week'!$AJ$24)*'Data by week'!$H$24,N('Data by week'!$AK$24)*'Data by week'!$H$24,N('Data by week'!$AL$24)*'Data by week'!$H$24),2) | I22: =MAX(F22:H22) | J22: pens | K22: Week 1 | L22: Year 8: W1, W3, W8 | M22: Both plans | N22: Ink stains clothes: keep caps on. Pen B never sits on a student table except as a labelled reference pen. Permanent markers will not work (ink does not move with water).
A23: Storage boxes, plastic with lid | B23: 带盖塑料收纳箱 | C23: Lidded storage boxes big enough for 24 A4 case files or logbooks; also the Y7 mystery-cup box and Ice Engineers kit box. | D23: Buy: reusable | E23: Reusable | F23: =ROUND(MAX(N('Data by week'!$I$25)*'Data by week'!$H$25,N('Data by week'!$J$25)*'Data by week'!$H$25,N('Data by week'!$K$25)*'Data by week'!$H$25,N('Data by week'!$L$25)*'Data by week'!$H$25,N('Data by week'!$M$25)*'Data by week'!$H$25,N('Data by week'!$N$25)*'Data by week'!$H$25,N('Data by week'!$O$25)*'Data by week'!$H$25,N('Data by week'!$P$25)*'Data by week'!$H$25,N('Data by week'!$Q$25)*'Data by week'!$H$25,N('Data by week'!$R$25)*'Data by week'!$H$25),2) | G23: =ROUND(MAX(N('Data by week'!$S$25)*'Data by week'!$H$25,N('Data by week'!$T$25)*'Data by week'!$H$25,N('Data by week'!$U$25)*'Data by week'!$H$25,N('Data by week'!$V$25)*'Data by week'!$H$25,N('Data by week'!$W$25)*'Data by week'!$H$25,N('Data by week'!$X$25)*'Data by week'!$H$25,N('Data by week'!$Y$25)*'Data by week'!$H$25,N('Data by week'!$Z$25)*'Data by week'!$H$25,N('Data by week'!$AA$25)*'Data by week'!$H$25,N('Data by week'!$AB$25)*'Data by week'!$H$25),2) | H23: =ROUND(MAX(N('Data by week'!$AC$25)*'Data by week'!$H$25,N('Data by week'!$AD$25)*'Data by week'!$H$25,N('Data by week'!$AE$25)*'Data by week'!$H$25,N('Data by week'!$AF$25)*'Data by week'!$H$25,N('Data by week'!$AG$25)*'Data by week'!$H$25,N('Data by week'!$AH$25)*'Data by week'!$H$25,N('Data by week'!$AI$25)*'Data by week'!$H$25,N('Data by week'!$AJ$25)*'Data by week'!$H$25,N('Data by week'!$AK$25)*'Data by week'!$H$25,N('Data by week'!$AL$25)*'Data by week'!$H$25),2) | I23: =MAX(F23:H23) | J23: boxes | K23: Week 1 | L23: Year 7: W1, W2, W10; Year 8: W1 | M23: Both plans
A24: Small lidded pots | B24: 带盖小样品盒 | C24: Small pots with lids, labelled. | D24: Buy: reusable | E24: Reusable | F24: =ROUND(MAX(N('Data by week'!$I$26)*'Data by week'!$H$26,N('Data by week'!$J$26)*'Data by week'!$H$26,N('Data by week'!$K$26)*'Data by week'!$H$26,N('Data by week'!$L$26)*'Data by week'!$H$26,N('Data by week'!$M$26)*'Data by week'!$H$26,N('Data by week'!$N$26)*'Data by week'!$H$26,N('Data by week'!$O$26)*'Data by week'!$H$26,N('Data by week'!$P$26)*'Data by week'!$H$26,N('Data by week'!$Q$26)*'Data by week'!$H$26,N('Data by week'!$R$26)*'Data by week'!$H$26),2) | G24: =ROUND(MAX(N('Data by week'!$S$26)*'Data by week'!$H$26,N('Data by week'!$T$26)*'Data by week'!$H$26,N('Data by week'!$U$26)*'Data by week'!$H$26,N('Data by week'!$V$26)*'Data by week'!$H$26,N('Data by week'!$W$26)*'Data by week'!$H$26,N('Data by week'!$X$26)*'Data by week'!$H$26,N('Data by week'!$Y$26)*'Data by week'!$H$26,N('Data by week'!$Z$26)*'Data by week'!$H$26,N('Data by week'!$AA$26)*'Data by week'!$H$26,N('Data by week'!$AB$26)*'Data by week'!$H$26),2) | H24: =ROUND(MAX(N('Data by week'!$AC$26)*'Data by week'!$H$26,N('Data by week'!$AD$26)*'Data by week'!$H$26,N('Data by week'!$AE$26)*'Data by week'!$H$26,N('Data by week'!$AF$26)*'Data by week'!$H$26,N('Data by week'!$AG$26)*'Data by week'!$H$26,N('Data by week'!$AH$26)*'Data by week'!$H$26,N('Data by week'!$AI$26)*'Data by week'!$H$26,N('Data by week'!$AJ$26)*'Data by week'!$H$26,N('Data by week'!$AK$26)*'Data by week'!$H$26,N('Data by week'!$AL$26)*'Data by week'!$H$26),2) | I24: =MAX(F24:H24) | J24: pots | K24: Week 4 | L24: Year 8: W4, W8 | M24: Both plans
A25: Ballpoint pens, identical | B25: 圆珠笔（同款同色） | C25: 24 identical pens: same model and colour, ideally new; check every one writes. Reused for raw data in later weeks. | D25: Buy: reusable | E25: Reusable | F25: =ROUND(MAX(N('Data by week'!$I$27)*'Data by week'!$H$27,N('Data by week'!$J$27)*'Data by week'!$H$27,N('Data by week'!$K$27)*'Data by week'!$H$27,N('Data by week'!$L$27)*'Data by week'!$H$27,N('Data by week'!$M$27)*'Data by week'!$H$27,N('Data by week'!$N$27)*'Data by week'!$H$27,N('Data by week'!$O$27)*'Data by week'!$H$27,N('Data by week'!$P$27)*'Data by week'!$H$27,N('Data by week'!$Q$27)*'Data by week'!$H$27,N('Data by week'!$R$27)*'Data by week'!$H$27),2) | G25: =ROUND(MAX(N('Data by week'!$S$27)*'Data by week'!$H$27,N('Data by week'!$T$27)*'Data by week'!$H$27,N('Data by week'!$U$27)*'Data by week'!$H$27,N('Data by week'!$V$27)*'Data by week'!$H$27,N('Data by week'!$W$27)*'Data by week'!$H$27,N('Data by week'!$X$27)*'Data by week'!$H$27,N('Data by week'!$Y$27)*'Data by week'!$H$27,N('Data by week'!$Z$27)*'Data by week'!$H$27,N('Data by week'!$AA$27)*'Data by week'!$H$27,N('Data by week'!$AB$27)*'Data by week'!$H$27),2) | H25: =ROUND(MAX(N('Data by week'!$AC$27)*'Data by week'!$H$27,N('Data by week'!$AD$27)*'Data by week'!$H$27,N('Data by week'!$AE$27)*'Data by week'!$H$27,N('Data by week'!$AF$27)*'Data by week'!$H$27,N('Data by week'!$AG$27)*'Data by week'!$H$27,N('Data by week'!$AH$27)*'Data by week'!$H$27,N('Data by week'!$AI$27)*'Data by week'!$H$27,N('Data by week'!$AJ$27)*'Data by week'!$H$27,N('Data by week'!$AK$27)*'Data by week'!$H$27,N('Data by week'!$AL$27)*'Data by week'!$H$27),2) | I25: =MAX(F25:H25) | J25: pens | K25: Week 5 | L25: Year 9: W5, W8, W9 | M25: Both plans | N25: Week 5 involves mild deception, so: explain the secret in the same lesson straight after the test; taking part is voluntary; any student may withdraw their score
A26: Cool box, insulated, with lid | B26: 保温箱（带盖） | C26: Insulated cool box with lid; big enough for 2 to 3 kg of ice or a group's flat tray of ice strips. | D26: Buy: reusable | E26: Reusable | F26: =ROUND(MAX(N('Data by week'!$I$28)*'Data by week'!$H$28,N('Data by week'!$J$28)*'Data by week'!$H$28,N('Data by week'!$K$28)*'Data by week'!$H$28,N('Data by week'!$L$28)*'Data by week'!$H$28,N('Data by week'!$M$28)*'Data by week'!$H$28,N('Data by week'!$N$28)*'Data by week'!$H$28,N('Data by week'!$O$28)*'Data by week'!$H$28,N('Data by week'!$P$28)*'Data by week'!$H$28,N('Data by week'!$Q$28)*'Data by week'!$H$28,N('Data by week'!$R$28)*'Data by week'!$H$28),2) | G26: =ROUND(MAX(N('Data by week'!$S$28)*'Data by week'!$H$28,N('Data by week'!$T$28)*'Data by week'!$H$28,N('Data by week'!$U$28)*'Data by week'!$H$28,N('Data by week'!$V$28)*'Data by week'!$H$28,N('Data by week'!$W$28)*'Data by week'!$H$28,N('Data by week'!$X$28)*'Data by week'!$H$28,N('Data by week'!$Y$28)*'Data by week'!$H$28,N('Data by week'!$Z$28)*'Data by week'!$H$28,N('Data by week'!$AA$28)*'Data by week'!$H$28,N('Data by week'!$AB$28)*'Data by week'!$H$28),2) | H26: =ROUND(MAX(N('Data by week'!$AC$28)*'Data by week'!$H$28,N('Data by week'!$AD$28)*'Data by week'!$H$28,N('Data by week'!$AE$28)*'Data by week'!$H$28,N('Data by week'!$AF$28)*'Data by week'!$H$28,N('Data by week'!$AG$28)*'Data by week'!$H$28,N('Data by week'!$AH$28)*'Data by week'!$H$28,N('Data by week'!$AI$28)*'Data by week'!$H$28,N('Data by week'!$AJ$28)*'Data by week'!$H$28,N('Data by week'!$AK$28)*'Data by week'!$H$28,N('Data by week'!$AL$28)*'Data by week'!$H$28),2) | I26: =MAX(F26:H26) | J26: boxes | K26: Week 6 | L26: Year 7: W6, W8; Year 9: W6, W8 | M26: Plan A (freezer)
A27: Height charts, paper, for the wall, 130 to 190 cm | B27: 纸质身高表（墙贴，130至190厘米） | C27: Wall height chart covering 130 to 190 cm. | D27: Buy: reusable | E27: Reusable | F27: =ROUND(MAX(N('Data by week'!$I$29)*'Data by week'!$H$29,N('Data by week'!$J$29)*'Data by week'!$H$29,N('Data by week'!$K$29)*'Data by week'!$H$29,N('Data by week'!$L$29)*'Data by week'!$H$29,N('Data by week'!$M$29)*'Data by week'!$H$29,N('Data by week'!$N$29)*'Data by week'!$H$29,N('Data by week'!$O$29)*'Data by week'!$H$29,N('Data by week'!$P$29)*'Data by week'!$H$29,N('Data by week'!$Q$29)*'Data by week'!$H$29,N('Data by week'!$R$29)*'Data by week'!$H$29),2) | G27: =ROUND(MAX(N('Data by week'!$S$29)*'Data by week'!$H$29,N('Data by week'!$T$29)*'Data by week'!$H$29,N('Data by week'!$U$29)*'Data by week'!$H$29,N('Data by week'!$V$29)*'Data by week'!$H$29,N('Data by week'!$W$29)*'Data by week'!$H$29,N('Data by week'!$X$29)*'Data by week'!$H$29,N('Data by week'!$Y$29)*'Data by week'!$H$29,N('Data by week'!$Z$29)*'Data by week'!$H$29,N('Data by week'!$AA$29)*'Data by week'!$H$29,N('Data by week'!$AB$29)*'Data by week'!$H$29),2) | H27: =ROUND(MAX(N('Data by week'!$AC$29)*'Data by week'!$H$29,N('Data by week'!$AD$29)*'Data by week'!$H$29,N('Data by week'!$AE$29)*'Data by week'!$H$29,N('Data by week'!$AF$29)*'Data by week'!$H$29,N('Data by week'!$AG$29)*'Data by week'!$H$29,N('Data by week'!$AH$29)*'Data by week'!$H$29,N('Data by week'!$AI$29)*'Data by week'!$H$29,N('Data by week'!$AJ$29)*'Data by week'!$H$29,N('Data by week'!$AK$29)*'Data by week'!$H$29,N('Data by week'!$AL$29)*'Data by week'!$H$29),2) | I27: =MAX(F27:H27) | J27: charts | K27: Week 6 | L27: Year 8: W6 | M27: Both plans | N27: Shoes off for measuring and under desks, not in walkways; no standing on chairs or tables; measuring is voluntary and data have numbers, not names.
A28: Ice-cube trays | B28: 冰格 | C28: Two of the same tray type. | D28: Buy: reusable | E28: Reusable | F28: =ROUND(MAX(N('Data by week'!$I$30)*'Data by week'!$H$30,N('Data by week'!$J$30)*'Data by week'!$H$30,N('Data by week'!$K$30)*'Data by week'!$H$30,N('Data by week'!$L$30)*'Data by week'!$H$30,N('Data by week'!$M$30)*'Data by week'!$H$30,N('Data by week'!$N$30)*'Data by week'!$H$30,N('Data by week'!$O$30)*'Data by week'!$H$30,N('Data by week'!$P$30)*'Data by week'!$H$30,N('Data by week'!$Q$30)*'Data by week'!$H$30,N('Data by week'!$R$30)*'Data by week'!$H$30),2) | G28: =ROUND(MAX(N('Data by week'!$S$30)*'Data by week'!$H$30,N('Data by week'!$T$30)*'Data by week'!$H$30,N('Data by week'!$U$30)*'Data by week'!$H$30,N('Data by week'!$V$30)*'Data by week'!$H$30,N('Data by week'!$W$30)*'Data by week'!$H$30,N('Data by week'!$X$30)*'Data by week'!$H$30,N('Data by week'!$Y$30)*'Data by week'!$H$30,N('Data by week'!$Z$30)*'Data by week'!$H$30,N('Data by week'!$AA$30)*'Data by week'!$H$30,N('Data by week'!$AB$30)*'Data by week'!$H$30),2) | H28: =ROUND(MAX(N('Data by week'!$AC$30)*'Data by week'!$H$30,N('Data by week'!$AD$30)*'Data by week'!$H$30,N('Data by week'!$AE$30)*'Data by week'!$H$30,N('Data by week'!$AF$30)*'Data by week'!$H$30,N('Data by week'!$AG$30)*'Data by week'!$H$30,N('Data by week'!$AH$30)*'Data by week'!$H$30,N('Data by week'!$AI$30)*'Data by week'!$H$30,N('Data by week'!$AJ$30)*'Data by week'!$H$30,N('Data by week'!$AK$30)*'Data by week'!$H$30,N('Data by week'!$AL$30)*'Data by week'!$H$30),2) | I28: =MAX(F28:H28) | J28: trays | K28: Week 6 | L28: Year 7: W6 | M28: Plan A (freezer)
A29: Polystyrene cups (insulated foam cups) | B29: 泡沫杯（聚苯乙烯，隔热） | C29: Insulated cup for the freezing mixture; two nested plastic cups will do instead. | D29: Buy: reusable | E29: Reusable | F29: =ROUND(MAX(N('Data by week'!$I$31)*'Data by week'!$H$31,N('Data by week'!$J$31)*'Data by week'!$H$31,N('Data by week'!$K$31)*'Data by week'!$H$31,N('Data by week'!$L$31)*'Data by week'!$H$31,N('Data by week'!$M$31)*'Data by week'!$H$31,N('Data by week'!$N$31)*'Data by week'!$H$31,N('Data by week'!$O$31)*'Data by week'!$H$31,N('Data by week'!$P$31)*'Data by week'!$H$31,N('Data by week'!$Q$31)*'Data by week'!$H$31,N('Data by week'!$R$31)*'Data by week'!$H$31),2) | G29: =ROUND(MAX(N('Data by week'!$S$31)*'Data by week'!$H$31,N('Data by week'!$T$31)*'Data by week'!$H$31,N('Data by week'!$U$31)*'Data by week'!$H$31,N('Data by week'!$V$31)*'Data by week'!$H$31,N('Data by week'!$W$31)*'Data by week'!$H$31,N('Data by week'!$X$31)*'Data by week'!$H$31,N('Data by week'!$Y$31)*'Data by week'!$H$31,N('Data by week'!$Z$31)*'Data by week'!$H$31,N('Data by week'!$AA$31)*'Data by week'!$H$31,N('Data by week'!$AB$31)*'Data by week'!$H$31),2) | H29: =ROUND(MAX(N('Data by week'!$AC$31)*'Data by week'!$H$31,N('Data by week'!$AD$31)*'Data by week'!$H$31,N('Data by week'!$AE$31)*'Data by week'!$H$31,N('Data by week'!$AF$31)*'Data by week'!$H$31,N('Data by week'!$AG$31)*'Data by week'!$H$31,N('Data by week'!$AH$31)*'Data by week'!$H$31,N('Data by week'!$AI$31)*'Data by week'!$H$31,N('Data by week'!$AJ$31)*'Data by week'!$H$31,N('Data by week'!$AK$31)*'Data by week'!$H$31,N('Data by week'!$AL$31)*'Data by week'!$H$31),2) | I29: =MAX(F29:H29) | J29: cups | K29: Week 6 | L29: Year 9: W6, W8 | M29: Plan A (freezer)
A30: Mini whiteboards | B30: 小白板（学生用） | C30: Mini whiteboards, 4 per group. | D30: Buy: reusable | E30: Reusable | F30: =ROUND(MAX(N('Data by week'!$I$32)*'Data by week'!$H$32,N('Data by week'!$J$32)*'Data by week'!$H$32,N('Data by week'!$K$32)*'Data by week'!$H$32,N('Data by week'!$L$32)*'Data by week'!$H$32,N('Data by week'!$M$32)*'Data by week'!$H$32,N('Data by week'!$N$32)*'Data by week'!$H$32,N('Data by week'!$O$32)*'Data by week'!$H$32,N('Data by week'!$P$32)*'Data by week'!$H$32,N('Data by week'!$Q$32)*'Data by week'!$H$32,N('Data by week'!$R$32)*'Data by week'!$H$32),2) | G30: =ROUND(MAX(N('Data by week'!$S$32)*'Data by week'!$H$32,N('Data by week'!$T$32)*'Data by week'!$H$32,N('Data by week'!$U$32)*'Data by week'!$H$32,N('Data by week'!$V$32)*'Data by week'!$H$32,N('Data by week'!$W$32)*'Data by week'!$H$32,N('Data by week'!$X$32)*'Data by week'!$H$32,N('Data by week'!$Y$32)*'Data by week'!$H$32,N('Data by week'!$Z$32)*'Data by week'!$H$32,N('Data by week'!$AA$32)*'Data by week'!$H$32,N('Data by week'!$AB$32)*'Data by week'!$H$32),2) | H30: =ROUND(MAX(N('Data by week'!$AC$32)*'Data by week'!$H$32,N('Data by week'!$AD$32)*'Data by week'!$H$32,N('Data by week'!$AE$32)*'Data by week'!$H$32,N('Data by week'!$AF$32)*'Data by week'!$H$32,N('Data by week'!$AG$32)*'Data by week'!$H$32,N('Data by week'!$AH$32)*'Data by week'!$H$32,N('Data by week'!$AI$32)*'Data by week'!$H$32,N('Data by week'!$AJ$32)*'Data by week'!$H$32,N('Data by week'!$AK$32)*'Data by week'!$H$32,N('Data by week'!$AL$32)*'Data by week'!$H$32),2) | I30: =MAX(F30:H30) | J30: boards | K30: Week 7 | L30: Year 8: W7 | M30: Both plans
A31: Waste bowl | B31: 废料盆 | C31: Plastic bowl, 1 per group. | D31: Buy: reusable | E31: Reusable | F31: =ROUND(MAX(N('Data by week'!$I$33)*'Data by week'!$H$33,N('Data by week'!$J$33)*'Data by week'!$H$33,N('Data by week'!$K$33)*'Data by week'!$H$33,N('Data by week'!$L$33)*'Data by week'!$H$33,N('Data by week'!$M$33)*'Data by week'!$H$33,N('Data by week'!$N$33)*'Data by week'!$H$33,N('Data by week'!$O$33)*'Data by week'!$H$33,N('Data by week'!$P$33)*'Data by week'!$H$33,N('Data by week'!$Q$33)*'Data by week'!$H$33,N('Data by week'!$R$33)*'Data by week'!$H$33),2) | G31: =ROUND(MAX(N('Data by week'!$S$33)*'Data by week'!$H$33,N('Data by week'!$T$33)*'Data by week'!$H$33,N('Data by week'!$U$33)*'Data by week'!$H$33,N('Data by week'!$V$33)*'Data by week'!$H$33,N('Data by week'!$W$33)*'Data by week'!$H$33,N('Data by week'!$X$33)*'Data by week'!$H$33,N('Data by week'!$Y$33)*'Data by week'!$H$33,N('Data by week'!$Z$33)*'Data by week'!$H$33,N('Data by week'!$AA$33)*'Data by week'!$H$33,N('Data by week'!$AB$33)*'Data by week'!$H$33),2) | H31: =ROUND(MAX(N('Data by week'!$AC$33)*'Data by week'!$H$33,N('Data by week'!$AD$33)*'Data by week'!$H$33,N('Data by week'!$AE$33)*'Data by week'!$H$33,N('Data by week'!$AF$33)*'Data by week'!$H$33,N('Data by week'!$AG$33)*'Data by week'!$H$33,N('Data by week'!$AH$33)*'Data by week'!$H$33,N('Data by week'!$AI$33)*'Data by week'!$H$33,N('Data by week'!$AJ$33)*'Data by week'!$H$33,N('Data by week'!$AK$33)*'Data by week'!$H$33,N('Data by week'!$AL$33)*'Data by week'!$H$33),2) | I31: =MAX(F31:H31) | J31: bowls | K31: Week 8 | L31: Year 7: W8 | M31: Both plans
A32: Bell, hand bell or desk bell (timing signal) | B32: 手摇铃或桌铃（计时提示用） | C32: Rung at 1 min 45 s in each 2-minute talk; a phone alarm will do instead. | D32: Buy: reusable | E32: Reusable | F32: =ROUND(MAX(N('Data by week'!$I$34)*'Data by week'!$H$34,N('Data by week'!$J$34)*'Data by week'!$H$34,N('Data by week'!$K$34)*'Data by week'!$H$34,N('Data by week'!$L$34)*'Data by week'!$H$34,N('Data by week'!$M$34)*'Data by week'!$H$34,N('Data by week'!$N$34)*'Data by week'!$H$34,N('Data by week'!$O$34)*'Data by week'!$H$34,N('Data by week'!$P$34)*'Data by week'!$H$34,N('Data by week'!$Q$34)*'Data by week'!$H$34,N('Data by week'!$R$34)*'Data by week'!$H$34),2) | G32: =ROUND(MAX(N('Data by week'!$S$34)*'Data by week'!$H$34,N('Data by week'!$T$34)*'Data by week'!$H$34,N('Data by week'!$U$34)*'Data by week'!$H$34,N('Data by week'!$V$34)*'Data by week'!$H$34,N('Data by week'!$W$34)*'Data by week'!$H$34,N('Data by week'!$X$34)*'Data by week'!$H$34,N('Data by week'!$Y$34)*'Data by week'!$H$34,N('Data by week'!$Z$34)*'Data by week'!$H$34,N('Data by week'!$AA$34)*'Data by week'!$H$34,N('Data by week'!$AB$34)*'Data by week'!$H$34),2) | H32: =ROUND(MAX(N('Data by week'!$AC$34)*'Data by week'!$H$34,N('Data by week'!$AD$34)*'Data by week'!$H$34,N('Data by week'!$AE$34)*'Data by week'!$H$34,N('Data by week'!$AF$34)*'Data by week'!$H$34,N('Data by week'!$AG$34)*'Data by week'!$H$34,N('Data by week'!$AH$34)*'Data by week'!$H$34,N('Data by week'!$AI$34)*'Data by week'!$H$34,N('Data by week'!$AJ$34)*'Data by week'!$H$34,N('Data by week'!$AK$34)*'Data by week'!$H$34,N('Data by week'!$AL$34)*'Data by week'!$H$34),2) | I32: =MAX(F32:H32) | J32: bell | K32: Week 10 | L32: Year 9: W10 | M32: Both plans
A33: A3 paper, white, 80 gsm | B33: A3复印纸（白色，80克） | C33: A3 white paper for black-and-white (greyscale) printing; some sheets printed on both sides (Y9 Week 9 report template). | D33: Stationery and card | E33: Used up | F33: =ROUND('Data by week'!$AW$35*'Data by week'!$H$35,2) | G33: =ROUND('Data by week'!$AX$35*'Data by week'!$H$35,2) | H33: =ROUND('Data by week'!$AY$35*'Data by week'!$H$35,2) | I33: =ROUNDUP(F33*'Read me'!$C$5+G33*'Read me'!$C$6+H33*'Read me'!$C$7,0) | J33: sheets | K33: Week 1 | L33: Year 7: W1, W2, W6, W7, W8, W9; Year 8: W1, W4, W5, W8, W9; Year 9: W1, W4, W6, W7, W9, W10 | M33: Both plans
A34: A4 folders for case files | B34: A4文件夹（案件档案用） | C34: A4 folder, 1 per student, to hold the case file pages. | D34: Stationery and card | E34: Used up | F34: =ROUND('Data by week'!$AW$36*'Data by week'!$H$36,2) | G34: =ROUND('Data by week'!$AX$36*'Data by week'!$H$36,2) | H34: =ROUND('Data by week'!$AY$36*'Data by week'!$H$36,2) | I34: =ROUNDUP(F34*'Read me'!$C$5+G34*'Read me'!$C$6+H34*'Read me'!$C$7,0) | J34: folders | K34: Week 1 | L34: Year 8: W1 | M34: Both plans
A35: Envelopes, C4 (for A4) | B35: C4信封（可平放A4纸） | C35: C4 or similar, large enough to hold A4 landscape cards or A4 papers flat. Also covers the 2 A4-size envelopes Y9 needs in Week 10. | D35: Stationery and card | E35: Reusable | F35: =ROUND(MAX(N('Data by week'!$I$37)*'Data by week'!$H$37,N('Data by week'!$J$37)*'Data by week'!$H$37,N('Data by week'!$K$37)*'Data by week'!$H$37,N('Data by week'!$L$37)*'Data by week'!$H$37,N('Data by week'!$M$37)*'Data by week'!$H$37,N('Data by week'!$N$37)*'Data by week'!$H$37,N('Data by week'!$O$37)*'Data by week'!$H$37,N('Data by week'!$P$37)*'Data by week'!$H$37,N('Data by week'!$Q$37)*'Data by week'!$H$37,N('Data by week'!$R$37)*'Data by week'!$H$37),2) | G35: =ROUND(MAX(N('Data by week'!$S$37)*'Data by week'!$H$37,N('Data by week'!$T$37)*'Data by week'!$H$37,N('Data by week'!$U$37)*'Data by week'!$H$37,N('Data by week'!$V$37)*'Data by week'!$H$37,N('Data by week'!$W$37)*'Data by week'!$H$37,N('Data by week'!$X$37)*'Data by week'!$H$37,N('Data by week'!$Y$37)*'Data by week'!$H$37,N('Data by week'!$Z$37)*'Data by week'!$H$37,N('Data by week'!$AA$37)*'Data by week'!$H$37,N('Data by week'!$AB$37)*'Data by week'!$H$37),2) | H35: =ROUND(MAX(N('Data by week'!$AC$37)*'Data by week'!$H$37,N('Data by week'!$AD$37)*'Data by week'!$H$37,N('Data by week'!$AE$37)*'Data by week'!$H$37,N('Data by week'!$AF$37)*'Data by week'!$H$37,N('Data by week'!$AG$37)*'Data by week'!$H$37,N('Data by week'!$AH$37)*'Data by week'!$H$37,N('Data by week'!$AI$37)*'Data by week'!$H$37,N('Data by week'!$AJ$37)*'Data by week'!$H$37,N('Data by week'!$AK$37)*'Data by week'!$H$37,N('Data by week'!$AL$37)*'Data by week'!$H$37),2) | I35: =MAX(F35:H35) | J35: envelopes | K35: Week 1 | L35: Year 7: W1 | M35: Both plans
A36: Envelopes, C6 (for small card sets) | B36: C6信封（可装A6及名片大小卡片） | C36: C6 (114 x 162 mm), big enough for a set of cards up to A6 or business-card size (8.5 x 5.5 cm). Write the group number or contents on each. Y9's 2 A4-size envelopes for Week 10 come from the C4 line. | D36: Stationery and card | E36: Reusable | F36: =ROUND(MAX(N('Data by week'!$I$38)*'Data by week'!$H$38,N('Data by week'!$J$38)*'Data by week'!$H$38,N('Data by week'!$K$38)*'Data by week'!$H$38,N('Data by week'!$L$38)*'Data by week'!$H$38,N('Data by week'!$M$38)*'Data by week'!$H$38,N('Data by week'!$N$38)*'Data by week'!$H$38,N('Data by week'!$O$38)*'Data by week'!$H$38,N('Data by week'!$P$38)*'Data by week'!$H$38,N('Data by week'!$Q$38)*'Data by week'!$H$38,N('Data by week'!$R$38)*'Data by week'!$H$38),2) | G36: =ROUND(MAX(N('Data by week'!$S$38)*'Data by week'!$H$38,N('Data by week'!$T$38)*'Data by week'!$H$38,N('Data by week'!$U$38)*'Data by week'!$H$38,N('Data by week'!$V$38)*'Data by week'!$H$38,N('Data by week'!$W$38)*'Data by week'!$H$38,N('Data by week'!$X$38)*'Data by week'!$H$38,N('Data by week'!$Y$38)*'Data by week'!$H$38,N('Data by week'!$Z$38)*'Data by week'!$H$38,N('Data by week'!$AA$38)*'Data by week'!$H$38,N('Data by week'!$AB$38)*'Data by week'!$H$38),2) | H36: =ROUND(MAX(N('Data by week'!$AC$38)*'Data by week'!$H$38,N('Data by week'!$AD$38)*'Data by week'!$H$38,N('Data by week'!$AE$38)*'Data by week'!$H$38,N('Data by week'!$AF$38)*'Data by week'!$H$38,N('Data by week'!$AG$38)*'Data by week'!$H$38,N('Data by week'!$AH$38)*'Data by week'!$H$38,N('Data by week'!$AI$38)*'Data by week'!$H$38,N('Data by week'!$AJ$38)*'Data by week'!$H$38,N('Data by week'!$AK$38)*'Data by week'!$H$38,N('Data by week'!$AL$38)*'Data by week'!$H$38),2) | I36: =MAX(F36:H36) | J36: envelopes | K36: Week 1 | L36: Year 7: W2; Year 9: W1, W2, W4, W7, W10 | M36: Both plans
A37: Group role cards (Year 9) | B37: 小组角色卡（九年级） | C37: Business-card size, one card per role (Lead Scientist, Measurer, Recorder, Safety Officer, Reporter); 1 set of 5 per group, stay on the tables all series. | D37: Stationery and card | E37: Kept by class | F37: =ROUND(MAX(N('Data by week'!$I$39)*'Data by week'!$H$39,N('Data by week'!$J$39)*'Data by week'!$H$39,N('Data by week'!$K$39)*'Data by week'!$H$39,N('Data by week'!$L$39)*'Data by week'!$H$39,N('Data by week'!$M$39)*'Data by week'!$H$39,N('Data by week'!$N$39)*'Data by week'!$H$39,N('Data by week'!$O$39)*'Data by week'!$H$39,N('Data by week'!$P$39)*'Data by week'!$H$39,N('Data by week'!$Q$39)*'Data by week'!$H$39,N('Data by week'!$R$39)*'Data by week'!$H$39),2) | G37: =ROUND(MAX(N('Data by week'!$S$39)*'Data by week'!$H$39,N('Data by week'!$T$39)*'Data by week'!$H$39,N('Data by week'!$U$39)*'Data by week'!$H$39,N('Data by week'!$V$39)*'Data by week'!$H$39,N('Data by week'!$W$39)*'Data by week'!$H$39,N('Data by week'!$X$39)*'Data by week'!$H$39,N('Data by week'!$Y$39)*'Data by week'!$H$39,N('Data by week'!$Z$39)*'Data by week'!$H$39,N('Data by week'!$AA$39)*'Data by week'!$H$39,N('Data by week'!$AB$39)*'Data by week'!$H$39),2) | H37: =ROUND(MAX(N('Data by week'!$AC$39)*'Data by week'!$H$39,N('Data by week'!$AD$39)*'Data by week'!$H$39,N('Data by week'!$AE$39)*'Data by week'!$H$39,N('Data by week'!$AF$39)*'Data by week'!$H$39,N('Data by week'!$AG$39)*'Data by week'!$H$39,N('Data by week'!$AH$39)*'Data by week'!$H$39,N('Data by week'!$AI$39)*'Data by week'!$H$39,N('Data by week'!$AJ$39)*'Data by week'!$H$39,N('Data by week'!$AK$39)*'Data by week'!$H$39,N('Data by week'!$AL$39)*'Data by week'!$H$39),2) | I37: =ROUNDUP(F37*'Read me'!$C$5+G37*'Read me'!$C$6+H37*'Read me'!$C$7,0) | J37: sets of 5 | K37: Week 1 | L37: Year 9: W1 | M37: Both plans
A38: Laminating pouches, A3 | B38: 塑封膜 A3 | C38: A3 laminating pouches for the school laminator (laminate 'if possible'). | D38: Stationery and card | E38: Used up | F38: =ROUND('Data by week'!$AW$40*'Data by week'!$H$40,2) | G38: =ROUND('Data by week'!$AX$40*'Data by week'!$H$40,2) | H38: =ROUND('Data by week'!$AY$40*'Data by week'!$H$40,2) | I38: =ROUNDUP(F38*'Read me'!$C$5+G38*'Read me'!$C$6+H38*'Read me'!$C$7,0) | J38: pouches | K38: Week 1 | L38: Year 7: W6, W7; Year 9: W1 | M38: Both plans
A39: Laminating pouches, A4 | B39: 塑封膜 A4 | C39: A4 laminating pouches for the school laminator. | D39: Stationery and card | E39: Used up | F39: =ROUND('Data by week'!$AW$41*'Data by week'!$H$41,2) | G39: =ROUND('Data by week'!$AX$41*'Data by week'!$H$41,2) | H39: =ROUND('Data by week'!$AY$41*'Data by week'!$H$41,2) | I39: =ROUNDUP(F39*'Read me'!$C$5+G39*'Read me'!$C$6+H39*'Read me'!$C$7,0) | J39: pouches | K39: Week 1 | L39: Year 7: W1, W8, W9; Year 8: W1, W7; Year 9: W8 | M39: Both plans
A40: Laminating pouches, A5 | B40: 塑封膜 A5 | C40: A5 laminating pouches for the school laminator. | D40: Stationery and card | E40: Used up | F40: =ROUND('Data by week'!$AW$42*'Data by week'!$H$42,2) | G40: =ROUND('Data by week'!$AX$42*'Data by week'!$H$42,2) | H40: =ROUND('Data by week'!$AY$42*'Data by week'!$H$42,2) | I40: =ROUNDUP(F40*'Read me'!$C$5+G40*'Read me'!$C$6+H40*'Read me'!$C$7,0) | J40: pouches | K40: Week 1 | L40: Year 7: W1, W4, W8; Year 8: W1, W3, W4, W5, W6; Year 9: W3, W5, W6, W8, W9 | M40: Both plans
...

Sheet Prep room check
A1: Item | B1: 中文名称（草稿） | C1: Specification | D1: Type | E1: Most needed at once | F1: Unit | G1: First needed | H1: Weeks used | I1: Plan | J1: Already have | K1: Shortfall to order | L1: Safety and notes
A2: Plastic cups, small, clear | B2: 透明小塑料杯 | C2: Small clear plastic cups (or small beakers) so colour and cloudiness can be seen. | D2: Reusable | E2: =MAX(MAX(N('Data by week'!$I$72)*'Data by week'!$H$72,N('Data by week'!$J$72)*'Data by week'!$H$72,N('Data by week'!$K$72)*'Data by week'!$H$72,N('Data by week'!$L$72)*'Data by week'!$H$72,N('Data by week'!$M$72)*'Data by week'!$H$72,N('Data by week'!$N$72)*'Data by week'!$H$72,N('Data by week'!$O$72)*'Data by week'!$H$72,N('Data by week'!$P$72)*'Data by week'!$H$72,N('Data by week'!$Q$72)*'Data by week'!$H$72,N('Data by week'!$R$72)*'Data by week'!$H$72),MAX(N('Data by week'!$S$72)*'Data by week'!$H$72,N('Data by week'!$T$72)*'Data by week'!$H$72,N('Data by week'!$U$72)*'Data by week'!$H$72,N('Data by week'!$V$72)*'Data by week'!$H$72,N('Data by week'!$W$72)*'Data by week'!$H$72,N('Data by week'!$X$72)*'Data by week'!$H$72,N('Data by week'!$Y$72)*'Data by week'!$H$72,N('Data by week'!$Z$72)*'Data by week'!$H$72,N('Data by week'!$AA$72)*'Data by week'!$H$72,N('Data by week'!$AB$72)*'Data by week'!$H$72),MAX(N('Data by week'!$AC$72)*'Data by week'!$H$72,N('Data by week'!$AD$72)*'Data by week'!$H$72,N('Data by week'!$AE$72)*'Data by week'!$H$72,N('Data by week'!$AF$72)*'Data by week'!$H$72,N('Data by week'!$AG$72)*'Data by week'!$H$72,N('Data by week'!$AH$72)*'Data by week'!$H$72,N('Data by week'!$AI$72)*'Data by week'!$H$72,N('Data by week'!$AJ$72)*'Data by week'!$H$72,N('Data by week'!$AK$72)*'Data by week'!$H$72,N('Data by week'!$AL$72)*'Data by week'!$H$72)) | F2: cups | G2: Week 1 | H2: Year 8: W1, W3, W4, W5, W8 | I2: Both plans | K2: =MAX(0,E2-N(J2)) | L2: Do not drink from any cup. Rinse to reuse, or recycle.
A3: Trays, flat (kit trays) | B3: 托盘（平底） | C3: Flat kit trays, 1 per group; must hold 9 foil troughs (or cups of water) and fit flat in the freezer drawer; one dark tray for the optional Y8 scene table. | D3: Reusable | E3: =MAX(MAX(N('Data by week'!$I$73)*'Data by week'!$H$73,N('Data by week'!$J$73)*'Data by week'!$H$73,N('Data by week'!$K$73)*'Data by week'!$H$73,N('Data by week'!$L$73)*'Data by week'!$H$73,N('Data by week'!$M$73)*'Data by week'!$H$73,N('Data by week'!$N$73)*'Data by week'!$H$73,N('Data by week'!$O$73)*'Data by week'!$H$73,N('Data by week'!$P$73)*'Data by week'!$H$73,N('Data by week'!$Q$73)*'Data by week'!$H$73,N('Data by week'!$R$73)*'Data by week'!$H$73),MAX(N('Data by week'!$S$73)*'Data by week'!$H$73,N('Data by week'!$T$73)*'Data by week'!$H$73,N('Data by week'!$U$73)*'Data by week'!$H$73,N('Data by week'!$V$73)*'Data by week'!$H$73,N('Data by week'!$W$73)*'Data by week'!$H$73,N('Data by week'!$X$73)*'Data by week'!$H$73,N('Data by week'!$Y$73)*'Data by week'!$H$73,N('Data by week'!$Z$73)*'Data by week'!$H$73,N('Data by week'!$AA$73)*'Data by week'!$H$73,N('Data by week'!$AB$73)*'Data by week'!$H$73),MAX(N('Data by week'!$AC$73)*'Data by week'!$H$73,N('Data by week'!$AD$73)*'Data by week'!$H$73,N('Data by week'!$AE$73)*'Data by week'!$H$73,N('Data by week'!$AF$73)*'Data by week'!$H$73,N('Data by week'!$AG$73)*'Data by week'!$H$73,N('Data by week'!$AH$73)*'Data by week'!$H$73,N('Data by week'!$AI$73)*'Data by week'!$H$73,N('Data by week'!$AJ$73)*'Data by week'!$H$73,N('Data by week'!$AK$73)*'Data by week'!$H$73,N('Data by week'!$AL$73)*'Data by week'!$H$73)) | F3: trays | G3: Week 1 | H3: Year 7: W3, W4, W6, W7, W8; Year 8: W1, W2, W3, W4, W5, W6, W8; Year 9: W6, W8 | I3: Both plans | K3: =MAX(0,E3-N(J3)) | L3: Cups of warm water stay on the tray Only the teacher carries the sample trays and puts them in the freezer; keep them flat and level.
A4: Calculator, basic | B4: 计算器（简易型） | C4: Basic calculator, 1 per group. | D4: Reusable | E4: =MAX(MAX(N('Data by week'!$I$74)*'Data by week'!$H$74,N('Data by week'!$J$74)*'Data by week'!$H$74,N('Data by week'!$K$74)*'Data by week'!$H$74,N('Data by week'!$L$74)*'Data by week'!$H$74,N('Data by week'!$M$74)*'Data by week'!$H$74,N('Data by week'!$N$74)*'Data by week'!$H$74,N('Data by week'!$O$74)*'Data by week'!$H$74,N('Data by week'!$P$74)*'Data by week'!$H$74,N('Data by week'!$Q$74)*'Data by week'!$H$74,N('Data by week'!$R$74)*'Data by week'!$H$74),MAX(N('Data by week'!$S$74)*'Data by week'!$H$74,N('Data by week'!$T$74)*'Data by week'!$H$74,N('Data by week'!$U$74)*'Data by week'!$H$74,N('Data by week'!$V$74)*'Data by week'!$H$74,N('Data by week'!$W$74)*'Data by week'!$H$74,N('Data by week'!$X$74)*'Data by week'!$H$74,N('Data by week'!$Y$74)*'Data by week'!$H$74,N('Data by week'!$Z$74)*'Data by week'!$H$74,N('Data by week'!$AA$74)*'Data by week'!$H$74,N('Data by week'!$AB$74)*'Data by week'!$H$74),MAX(N('Data by week'!$AC$74)*'Data by week'!$H$74,N('Data by week'!$AD$74)*'Data by week'!$H$74,N('Data by week'!$AE$74)*'Data by week'!$H$74,N('Data by week'!$AF$74)*'Data by week'!$H$74,N('Data by week'!$AG$74)*'Data by week'!$H$74,N('Data by week'!$AH$74)*'Data by week'!$H$74,N('Data by week'!$AI$74)*'Data by week'!$H$74,N('Data by week'!$AJ$74)*'Data by week'!$H$74,N('Data by week'!$AK$74)*'Data by week'!$H$74,N('Data by week'!$AL$74)*'Data by week'!$H$74)) | F4: calculators | G4: Week 2 | H4: Year 9: W2, W3, W9 | I4: Both plans | K4: =MAX(0,E4-N(J4))
A5: Cloths for wiping tables | B5: 抹布 | C5: Damp cloths for wiping tables, about 1 per group, plus a teacher spare for spills. | D5: Reusable | E5: =MAX(MAX(N('Data by week'!$I$75)*'Data by week'!$H$75+N('Data by week'!$I$102)*'Data by week'!$H$102,N('Data by week'!$J$75)*'Data by week'!$H$75+N('Data by week'!$J$102)*'Data by week'!$H$102,N('Data by week'!$K$75)*'Data by week'!$H$75+N('Data by week'!$K$102)*'Data by week'!$H$102,N('Data by week'!$L$75)*'Data by week'!$H$75+N('Data by week'!$L$102)*'Data by week'!$H$102,N('Data by week'!$M$75)*'Data by week'!$H$75+N('Data by week'!$M$102)*'Data by week'!$H$102,N('Data by week'!$N$75)*'Data by week'!$H$75+N('Data by week'!$N$102)*'Data by week'!$H$102,N('Data by week'!$O$75)*'Data by week'!$H$75+N('Data by week'!$O$102)*'Data by week'!$H$102,N('Data by week'!$P$75)*'Data by week'!$H$75+N('Data by week'!$P$102)*'Data by week'!$H$102,N('Data by week'!$Q$75)*'Data by week'!$H$75+N('Data by week'!$Q$102)*'Data by week'!$H$102,N('Data by week'!$R$75)*'Data by week'!$H$75+N('Data by week'!$R$102)*'Data by week'!$H$102),MAX(N('Data by week'!$S$75)*'Data by week'!$H$75+N('Data by week'!$S$102)*'Data by week'!$H$102,N('Data by week'!$T$75)*'Data by week'!$H$75+N('Data by week'!$T$102)*'Data by week'!$H$102,N('Data by week'!$U$75)*'Data by week'!$H$75+N('Data by week'!$U$102)*'Data by week'!$H$102,N('Data by week'!$V$75)*'Data by week'!$H$75+N('Data by week'!$V$102)*'Data by week'!$H$102,N('Data by week'!$W$75)*'Data by week'!$H$75+N('Data by week'!$W$102)*'Data by week'!$H$102,N('Data by week'!$X$75)*'Data by week'!$H$75+N('Data by week'!$X$102)*'Data by week'!$H$102,N('Data by week'!$Y$75)*'Data by week'!$H$75+N('Data by week'!$Y$102)*'Data by week'!$H$102,N('Data by week'!$Z$75)*'Data by week'!$H$75+N('Data by week'!$Z$102)*'Data by week'!$H$102,N('Data by week'!$AA$75)*'Data by week'!$H$75+N('Data by week'!$AA$102)*'Data by week'!$H$102,N('Data by week'!$AB$75)*'Data by week'!$H$75+N('Data by week'!$AB$102)*'Data by week'!$H$102),MAX(N('Data by week'!$AC$75)*'Data by week'!$H$75+N('Data by week'!$AC$102)*'Data by week'!$H$102,N('Data by week'!$AD$75)*'Data by week'!$H$75+N('Data by week'!$AD$102)*'Data by week'!$H$102,N('Data by week'!$AE$75)*'Data by week'!$H$75+N('Data by week'!$AE$102)*'Data by week'!$H$102,N('Data by week'!$AF$75)*'Data by week'!$H$75+N('Data by week'!$AF$102)*'Data by week'!$H$102,N('Data by week'!$AG$75)*'Data by week'!$H$75+N('Data by week'!$AG$102)*'Data by week'!$H$102,N('Data by week'!$AH$75)*'Data by week'!$H$75+N('Data by week'!$AH$102)*'Data by week'!$H$102,N('Data by week'!$AI$75)*'Data by week'!$H$75+N('Data by week'!$AI$102)*'Data by week'!$H$102,N('Data by week'!$AJ$75)*'Data by week'!$H$75+N('Data by week'!$AJ$102)*'Data by week'!$H$102,N('Data by week'!$AK$75)*'Data by week'!$H$75+N('Data by week'!$AK$102)*'Data by week'!$H$102,N('Data by week'!$AL$75)*'Data by week'!$H$75+N('Data by week'!$AL$102)*'Data by week'!$H$102)) | F5: cloths | G5: Week 2 | H5: Year 7: W7; Year 8: W2, W3, W4, W5, W8; Year 9: W8 | I5: Both plans, Plan B (no freezer) | K5: =MAX(0,E5-N(J5)) | L5: Wipe up spills at once Wipe up spills straight away.
A6: Magnifying glasses, hand-held | B6: 放大镜（手持） | C6: Hand magnifiers. | D6: Reusable | E6: =MAX(MAX(N('Data by week'!$I$76)*'Data by week'!$H$76,N('Data by week'!$J$76)*'Data by week'!$H$76,N('Data by week'!$K$76)*'Data by week'!$H$76,N('Data by week'!$L$76)*'Data by week'!$H$76,N('Data by week'!$M$76)*'Data by week'!$H$76,N('Data by week'!$N$76)*'Data by week'!$H$76,N('Data by week'!$O$76)*'Data by week'!$H$76,N('Data by week'!$P$76)*'Data by week'!$H$76,N('Data by week'!$Q$76)*'Data by week'!$H$76,N('Data by week'!$R$76)*'Data by week'!$H$76),MAX(N('Data by week'!$S$76)*'Data by week'!$H$76,N('Data by week'!$T$76)*'Data by week'!$H$76,N('Data by week'!$U$76)*'Data by week'!$H$76,N('Data by week'!$V$76)*'Data by week'!$H$76,N('Data by week'!$W$76)*'Data by week'!$H$76,N('Data by week'!$X$76)*'Data by week'!$H$76,N('Data by week'!$Y$76)*'Data by week'!$H$76,N('Data by week'!$Z$76)*'Data by week'!$H$76,N('Data by week'!$AA$76)*'Data by week'!$H$76,N('Data by week'!$AB$76)*'Data by week'!$H$76),MAX(N('Data by week'!$AC$76)*'Data by week'!$H$76,N('Data by week'!$AD$76)*'Data by week'!$H$76,N('Data by week'!$AE$76)*'Data by week'!$H$76,N('Data by week'!$AF$76)*'Data by week'!$H$76,N('Data by week'!$AG$76)*'Data by week'!$H$76,N('Data by week'!$AH$76)*'Data by week'!$H$76,N('Data by week'!$AI$76)*'Data by week'!$H$76,N('Data by week'!$AJ$76)*'Data by week'!$H$76,N('Data by week'!$AK$76)*'Data by week'!$H$76,N('Data by week'!$AL$76)*'Data by week'!$H$76)) | F6: magnifiers | G6: Week 2 | H6: Year 8: W2, W4, W8 | I6: Both plans | K6: =MAX(0,E6-N(J6))
A7: Paper towels, the lab's own dispenser roll | B7: 实验室纸巾（水槽抽取式擦手纸） | C7: The lab's own sink-dispenser paper towels; reference P1 and Evidence 7 must both come from the same roll. | D7: Used up | E7: =ROUNDUP(('Data by week'!$AW$77*'Data by week'!$H$77)*'Read me'!$C$5+('Data by week'!$AX$77*'Data by week'!$H$77)*'Read me'!$C$6+('Data by week'!$AY$77*'Data by week'!$H$77)*'Read me'!$C$7,0) | F7: sheets | G7: Week 2 | H7: Year 8: W2, W3, W4, W5, W7, W8 | I7: Both plans | K7: =MAX(0,E7-N(J7)) | L7: P1 and Evidence 7 must come from the lab's own roll, or the Week 8 result will not match the Case Bible.
A8: Ruler, 30 cm | B8: 直尺 30厘米 | C8: 30 cm, marked in mm, with the 0 cm mark at the very end (Y9 ruler drop). | D8: Reusable | E8: =MAX(MAX(N('Data by week'!$I$78)*'Data by week'!$H$78,N('Data by week'!$J$78)*'Data by week'!$H$78,N('Data by week'!$K$78)*'Data by week'!$H$78,N('Data by week'!$L$78)*'Data by week'!$H$78,N('Data by week'!$M$78)*'Data by week'!$H$78,N('Data by week'!$N$78)*'Data by week'!$H$78,N('Data by week'!$O$78)*'Data by week'!$H$78,N('Data by week'!$P$78)*'Data by week'!$H$78,N('Data by week'!$Q$78)*'Data by week'!$H$78,N('Data by week'!$R$78)*'Data by week'!$H$78),MAX(N('Data by week'!$S$78)*'Data by week'!$H$78,N('Data by week'!$T$78)*'Data by week'!$H$78,N('Data by week'!$U$78)*'Data by week'!$H$78,N('Data by week'!$V$78)*'Data by week'!$H$78,N('Data by week'!$W$78)*'Data by week'!$H$78,N('Data by week'!$X$78)*'Data by week'!$H$78,N('Data by week'!$Y$78)*'Data by week'!$H$78,N('Data by week'!$Z$78)*'Data by week'!$H$78,N('Data by week'!$AA$78)*'Data by week'!$H$78,N('Data by week'!$AB$78)*'Data by week'!$H$78),MAX(N('Data by week'!$AC$78)*'Data by week'!$H$78,N('Data by week'!$AD$78)*'Data by week'!$H$78,N('Data by week'!$AE$78)*'Data by week'!$H$78,N('Data by week'!$AF$78)*'Data by week'!$H$78,N('Data by week'!$AG$78)*'Data by week'!$H$78,N('Data by week'!$AH$78)*'Data by week'!$H$78,N('Data by week'!$AI$78)*'Data by week'!$H$78,N('Data by week'!$AJ$78)*'Data by week'!$H$78,N('Data by week'!$AK$78)*'Data by week'!$H$78,N('Data by week'!$AL$78)*'Data by week'!$H$78)) | F8: rulers | G8: Week 2 | H8: Year 7: W5, W8, W9; Year 8: W3, W6, W8; Year 9: W2, W3, W4, W8, W9 | I8: Both plans | K8: =MAX(0,E8-N(J8)) | L8: Carry rulers safely; do not wave them near faces. Week 3: a flicked or swung ruler can hit faces or fingers. Hold it upright and still, sit for every test, and keep your face back from the falling ruler
A9: Metre stick | B9: 米尺（1米） | C9: 1 m stick marked in cm (Y8: a tape measure will do). | D9: Reusable | E9: =MAX(MAX(N('Data by week'!$I$79)*'Data by week'!$H$79,N('Data by week'!$J$79)*'Data by week'!$H$79,N('Data by week'!$K$79)*'Data by week'!$H$79,N('Data by week'!$L$79)*'Data by week'!$H$79,N('Data by week'!$M$79)*'Data by week'!$H$79,N('Data by week'!$N$79)*'Data by week'!$H$79,N('Data by week'!$O$79)*'Data by week'!$H$79,N('Data by week'!$P$79)*'Data by week'!$H$79,N('Data by week'!$Q$79)*'Data by week'!$H$79,N('Data by week'!$R$79)*'Data by week'!$H$79),MAX(N('Data by week'!$S$79)*'Data by week'!$H$79,N('Data by week'!$T$79)*'Data by week'!$H$79,N('Data by week'!$U$79)*'Data by week'!$H$79,N('Data by week'!$V$79)*'Data by week'!$H$79,N('Data by week'!$W$79)*'Data by week'!$H$79,N('Data by week'!$X$79)*'Data by week'!$H$79,N('Data by week'!$Y$79)*'Data by week'!$H$79,N('Data by week'!$Z$79)*'Data by week'!$H$79,N('Data by week'!$AA$79)*'Data by week'!$H$79,N('Data by week'!$AB$79)*'Data by week'!$H$79),MAX(N('Data by week'!$AC$79)*'Data by week'!$H$79,N('Data by week'!$AD$79)*'Data by week'!$H$79,N('Data by week'!$AE$79)*'Data by week'!$H$79,N('Data by week'!$AF$79)*'Data by week'!$H$79,N('Data by week'!$AG$79)*'Data by week'!$H$79,N('Data by week'!$AH$79)*'Data by week'!$H$79,N('Data by week'!$AI$79)*'Data by week'!$H$79,N('Data by week'!$AJ$79)*'Data by week'!$H$79,N('Data by week'!$AK$79)*'Data by week'!$H$79,N('Data by week'!$AL$79)*'Data by week'!$H$79)) | F9: metre sticks | G9: Week 3 | H9: Year 7: W3, W4; Year 8: W6 | I9: Both plans | K9: =MAX(0,E9-N(J9)) | L9: Hold metre sticks upright and close to the wall; do not swing them. Retract tape measures slowly. Never stand on chairs or tables; the Dropper stands flat on the floor.
A10: Scissors | B10: 剪刀 | C10: Student scissors. | D10: Reusable | E10: =MAX(MAX(N('Data by week'!$I$80)*'Data by week'!$H$80,N('Data by week'!$J$80)*'Data by week'!$H$80,N('Data by week'!$K$80)*'Data by week'!$H$80,N('Data by week'!$L$80)*'Data by week'!$H$80,N('Data by week'!$M$80)*'Data by week'!$H$80,N('Data by week'!$N$80)*'Data by week'!$H$80,N('Data by week'!$O$80)*'Data by week'!$H$80,N('Data by week'!$P$80)*'Data by week'!$H$80,N('Data by week'!$Q$80)*'Data by week'!$H$80,N('Data by week'!$R$80)*'Data by week'!$H$80),MAX(N('Data by week'!$S$80)*'Data by week'!$H$80,N('Data by week'!$T$80)*'Data by week'!$H$80,N('Data by week'!$U$80)*'Data by week'!$H$80,N('Data by week'!$V$80)*'Data by week'!$H$80,N('Data by week'!$W$80)*'Data by week'!$H$80,N('Data by week'!$X$80)*'Data by week'!$H$80,N('Data by week'!$Y$80)*'Data by week'!$H$80,N('Data by week'!$Z$80)*'Data by week'!$H$80,N('Data by week'!$AA$80)*'Data by week'!$H$80,N('Data by week'!$AB$80)*'Data by week'!$H$80),MAX(N('Data by week'!$AC$80)*'Data by week'!$H$80,N('Data by week'!$AD$80)*'Data by week'!$H$80,N('Data by week'!$AE$80)*'Data by week'!$H$80,N('Data by week'!$AF$80)*'Data by week'!$H$80,N('Data by week'!$AG$80)*'Data by week'!$H$80,N('Data by week'!$AH$80)*'Data by week'!$H$80,N('Data by week'!$AI$80)*'Data by week'!$H$80,N('Data by week'!$AJ$80)*'Data by week'!$H$80,N('Data by week'!$AK$80)*'Data by week'!$H$80,N('Data by week'!$AL$80)*'Data by week'!$H$80)) | F10: pairs | G10: Week 3 | H10: Year 7: W3, W4, W9; Year 8: W8; Year 9: W8 | I10: Both plans | K10: =MAX(0,E10-N(J10)) | L10: Carry scissors with the points down; cut away from your fingers. Cut away from your fingers; pass scissors handle first; count back in.
A11: Stopwatch | B11: 秒表 | C11: Digital stopwatch. | D11: Reusable | E11: =MAX(MAX(N('Data by week'!$I$81)*'Data by week'!$H$81,N('Data by week'!$J$81)*'Data by week'!$H$81,N('Data by week'!$K$81)*'Data by week'!$H$81,N('Data by week'!$L$81)*'Data by week'!$H$81,N('Data by week'!$M$81)*'Data by week'!$H$81,N('Data by week'!$N$81)*'Data by week'!$H$81,N('Data by week'!$O$81)*'Data by week'!$H$81,N('Data by week'!$P$81)*'Data by week'!$H$81,N('Data by week'!$Q$81)*'Data by week'!$H$81,N('Data by week'!$R$81)*'Data by week'!$H$81),MAX(N('Data by week'!$S$81)*'Data by week'!$H$81,N('Data by week'!$T$81)*'Data by week'!$H$81,N('Data by week'!$U$81)*'Data by week'!$H$81,N('Data by week'!$V$81)*'Data by week'!$H$81,N('Data by week'!$W$81)*'Data by week'!$H$81,N('Data by week'!$X$81)*'Data by week'!$H$81,N('Data by week'!$Y$81)*'Data by week'!$H$81,N('Data by week'!$Z$81)*'Data by week'!$H$81,N('Data by week'!$AA$81)*'Data by week'!$H$81,N('Data by week'!$AB$81)*'Data by week'!$H$81),MAX(N('Data by week'!$AC$81)*'Data by week'!$H$81,N('Data by week'!$AD$81)*'Data by week'!$H$81,N('Data by week'!$AE$81)*'Data by week'!$H$81,N('Data by week'!$AF$81)*'Data by week'!$H$81,N('Data by week'!$AG$81)*'Data by week'!$H$81,N('Data by week'!$AH$81)*'Data by week'!$H$81,N('Data by week'!$AI$81)*'Data by week'!$H$81,N('Data by week'!$AJ$81)*'Data by week'!$H$81,N('Data by week'!$AK$81)*'Data by week'!$H$81,N('Data by week'!$AL$81)*'Data by week'!$H$81)) | F11: stopwatches | G11: Week 3 | H11: Year 7: W3, W4, W6, W8; Year 8: W8, W10; Year 9: W6, W8, W10 | I11: Both plans | K11: =MAX(0,E11-N(J11))
