Workbook

Sheet How_to_use
A1: Think Like a Scientist | 像科学家一样思考: Progress Tracker
A2: One tab per class. Yellow cells are for you to fill in; grey cells calculate automatically. Do not type in grey cells, except to override an Award marked "Check" (explain why in Notes).
A4: Setting up
A5: 1. Rename the class tabs (Y7_Class1, Y8_Class1, Y9_Class1) to your real class names, for example Y7_7A. The Summary formulas follow the rename automatically.
A6: 2. For an extra class, right-click a class tab > Move or Copy > Create a copy, rename it, then copy a row on the Summary tab and point it at the new tab.
A7: 3. Enter register number, names, groups and roles in Week 1. Fictional names only in any training copy.
A9: When to enter what
A10: Week 1: skills check score (/20) in column I; survey answers S1 to S6 (1 to 5) in J to O. Leave blank if absent and write ABS in Notes. Do NOT go through or return the Week 1 papers.
A11: Week 5: checkpoint score (/12) in column Q, before the handover note is written. Checkpoint % below 40 is shaded grey.
A12: Week 10: skills check (/20) in column S; survey S1 to S6 in U to Z; rubric levels for strands 1 to 6 in AC to AH (B Beginning 起步, D Developing 发展, S Secure 达标, E Excellent 优秀, N not judged).
A14: What calculates automatically
A15: Growth (T) = Week 10 minus Week 1: bold if 4 or more; italic and grey if negative (check the marking).
... A19: Example row (format only, fictional student)
A20: No. | B20: Name | C20: 中文姓名 | D20: Group | E20: Role | F20: W1 check | G20: W1 survey S1-S6 | H20: W5 checkpoint | I20: W10 check | J20: Growth | K20: Strands 1-6 | L20: Award
A21: 1 | B21: Lily Wang | C21: 王丽 | D21: G3 | E21: Recorder | F21: 9 | G21: 3, 4, 3, 2, 3, 4 | H21: 8 | I21: 14 | J21: 5 | K21: S, S, E, S, D, S | L21: Silver
A23: File: 00_Tracker/Think_Like_a_Scientist_Tracker.xlsx. Specification: assessment/Tracker_Spec.md.

Sheet Y7_Class1
A1: No. | B1: Student name (English) | C1: 中文姓名 | D1: Group W1 to 5 | E1: Role W1 to 5 | F1: Project group W6 to 10 | G1: Language band (1, 2 or 3) | H1: Access arrangement | I1: W1 skills check (/20) | J1: W1 survey S1 | K1: W1 survey S2 | L1: W1 survey S3 | M1: W1 survey S4 | N1: W1 survey S5 | O1: W1 survey S6 | P1: W1 survey mean | Q1: W5 checkpoint (/12) | R1: W5 checkpoint % | S1: W10 skills check (/20) | T1: Growth | U1: W10 survey S1 | V1: W10 survey S2 | W1: W10 survey S3 | X1: W10 survey S4 | Y1: W10 survey S5 | Z1: W10 survey S6 | AA1: W10 survey mean | AB1: Survey change | AC1: Strand 1 Questioning and predicting 提问与预测 | AD1: Strand 2 Planning 计划设计 | AE1: Strand 3 Doing and recording 实施与记录 | AF1: Strand 4 Analysing and concluding 分析与结论 | AG1: Strand 5 Evaluating and critical thinking 评价与批判性思维 | AH1: Strand 6 Communicating 表达与交流 | AI1: Strands judged | AJ1: Award | AK1: Most Improved | AL1: Certificate printed | AM1: Notes
A2: 1 | P2: =IF(COUNT(J2:O2)=0,"",ROUND(AVERAGE(J2:O2),1)) | R2: =IF(Q2="","",ROUND(Q2/12*100,0)) | T2: =IF(AND(ISNUMBER(I2),ISNUMBER(S2)),S2-I2,"") | AA2: =IF(COUNT(U2:Z2)=0,"",ROUND(AVERAGE(U2:Z2),1)) | AB2: =IF(AND(ISNUMBER(P2),ISNUMBER(AA2)),ROUND(AA2-P2,1),"") | AI2: =COUNTIF(AC2:AH2,"B")+COUNTIF(AC2:AH2,"D")+COUNTIF(AC2:AH2,"S")+COUNTIF(AC2:AH2,"E") | AJ2: =IF(COUNTA(AC2:AH2)=0,"",IF(AI2<5,"Check",IF(COUNTIF(AC2:AH2,"E")>=4,"Gold",IF(COUNTIF(AC2:AH2,"E")+COUNTIF(AC2:AH2,"S")>=4,"Silver",IF(COUNTIF(AC2:AH2,"E")+COUNTIF(AC2:AH2,"S")+COUNTIF(AC2:AH2,"D")>=4,"Bronze","Participation"))))) | AK2: =IF(AND(ISNUMBER(T2),T2>=1,T2=MAX($T$2:$T$25)),"Y","")
A3: 2 | P3: =IF(COUNT(J3:O3)=0,"",ROUND(AVERAGE(J3:O3),1)) | R3: =IF(Q3="","",ROUND(Q3/12*100,0)) | T3: =IF(AND(ISNUMBER(I3),ISNUMBER(S3)),S3-I3,"") | AA3: =IF(COUNT(U3:Z3)=0,"",ROUND(AVERAGE(U3:Z3),1)) | AB3: =IF(AND(ISNUMBER(P3),ISNUMBER(AA3)),ROUND(AA3-P3,1),"") | AI3: =COUNTIF(AC3:AH3,"B")+COUNTIF(AC3:AH3,"D")+COUNTIF(AC3:AH3,"S")+COUNTIF(AC3:AH3,"E") | AJ3: =IF(COUNTA(AC3:AH3)=0,"",IF(AI3<5,"Check",IF(COUNTIF(AC3:AH3,"E")>=4,"Gold",IF(COUNTIF(AC3:AH3,"E")+COUNTIF(AC3:AH3,"S")>=4,"Silver",IF(COUNTIF(AC3:AH3,"E")+COUNTIF(AC3:AH3,"S")+COUNTIF(AC3:AH3,"D")>=4,"Bronze","Participation"))))) | AK3: =IF(AND(ISNUMBER(T3),T3>=1,T3=MAX($T$2:$T$25)),"Y","")
A4: 3 | P4: =IF(COUNT(J4:O4)=0,"",ROUND(AVERAGE(J4:O4),1)) | R4: =IF(Q4="","",ROUND(Q4/12*100,0)) | T4: =IF(AND(ISNUMBER(I4),ISNUMBER(S4)),S4-I4,"") | AA4: =IF(COUNT(U4:Z4)=0,"",ROUND(AVERAGE(U4:Z4),1)) | AB4: =IF(AND(ISNUMBER(P4),ISNUMBER(AA4)),ROUND(AA4-P4,1),"") | AI4: =COUNTIF(AC4:AH4,"B")+COUNTIF(AC4:AH4,"D")+COUNTIF(AC4:AH4,"S")+COUNTIF(AC4:AH4,"E") | AJ4: =IF(COUNTA(AC4:AH4)=0,"",IF(AI4<5,"Check",IF(COUNTIF(AC4:AH4,"E")>=4,"Gold",IF(COUNTIF(AC4:AH4,"E")+COUNTIF(AC4:AH4,"S")>=4,"Silver",IF(COUNTIF(AC4:AH4,"E")+COUNTIF(AC4:AH4,"S")+COUNTIF(AC4:AH4,"D")>=4,"Bronze","Participation"))))) | AK4: =IF(AND(ISNUMBER(T4),T4>=1,T4=MAX($T$2:$T$25)),"Y","")
A5: 4 | P5: =IF(COUNT(J5:O5)=0,"",ROUND(AVERAGE(J5:O5),1)) | R5: =IF(Q5="","",ROUND(Q5/12*100,0)) | T5: =IF(AND(ISNUMBER(I5),ISNUMBER(S5)),S5-I5,"") | AA5: =IF(COUNT(U5:Z5)=0,"",ROUND(AVERAGE(U5:Z5),1)) | AB5: =IF(AND(ISNUMBER(P5),ISNUMBER(AA5)),ROUND(AA5-P5,1),"") | AI5: =COUNTIF(AC5:AH5,"B")+COUNTIF(AC5:AH5,"D")+COUNTIF(AC5:AH5,"S")+COUNTIF(AC5:AH5,"E") | AJ5: =IF(COUNTA(AC5:AH5)=0,"",IF(AI5<5,"Check",IF(COUNTIF(AC5:AH5,"E")>=4,"Gold",IF(COUNTIF(AC5:AH5,"E")+COUNTIF(AC5:AH5,"S")>=4,"Silver",IF(COUNTIF(AC5:AH5,"E")+COUNTIF(AC5:AH5,"S")+COUNTIF(AC5:AH5,"D")>=4,"Bronze","Participation"))))) | AK5: =IF(AND(ISNUMBER(T5),T5>=1,T5=MAX($T$2:$T$25)),"Y","")
A6: 5 | P6: =IF(COUNT(J6:O6)=0,"",ROUND(AVERAGE(J6:O6),1)) | R6: =IF(Q6="","",ROUND(Q6/12*100,0)) | T6: =IF(AND(ISNUMBER(I6),ISNUMBER(S6)),S6-I6,"") | AA6: =IF(COUNT(U6:Z6)=0,"",ROUND(AVERAGE(U6:Z6),1)) | AB6: =IF(AND(ISNUMBER(P6),ISNUMBER(AA6)),ROUND(AA6-P6,1),"") | AI6: =COUNTIF(AC6:AH6,"B")+COUNTIF(AC6:AH6,"D")+COUNTIF(AC6:AH6,"S")+COUNTIF(AC6:AH6,"E") | AJ6: =IF(COUNTA(AC6:AH6)=0,"",IF(AI6<5,"Check",IF(COUNTIF(AC6:AH6,"E")>=4,"Gold",IF(COUNTIF(AC6:AH6,"E")+COUNTIF(AC6:AH6,"S")>=4,"Silver",IF(COUNTIF(AC6:AH6,"E")+COUNTIF(AC6:AH6,"S")+COUNTIF(AC6:AH6,"D")>=4,"Bronze","Participation"))))) | AK6: =IF(AND(ISNUMBER(T6),T6>=1,T6=MAX($T$2:$T$25)),"Y","")
A7: 6 | P7: =IF(COUNT(J7:O7)=0,"",ROUND(AVERAGE(J7:O7),1)) | R7: =IF(Q7="","",ROUND(Q7/12*100,0)) | T7: =IF(AND(ISNUMBER(I7),ISNUMBER(S7)),S7-I7,"") | AA7: =IF(COUNT(U7:Z7)=0,"",ROUND(AVERAGE(U7:Z7),1)) | AB7: =IF(AND(ISNUMBER(P7),ISNUMBER(AA7)),ROUND(AA7-P7,1),"") | AI7: =COUNTIF(AC7:AH7,"B")+COUNTIF(AC7:AH7,"D")+COUNTIF(AC7:AH7,"S")+COUNTIF(AC7:AH7,"E") | AJ7: =IF(COUNTA(AC7:AH7)=0,"",IF(AI7<5,"Check",IF(COUNTIF(AC7:AH7,"E")>=4,"Gold",IF(COUNTIF(AC7:AH7,"E")+COUNTIF(AC7:AH7,"S")>=4,"Silver",IF(COUNTIF(AC7:AH7,"E")+COUNTIF(AC7:AH7,"S")+COUNTIF(AC7:AH7,"D")>=4,"Bronze","Participation"))))) | AK7: =IF(AND(ISNUMBER(T7),T7>=1,T7=MAX($T$2:$T$25)),"Y","")
A8: 7 | P8: =IF(COUNT(J8:O8)=0,"",ROUND(AVERAGE(J8:O8),1)) | R8: =IF(Q8="","",ROUND(Q8/12*100,0)) | T8: =IF(AND(ISNUMBER(I8),ISNUMBER(S8)),S8-I8,"") | AA8: =IF(COUNT(U8:Z8)=0,"",ROUND(AVERAGE(U8:Z8),1)) | AB8: =IF(AND(ISNUMBER(P8),ISNUMBER(AA8)),ROUND(AA8-P8,1),"") | AI8: =COUNTIF(AC8:AH8,"B")+COUNTIF(AC8:AH8,"D")+COUNTIF(AC8:AH8,"S")+COUNTIF(AC8:AH8,"E") | AJ8: =IF(COUNTA(AC8:AH8)=0,"",IF(AI8<5,"Check",IF(COUNTIF(AC8:AH8,"E")>=4,"Gold",IF(COUNTIF(AC8:AH8,"E")+COUNTIF(AC8:AH8,"S")>=4,"Silver",IF(COUNTIF(AC8:AH8,"E")+COUNTIF(AC8:AH8,"S")+COUNTIF(AC8:AH8,"D")>=4,"Bronze","Participation"))))) | AK8: =IF(AND(ISNUMBER(T8),T8>=1,T8=MAX($T$2:$T$25)),"Y","")
A9: 8 | P9: =IF(COUNT(J9:O9)=0,"",ROUND(AVERAGE(J9:O9),1)) | R9: =IF(Q9="","",ROUND(Q9/12*100,0)) | T9: =IF(AND(ISNUMBER(I9),ISNUMBER(S9)),S9-I9,"") | AA9: =IF(COUNT(U9:Z9)=0,"",ROUND(AVERAGE(U9:Z9),1)) | AB9: =IF(AND(ISNUMBER(P9),ISNUMBER(AA9)),ROUND(AA9-P9,1),"") | AI9: =COUNTIF(AC9:AH9,"B")+COUNTIF(AC9:AH9,"D")+COUNTIF(AC9:AH9,"S")+COUNTIF(AC9:AH9,"E") | AJ9: =IF(COUNTA(AC9:AH9)=0,"",IF(AI9<5,"Check",IF(COUNTIF(AC9:AH9,"E")>=4,"Gold",IF(COUNTIF(AC9:AH9,"E")+COUNTIF(AC9:AH9,"S")>=4,"Silver",IF(COUNTIF(AC9:AH9,"E")+COUNTIF(AC9:AH9,"S")+COUNTIF(AC9:AH9,"D")>=4,"Bronze","Participation"))))) | AK9: =IF(AND(ISNUMBER(T9),T9>=1,T9=MAX($T$2:$T$25)),"Y","")
A10: 9 | P10: =IF(COUNT(J10:O10)=0,"",ROUND(AVERAGE(J10:O10),1)) | R10: =IF(Q10="","",ROUND(Q10/12*100,0)) | T10: =IF(AND(ISNUMBER(I10),ISNUMBER(S10)),S10-I10,"") | AA10: =IF(COUNT(U10:Z10)=0,"",ROUND(AVERAGE(U10:Z10),1)) | AB10: =IF(AND(ISNUMBER(P10),ISNUMBER(AA10)),ROUND(AA10-P10,1),"") | AI10: =COUNTIF(AC10:AH10,"B")+COUNTIF(AC10:AH10,"D")+COUNTIF(AC10:AH10,"S")+COUNTIF(AC10:AH10,"E") | AJ10: =IF(COUNTA(AC10:AH10)=0,"",IF(AI10<5,"Check",IF(COUNTIF(AC10:AH10,"E")>=4,"Gold",IF(COUNTIF(AC10:AH10,"E")+COUNTIF(AC10:AH10,"S")>=4,"Silver",IF(COUNTIF(AC10:AH10,"E")+COUNTIF(AC10:AH10,"S")+COUNTIF(AC10:AH10,"D")>=4,"Bronze","Participation"))))) | AK10: =IF(AND(ISNUMBER(T10),T10>=1,T10=MAX($T$2:$T$25)),"Y","")
A11: 10 | P11: =IF(COUNT(J11:O11)=0,"",ROUND(AVERAGE(J11:O11),1)) | R11: =IF(Q11="","",ROUND(Q11/12*100,0)) | T11: =IF(AND(ISNUMBER(I11),ISNUMBER(S11)),S11-I11,"") | AA11: =IF(COUNT(U11:Z11)=0,"",ROUND(AVERAGE(U11:Z11),1)) | AB11: =IF(AND(ISNUMBER(P11),ISNUMBER(AA11)),ROUND(AA11-P11,1),"") | AI11: =COUNTIF(AC11:AH11,"B")+COUNTIF(AC11:AH11,"D")+COUNTIF(AC11:AH11,"S")+COUNTIF(AC11:AH11,"E") | AJ11: =IF(COUNTA(AC11:AH11)=0,"",IF(AI11<5,"Check",IF(COUNTIF(AC11:AH11,"E")>=4,"Gold",IF(COUNTIF(AC11:AH11,"E")+COUNTIF(AC11:AH11,"S")>=4,"Silver",IF(COUNTIF(AC11:AH11,"E")+COUNTIF(AC11:AH11,"S")+COUNTIF(AC11:AH11,"D")>=4,"Bronze","Participation"))))) | AK11: =IF(AND(ISNUMBER(T11),T11>=1,T11=MAX($T$2:$T$25)),"Y","")
A12: 11 | P12: =IF(COUNT(J12:O12)=0,"",ROUND(AVERAGE(J12:O12),1)) | R12: =IF(Q12="","",ROUND(Q12/12*100,0)) | T12: =IF(AND(ISNUMBER(I12),ISNUMBER(S12)),S12-I12,"") | AA12: =IF(COUNT(U12:Z12)=0,"",ROUND(AVERAGE(U12:Z12),1)) | AB12: =IF(AND(ISNUMBER(P12),ISNUMBER(AA12)),ROUND(AA12-P12,1),"") | AI12: =COUNTIF(AC12:AH12,"B")+COUNTIF(AC12:AH12,"D")+COUNTIF(AC12:AH12,"S")+COUNTIF(AC12:AH12,"E") | AJ12: =IF(COUNTA(AC12:AH12)=0,"",IF(AI12<5,"Check",IF(COUNTIF(AC12:AH12,"E")>=4,"Gold",IF(COUNTIF(AC12:AH12,"E")+COUNTIF(AC12:AH12,"S")>=4,"Silver",IF(COUNTIF(AC12:AH12,"E")+COUNTIF(AC12:AH12,"S")+COUNTIF(AC12:AH12,"D")>=4,"Bronze","Participation"))))) | AK12: =IF(AND(ISNUMBER(T12),T12>=1,T12=MAX($T$2:$T$25)),"Y","")
A13: 12 | P13: =IF(COUNT(J13:O13)=0,"",ROUND(AVERAGE(J13:O13),1)) | R13: =IF(Q13="","",ROUND(Q13/12*100,0)) | T13: =IF(AND(ISNUMBER(I13),ISNUMBER(S13)),S13-I13,"") | AA13: =IF(COUNT(U13:Z13)=0,"",ROUND(AVERAGE(U13:Z13),1)) | AB13: =IF(AND(ISNUMBER(P13),ISNUMBER(AA13)),ROUND(AA13-P13,1),"") | AI13: =COUNTIF(AC13:AH13,"B")+COUNTIF(AC13:AH13,"D")+COUNTIF(AC13:AH13,"S")+COUNTIF(AC13:AH13,"E") | AJ13: =IF(COUNTA(AC13:AH13)=0,"",IF(AI13<5,"Check",IF(COUNTIF(AC13:AH13,"E")>=4,"Gold",IF(COUNTIF(AC13:AH13,"E")+COUNTIF(AC13:AH13,"S")>=4,"Silver",IF(COUNTIF(AC13:AH13,"E")+COUNTIF(AC13:AH13,"S")+COUNTIF(AC13:AH13,"D")>=4,"Bronze","Participation"))))) | AK13: =IF(AND(ISNUMBER(T13),T13>=1,T13=MAX($T$2:$T$25)),"Y","")
... A25: 24 | P25: =IF(COUNT(J25:O25)=0,"",ROUND(AVERAGE(J25:O25),1)) | R25: =IF(Q25="","",ROUND(Q25/12*100,0)) | T25: =IF(AND(ISNUMBER(I25),ISNUMBER(S25)),S25-I25,"") | AA25: =IF(COUNT(U25:Z25)=0,"",ROUND(AVERAGE(U25:Z25),1)) | AB25: =IF(AND(ISNUMBER(P25),ISNUMBER(AA25)),ROUND(AA25-P25,1),"") | AI25: =COUNTIF(AC25:AH25,"B")+COUNTIF(AC25:AH25,"D")+COUNTIF(AC25:AH25,"S")+COUNTIF(AC25:AH25,"E") | AJ25: =IF(COUNTA(AC25:AH25)=0,"",IF(AI25<5,"Check",IF(COUNTIF(AC25:AH25,"E")>=4,"Gold",IF(COUNTIF(AC25:AH25,"E")+COUNTIF(AC25:AH25,"S")>=4,"Silver",IF(COUNTIF(AC25:AH25,"E")+COUNTIF(AC25:AH25,"S")+COUNTIF(AC25:AH25,"D")>=4,"Bronze","Participation"))))) | AK25: =IF(AND(ISNUMBER(T25),T25>=1,T25=MAX($T$2:$T$25)),"Y","")

Sheet Y8_Class1
A1: No. | B1: Student name (English) | C1: 中文姓名 | D1: Group W1 to 5 | E1: Role W1 to 5 | F1: Project group W6 to 10 | G1: Language band (1, 2 or 3) | H1: Access arrangement | I1: W1 skills check (/20) | J1: W1 survey S1 | K1: W1 survey S2 | L1: W1 survey S3 | M1: W1 survey S4 | N1: W1 survey S5 | O1: W1 survey S6 | P1: W1 survey mean | Q1: W5 checkpoint (/12) | R1: W5 checkpoint % | S1: W10 skills check (/20) | T1: Growth | U1: W10 survey S1 | V1: W10 survey S2 | W1: W10 survey S3 | X1: W10 survey S4 | Y1: W10 survey S5 | Z1: W10 survey S6 | AA1: W10 survey mean | AB1: Survey change | AC1: Strand 1 Questioning and predicting 提问与预测 | AD1: Strand 2 Planning 计划设计 | AE1: Strand 3 Doing and recording 实施与记录 | AF1: Strand 4 Analysing and concluding 分析与结论 | AG1: Strand 5 Evaluating and critical thinking 评价与批判性思维 | AH1: Strand 6 Communicating 表达与交流 | AI1: Strands judged | AJ1: Award | AK1: Most Improved | AL1: Certificate printed | AM1: Notes
A2: 1 | P2: =IF(COUNT(J2:O2)=0,"",ROUND(AVERAGE(J2:O2),1)) | R2: =IF(Q2="","",ROUND(Q2/12*100,0)) | T2: =IF(AND(ISNUMBER(I2),ISNUMBER(S2)),S2-I2,"") | AA2: =IF(COUNT(U2:Z2)=0,"",ROUND(AVERAGE(U2:Z2),1)) | AB2: =IF(AND(ISNUMBER(P2),ISNUMBER(AA2)),ROUND(AA2-P2,1),"") | AI2: =COUNTIF(AC2:AH2,"B")+COUNTIF(AC2:AH2,"D")+COUNTIF(AC2:AH2,"S")+COUNTIF(AC2:AH2,"E") | AJ2: =IF(COUNTA(AC2:AH2)=0,"",IF(AI2<5,"Check",IF(COUNTIF(AC2:AH2,"E")>=4,"Gold",IF(COUNTIF(AC2:AH2,"E")+COUNTIF(AC2:AH2,"S")>=4,"Silver",IF(COUNTIF(AC2:AH2,"E")+COUNTIF(AC2:AH2,"S")+COUNTIF(AC2:AH2,"D")>=4,"Bronze","Participation"))))) | AK2: =IF(AND(ISNUMBER(T2),T2>=1,T2=MAX($T$2:$T$25)),"Y","")
A3: 2 | P3: =IF(COUNT(J3:O3)=0,"",ROUND(AVERAGE(J3:O3),1)) | R3: =IF(Q3="","",ROUND(Q3/12*100,0)) | T3: =IF(AND(ISNUMBER(I3),ISNUMBER(S3)),S3-I3,"") | AA3: =IF(COUNT(U3:Z3)=0,"",ROUND(AVERAGE(U3:Z3),1)) | AB3: =IF(AND(ISNUMBER(P3),ISNUMBER(AA3)),ROUND(AA3-P3,1),"") | AI3: =COUNTIF(AC3:AH3,"B")+COUNTIF(AC3:AH3,"D")+COUNTIF(AC3:AH3,"S")+COUNTIF(AC3:AH3,"E") | AJ3: =IF(COUNTA(AC3:AH3)=0,"",IF(AI3<5,"Check",IF(COUNTIF(AC3:AH3,"E")>=4,"Gold",IF(COUNTIF(AC3:AH3,"E")+COUNTIF(AC3:AH3,"S")>=4,"Silver",IF(COUNTIF(AC3:AH3,"E")+COUNTIF(AC3:AH3,"S")+COUNTIF(AC3:AH3,"D")>=4,"Bronze","Participation"))))) | AK3: =IF(AND(ISNUMBER(T3),T3>=1,T3=MAX($T$2:$T$25)),"Y","")
A4: 3 | P4: =IF(COUNT(J4:O4)=0,"",ROUND(AVERAGE(J4:O4),1)) | R4: =IF(Q4="","",ROUND(Q4/12*100,0)) | T4: =IF(AND(ISNUMBER(I4),ISNUMBER(S4)),S4-I4,"") | AA4: =IF(COUNT(U4:Z4)=0,"",ROUND(AVERAGE(U4:Z4),1)) | AB4: =IF(AND(ISNUMBER(P4),ISNUMBER(AA4)),ROUND(AA4-P4,1),"") | AI4: =COUNTIF(AC4:AH4,"B")+COUNTIF(AC4:AH4,"D")+COUNTIF(AC4:AH4,"S")+COUNTIF(AC4:AH4,"E") | AJ4: =IF(COUNTA(AC4:AH4)=0,"",IF(AI4<5,"Check",IF(COUNTIF(AC4:AH4,"E")>=4,"Gold",IF(COUNTIF(AC4:AH4,"E")+COUNTIF(AC4:AH4,"S")>=4,"Silver",IF(COUNTIF(AC4:AH4,"E")+COUNTIF(AC4:AH4,"S")+COUNTIF(AC4:AH4,"D")>=4,"Bronze","Participation"))))) | AK4: =IF(AND(ISNUMBER(T4),T4>=1,T4=MAX($T$2:$T$25)),"Y","")
A5: 4 | P5: =IF(COUNT(J5:O5)=0,"",ROUND(AVERAGE(J5:O5),1)) | R5: =IF(Q5="","",ROUND(Q5/12*100,0)) | T5: =IF(AND(ISNUMBER(I5),ISNUMBER(S5)),S5-I5,"") | AA5: =IF(COUNT(U5:Z5)=0,"",ROUND(AVERAGE(U5:Z5),1)) | AB5: =IF(AND(ISNUMBER(P5),ISNUMBER(AA5)),ROUND(AA5-P5,1),"") | AI5: =COUNTIF(AC5:AH5,"B")+COUNTIF(AC5:AH5,"D")+COUNTIF(AC5:AH5,"S")+COUNTIF(AC5:AH5,"E") | AJ5: =IF(COUNTA(AC5:AH5)=0,"",IF(AI5<5,"Check",IF(COUNTIF(AC5:AH5,"E")>=4,"Gold",IF(COUNTIF(AC5:AH5,"E")+COUNTIF(AC5:AH5,"S")>=4,"Silver",IF(COUNTIF(AC5:AH5,"E")+COUNTIF(AC5:AH5,"S")+COUNTIF(AC5:AH5,"D")>=4,"Bronze","Participation"))))) | AK5: =IF(AND(ISNUMBER(T5),T5>=1,T5=MAX($T$2:$T$25)),"Y","")
A6: 5 | P6: =IF(COUNT(J6:O6)=0,"",ROUND(AVERAGE(J6:O6),1)) | R6: =IF(Q6="","",ROUND(Q6/12*100,0)) | T6: =IF(AND(ISNUMBER(I6),ISNUMBER(S6)),S6-I6,"") | AA6: =IF(COUNT(U6:Z6)=0,"",ROUND(AVERAGE(U6:Z6),1)) | AB6: =IF(AND(ISNUMBER(P6),ISNUMBER(AA6)),ROUND(AA6-P6,1),"") | AI6: =COUNTIF(AC6:AH6,"B")+COUNTIF(AC6:AH6,"D")+COUNTIF(AC6:AH6,"S")+COUNTIF(AC6:AH6,"E") | AJ6: =IF(COUNTA(AC6:AH6)=0,"",IF(AI6<5,"Check",IF(COUNTIF(AC6:AH6,"E")>=4,"Gold",IF(COUNTIF(AC6:AH6,"E")+COUNTIF(AC6:AH6,"S")>=4,"Silver",IF(COUNTIF(AC6:AH6,"E")+COUNTIF(AC6:AH6,"S")+COUNTIF(AC6:AH6,"D")>=4,"Bronze","Participation"))))) | AK6: =IF(AND(ISNUMBER(T6),T6>=1,T6=MAX($T$2:$T$25)),"Y","")
A7: 6 | P7: =IF(COUNT(J7:O7)=0,"",ROUND(AVERAGE(J7:O7),1)) | R7: =IF(Q7="","",ROUND(Q7/12*100,0)) | T7: =IF(AND(ISNUMBER(I7),ISNUMBER(S7)),S7-I7,"") | AA7: =IF(COUNT(U7:Z7)=0,"",ROUND(AVERAGE(U7:Z7),1)) | AB7: =IF(AND(ISNUMBER(P7),ISNUMBER(AA7)),ROUND(AA7-P7,1),"") | AI7: =COUNTIF(AC7:AH7,"B")+COUNTIF(AC7:AH7,"D")+COUNTIF(AC7:AH7,"S")+COUNTIF(AC7:AH7,"E") | AJ7: =IF(COUNTA(AC7:AH7)=0,"",IF(AI7<5,"Check",IF(COUNTIF(AC7:AH7,"E")>=4,"Gold",IF(COUNTIF(AC7:AH7,"E")+COUNTIF(AC7:AH7,"S")>=4,"Silver",IF(COUNTIF(AC7:AH7,"E")+COUNTIF(AC7:AH7,"S")+COUNTIF(AC7:AH7,"D")>=4,"Bronze","Participation"))))) | AK7: =IF(AND(ISNUMBER(T7),T7>=1,T7=MAX($T$2:$T$25)),"Y","")
A8: 7 | P8: =IF(COUNT(J8:O8)=0,"",ROUND(AVERAGE(J8:O8),1)) | R8: =IF(Q8="","",ROUND(Q8/12*100,0)) | T8: =IF(AND(ISNUMBER(I8),ISNUMBER(S8)),S8-I8,"") | AA8: =IF(COUNT(U8:Z8)=0,"",ROUND(AVERAGE(U8:Z8),1)) | AB8: =IF(AND(ISNUMBER(P8),ISNUMBER(AA8)),ROUND(AA8-P8,1),"") | AI8: =COUNTIF(AC8:AH8,"B")+COUNTIF(AC8:AH8,"D")+COUNTIF(AC8:AH8,"S")+COUNTIF(AC8:AH8,"E") | AJ8: =IF(COUNTA(AC8:AH8)=0,"",IF(AI8<5,"Check",IF(COUNTIF(AC8:AH8,"E")>=4,"Gold",IF(COUNTIF(AC8:AH8,"E")+COUNTIF(AC8:AH8,"S")>=4,"Silver",IF(COUNTIF(AC8:AH8,"E")+COUNTIF(AC8:AH8,"S")+COUNTIF(AC8:AH8,"D")>=4,"Bronze","Participation"))))) | AK8: =IF(AND(ISNUMBER(T8),T8>=1,T8=MAX($T$2:$T$25)),"Y","")
A9: 8 | P9: =IF(COUNT(J9:O9)=0,"",ROUND(AVERAGE(J9:O9),1)) | R9: =IF(Q9="","",ROUND(Q9/12*100,0)) | T9: =IF(AND(ISNUMBER(I9),ISNUMBER(S9)),S9-I9,"") | AA9: =IF(COUNT(U9:Z9)=0,"",ROUND(AVERAGE(U9:Z9),1)) | AB9: =IF(AND(ISNUMBER(P9),ISNUMBER(AA9)),ROUND(AA9-P9,1),"") | AI9: =COUNTIF(AC9:AH9,"B")+COUNTIF(AC9:AH9,"D")+COUNTIF(AC9:AH9,"S")+COUNTIF(AC9:AH9,"E") | AJ9: =IF(COUNTA(AC9:AH9)=0,"",IF(AI9<5,"Check",IF(COUNTIF(AC9:AH9,"E")>=4,"Gold",IF(COUNTIF(AC9:AH9,"E")+COUNTIF(AC9:AH9,"S")>=4,"Silver",IF(COUNTIF(AC9:AH9,"E")+COUNTIF(AC9:AH9,"S")+COUNTIF(AC9:AH9,"D")>=4,"Bronze","Participation"))))) | AK9: =IF(AND(ISNUMBER(T9),T9>=1,T9=MAX($T$2:$T$25)),"Y","")
A10: 9 | P10: =IF(COUNT(J10:O10)=0,"",ROUND(AVERAGE(J10:O10),1)) | R10: =IF(Q10="","",ROUND(Q10/12*100,0)) | T10: =IF(AND(ISNUMBER(I10),ISNUMBER(S10)),S10-I10,"") | AA10: =IF(COUNT(U10:Z10)=0,"",ROUND(AVERAGE(U10:Z10),1)) | AB10: =IF(AND(ISNUMBER(P10),ISNUMBER(AA10)),ROUND(AA10-P10,1),"") | AI10: =COUNTIF(AC10:AH10,"B")+COUNTIF(AC10:AH10,"D")+COUNTIF(AC10:AH10,"S")+COUNTIF(AC10:AH10,"E") | AJ10: =IF(COUNTA(AC10:AH10)=0,"",IF(AI10<5,"Check",IF(COUNTIF(AC10:AH10,"E")>=4,"Gold",IF(COUNTIF(AC10:AH10,"E")+COUNTIF(AC10:AH10,"S")>=4,"Silver",IF(COUNTIF(AC10:AH10,"E")+COUNTIF(AC10:AH10,"S")+COUNTIF(AC10:AH10,"D")>=4,"Bronze","Participation"))))) | AK10: =IF(AND(ISNUMBER(T10),T10>=1,T10=MAX($T$2:$T$25)),"Y","")
A11: 10 | P11: =IF(COUNT(J11:O11)=0,"",ROUND(AVERAGE(J11:O11),1)) | R11: =IF(Q11="","",ROUND(Q11/12*100,0)) | T11: =IF(AND(ISNUMBER(I11),ISNUMBER(S11)),S11-I11,"") | AA11: =IF(COUNT(U11:Z11)=0,"",ROUND(AVERAGE(U11:Z11),1)) | AB11: =IF(AND(ISNUMBER(P11),ISNUMBER(AA11)),ROUND(AA11-P11,1),"") | AI11: =COUNTIF(AC11:AH11,"B")+COUNTIF(AC11:AH11,"D")+COUNTIF(AC11:AH11,"S")+COUNTIF(AC11:AH11,"E") | AJ11: =IF(COUNTA(AC11:AH11)=0,"",IF(AI11<5,"Check",IF(COUNTIF(AC11:AH11,"E")>=4,"Gold",IF(COUNTIF(AC11:AH11,"E")+COUNTIF(AC11:AH11,"S")>=4,"Silver",IF(COUNTIF(AC11:AH11,"E")+COUNTIF(AC11:AH11,"S")+COUNTIF(AC11:AH11,"D")>=4,"Bronze","Participation"))))) | AK11: =IF(AND(ISNUMBER(T11),T11>=1,T11=MAX($T$2:$T$25)),"Y","")
A12: 11 | P12: =IF(COUNT(J12:O12)=0,"",ROUND(AVERAGE(J12:O12),1)) | R12: =IF(Q12="","",ROUND(Q12/12*100,0)) | T12: =IF(AND(ISNUMBER(I12),ISNUMBER(S12)),S12-I12,"") | AA12: =IF(COUNT(U12:Z12)=0,"",ROUND(AVERAGE(U12:Z12),1)) | AB12: =IF(AND(ISNUMBER(P12),ISNUMBER(AA12)),ROUND(AA12-P12,1),"") | AI12: =COUNTIF(AC12:AH12,"B")+COUNTIF(AC12:AH12,"D")+COUNTIF(AC12:AH12,"S")+COUNTIF(AC12:AH12,"E") | AJ12: =IF(COUNTA(AC12:AH12)=0,"",IF(AI12<5,"Check",IF(COUNTIF(AC12:AH12,"E")>=4,"Gold",IF(COUNTIF(AC12:AH12,"E")+COUNTIF(AC12:AH12,"S")>=4,"Silver",IF(COUNTIF(AC12:AH12,"E")+COUNTIF(AC12:AH12,"S")+COUNTIF(AC12:AH12,"D")>=4,"Bronze","Participation"))))) | AK12: =IF(AND(ISNUMBER(T12),T12>=1,T12=MAX($T$2:$T$25)),"Y","")
A13: 12 | P13: =IF(COUNT(J13:O13)=0,"",ROUND(AVERAGE(J13:O13),1)) | R13: =IF(Q13="","",ROUND(Q13/12*100,0)) | T13: =IF(AND(ISNUMBER(I13),ISNUMBER(S13)),S13-I13,"") | AA13: =IF(COUNT(U13:Z13)=0,"",ROUND(AVERAGE(U13:Z13),1)) | AB13: =IF(AND(ISNUMBER(P13),ISNUMBER(AA13)),ROUND(AA13-P13,1),"") | AI13: =COUNTIF(AC13:AH13,"B")+COUNTIF(AC13:AH13,"D")+COUNTIF(AC13:AH13,"S")+COUNTIF(AC13:AH13,"E") | AJ13: =IF(COUNTA(AC13:AH13)=0,"",IF(AI13<5,"Check",IF(COUNTIF(AC13:AH13,"E")>=4,"Gold",IF(COUNTIF(AC13:AH13,"E")+COUNTIF(AC13:AH13,"S")>=4,"Silver",IF(COUNTIF(AC13:AH13,"E")+COUNTIF(AC13:AH13,"S")+COUNTIF(AC13:AH13,"D")>=4,"Bronze","Participation"))))) | AK13: =IF(AND(ISNUMBER(T13),T13>=1,T13=MAX($T$2:$T$25)),"Y","")
... A25: 24 | P25: =IF(COUNT(J25:O25)=0,"",ROUND(AVERAGE(J25:O25),1)) | R25: =IF(Q25="","",ROUND(Q25/12*100,0)) | T25: =IF(AND(ISNUMBER(I25),ISNUMBER(S25)),S25-I25,"") | AA25: =IF(COUNT(U25:Z25)=0,"",ROUND(AVERAGE(U25:Z25),1)) | AB25: =IF(AND(ISNUMBER(P25),ISNUMBER(AA25)),ROUND(AA25-P25,1),"") | AI25: =COUNTIF(AC25:AH25,"B")+COUNTIF(AC25:AH25,"D")+COUNTIF(AC25:AH25,"S")+COUNTIF(AC25:AH25,"E") | AJ25: =IF(COUNTA(AC25:AH25)=0,"",IF(AI25<5,"Check",IF(COUNTIF(AC25:AH25,"E")>=4,"Gold",IF(COUNTIF(AC25:AH25,"E")+COUNTIF(AC25:AH25,"S")>=4,"Silver",IF(COUNTIF(AC25:AH25,"E")+COUNTIF(AC25:AH25,"S")+COUNTIF(AC25:AH25,"D")>=4,"Bronze","Participation"))))) | AK25: =IF(AND(ISNUMBER(T25),T25>=1,T25=MAX($T$2:$T$25)),"Y","")

Sheet Y9_Class1
A1: No. | B1: Student name (English) | C1: 中文姓名 | D1: Group W1 to 5 | E1: Role W1 to 5 | F1: Project group W6 to 10 | G1: Language band (1, 2 or 3) | H1: Access arrangement | I1: W1 skills check (/20) | J1: W1 survey S1 | K1: W1 survey S2 | L1: W1 survey S3 | M1: W1 survey S4 | N1: W1 survey S5 | O1: W1 survey S6 | P1: W1 survey mean | Q1: W5 checkpoint (/12) | R1: W5 checkpoint % | S1: W10 skills check (/20) | T1: Growth | U1: W10 survey S1 | V1: W10 survey S2 | W1: W10 survey S3 | X1: W10 survey S4 | Y1: W10 survey S5 | Z1: W10 survey S6 | AA1: W10 survey mean | AB1: Survey change | AC1: Strand 1 Questioning and predicting 提问与预测 | AD1: Strand 2 Planning 计划设计 | AE1: Strand 3 Doing and recording 实施与记录 | AF1: Strand 4 Analysing and concluding 分析与结论 | AG1: Strand 5 Evaluating and critical thinking 评价与批判性思维 | AH1: Strand 6 Communicating 表达与交流 | AI1: Strands judged | AJ1: Award | AK1: Most Improved | AL1: Certificate printed | AM1: Notes
A2: 1 | P2: =IF(COUNT(J2:O2)=0,"",ROUND(AVERAGE(J2:O2),1)) | R2: =IF(Q2="","",ROUND(Q2/12*100,0)) | T2: =IF(AND(ISNUMBER(I2),ISNUMBER(S2)),S2-I2,"") | AA2: =IF(COUNT(U2:Z2)=0,"",ROUND(AVERAGE(U2:Z2),1)) | AB2: =IF(AND(ISNUMBER(P2),ISNUMBER(AA2)),ROUND(AA2-P2,1),"") | AI2: =COUNTIF(AC2:AH2,"B")+COUNTIF(AC2:AH2,"D")+COUNTIF(AC2:AH2,"S")+COUNTIF(AC2:AH2,"E") | AJ2: =IF(COUNTA(AC2:AH2)=0,"",IF(AI2<5,"Check",IF(COUNTIF(AC2:AH2,"E")>=4,"Gold",IF(COUNTIF(AC2:AH2,"E")+COUNTIF(AC2:AH2,"S")>=4,"Silver",IF(COUNTIF(AC2:AH2,"E")+COUNTIF(AC2:AH2,"S")+COUNTIF(AC2:AH2,"D")>=4,"Bronze","Participation"))))) | AK2: =IF(AND(ISNUMBER(T2),T2>=1,T2=MAX($T$2:$T$25)),"Y","")
A3: 2 | P3: =IF(COUNT(J3:O3)=0,"",ROUND(AVERAGE(J3:O3),1)) | R3: =IF(Q3="","",ROUND(Q3/12*100,0)) | T3: =IF(AND(ISNUMBER(I3),ISNUMBER(S3)),S3-I3,"") | AA3: =IF(COUNT(U3:Z3)=0,"",ROUND(AVERAGE(U3:Z3),1)) | AB3: =IF(AND(ISNUMBER(P3),ISNUMBER(AA3)),ROUND(AA3-P3,1),"") | AI3: =COUNTIF(AC3:AH3,"B")+COUNTIF(AC3:AH3,"D")+COUNTIF(AC3:AH3,"S")+COUNTIF(AC3:AH3,"E") | AJ3: =IF(COUNTA(AC3:AH3)=0,"",IF(AI3<5,"Check",IF(COUNTIF(AC3:AH3,"E")>=4,"Gold",IF(COUNTIF(AC3:AH3,"E")+COUNTIF(AC3:AH3,"S")>=4,"Silver",IF(COUNTIF(AC3:AH3,"E")+COUNTIF(AC3:AH3,"S")+COUNTIF(AC3:AH3,"D")>=4,"Bronze","Participation"))))) | AK3: =IF(AND(ISNUMBER(T3),T3>=1,T3=MAX($T$2:$T$25)),"Y","")
A4: 3 | P4: =IF(COUNT(J4:O4)=0,"",ROUND(AVERAGE(J4:O4),1)) | R4: =IF(Q4="","",ROUND(Q4/12*100,0)) | T4: =IF(AND(ISNUMBER(I4),ISNUMBER(S4)),S4-I4,"") | AA4: =IF(COUNT(U4:Z4)=0,"",ROUND(AVERAGE(U4:Z4),1)) | AB4: =IF(AND(ISNUMBER(P4),ISNUMBER(AA4)),ROUND(AA4-P4,1),"") | AI4: =COUNTIF(AC4:AH4,"B")+COUNTIF(AC4:AH4,"D")+COUNTIF(AC4:AH4,"S")+COUNTIF(AC4:AH4,"E") | AJ4: =IF(COUNTA(AC4:AH4)=0,"",IF(AI4<5,"Check",IF(COUNTIF(AC4:AH4,"E")>=4,"Gold",IF(COUNTIF(AC4:AH4,"E")+COUNTIF(AC4:AH4,"S")>=4,"Silver",IF(COUNTIF(AC4:AH4,"E")+COUNTIF(AC4:AH4,"S")+COUNTIF(AC4:AH4,"D")>=4,"Bronze","Participation"))))) | AK4: =IF(AND(ISNUMBER(T4),T4>=1,T4=MAX($T$2:$T$25)),"Y","")
A5: 4 | P5: =IF(COUNT(J5:O5)=0,"",ROUND(AVERAGE(J5:O5),1)) | R5: =IF(Q5="","",ROUND(Q5/12*100,0)) | T5: =IF(AND(ISNUMBER(I5),ISNUMBER(S5)),S5-I5,"") | AA5: =IF(COUNT(U5:Z5)=0,"",ROUND(AVERAGE(U5:Z5),1)) | AB5: =IF(AND(ISNUMBER(P5),ISNUMBER(AA5)),ROUND(AA5-P5,1),"") | AI5: =COUNTIF(AC5:AH5,"B")+COUNTIF(AC5:AH5,"D")+COUNTIF(AC5:AH5,"S")+COUNTIF(AC5:AH5,"E") | AJ5: =IF(COUNTA(AC5:AH5)=0,"",IF(AI5<5,"Check",IF(COUNTIF(AC5:AH5,"E")>=4,"Gold",IF(COUNTIF(AC5:AH5,"E")+COUNTIF(AC5:AH5,"S")>=4,"Silver",IF(COUNTIF(AC5:AH5,"E")+COUNTIF(AC5:AH5,"S")+COUNTIF(AC5:AH5,"D")>=4,"Bronze","Participation"))))) | AK5: =IF(AND(ISNUMBER(T5),T5>=1,T5=MAX($T$2:$T$25)),"Y","")
A6: 5 | P6: =IF(COUNT(J6:O6)=0,"",ROUND(AVERAGE(J6:O6),1)) | R6: =IF(Q6="","",ROUND(Q6/12*100,0)) | T6: =IF(AND(ISNUMBER(I6),ISNUMBER(S6)),S6-I6,"") | AA6: =IF(COUNT(U6:Z6)=0,"",ROUND(AVERAGE(U6:Z6),1)) | AB6: =IF(AND(ISNUMBER(P6),ISNUMBER(AA6)),ROUND(AA6-P6,1),"") | AI6: =COUNTIF(AC6:AH6,"B")+COUNTIF(AC6:AH6,"D")+COUNTIF(AC6:AH6,"S")+COUNTIF(AC6:AH6,"E") | AJ6: =IF(COUNTA(AC6:AH6)=0,"",IF(AI6<5,"Check",IF(COUNTIF(AC6:AH6,"E")>=4,"Gold",IF(COUNTIF(AC6:AH6,"E")+COUNTIF(AC6:AH6,"S")>=4,"Silver",IF(COUNTIF(AC6:AH6,"E")+COUNTIF(AC6:AH6,"S")+COUNTIF(AC6:AH6,"D")>=4,"Bronze","Participation"))))) | AK6: =IF(AND(ISNUMBER(T6),T6>=1,T6=MAX($T$2:$T$25)),"Y","")
A7: 6 | P7: =IF(COUNT(J7:O7)=0,"",ROUND(AVERAGE(J7:O7),1)) | R7: =IF(Q7="","",ROUND(Q7/12*100,0)) | T7: =IF(AND(ISNUMBER(I7),ISNUMBER(S7)),S7-I7,"") | AA7: =IF(COUNT(U7:Z7)=0,"",ROUND(AVERAGE(U7:Z7),1)) | AB7: =IF(AND(ISNUMBER(P7),ISNUMBER(AA7)),ROUND(AA7-P7,1),"") | AI7: =COUNTIF(AC7:AH7,"B")+COUNTIF(AC7:AH7,"D")+COUNTIF(AC7:AH7,"S")+COUNTIF(AC7:AH7,"E") | AJ7: =IF(COUNTA(AC7:AH7)=0,"",IF(AI7<5,"Check",IF(COUNTIF(AC7:AH7,"E")>=4,"Gold",IF(COUNTIF(AC7:AH7,"E")+COUNTIF(AC7:AH7,"S")>=4,"Silver",IF(COUNTIF(AC7:AH7,"E")+COUNTIF(AC7:AH7,"S")+COUNTIF(AC7:AH7,"D")>=4,"Bronze","Participation"))))) | AK7: =IF(AND(ISNUMBER(T7),T7>=1,T7=MAX($T$2:$T$25)),"Y","")
A8: 7 | P8: =IF(COUNT(J8:O8)=0,"",ROUND(AVERAGE(J8:O8),1)) | R8: =IF(Q8="","",ROUND(Q8/12*100,0)) | T8: =IF(AND(ISNUMBER(I8),ISNUMBER(S8)),S8-I8,"") | AA8: =IF(COUNT(U8:Z8)=0,"",ROUND(AVERAGE(U8:Z8),1)) | AB8: =IF(AND(ISNUMBER(P8),ISNUMBER(AA8)),ROUND(AA8-P8,1),"") | AI8: =COUNTIF(AC8:AH8,"B")+COUNTIF(AC8:AH8,"D")+COUNTIF(AC8:AH8,"S")+COUNTIF(AC8:AH8,"E") | AJ8: =IF(COUNTA(AC8:AH8)=0,"",IF(AI8<5,"Check",IF(COUNTIF(AC8:AH8,"E")>=4,"Gold",IF(COUNTIF(AC8:AH8,"E")+COUNTIF(AC8:AH8,"S")>=4,"Silver",IF(COUNTIF(AC8:AH8,"E")+COUNTIF(AC8:AH8,"S")+COUNTIF(AC8:AH8,"D")>=4,"Bronze","Participation"))))) | AK8: =IF(AND(ISNUMBER(T8),T8>=1,T8=MAX($T$2:$T$25)),"Y","")
A9: 8 | P9: =IF(COUNT(J9:O9)=0,"",ROUND(AVERAGE(J9:O9),1)) | R9: =IF(Q9="","",ROUND(Q9/12*100,0)) | T9: =IF(AND(ISNUMBER(I9),ISNUMBER(S9)),S9-I9,"") | AA9: =IF(COUNT(U9:Z9)=0,"",ROUND(AVERAGE(U9:Z9),1)) | AB9: =IF(AND(ISNUMBER(P9),ISNUMBER(AA9)),ROUND(AA9-P9,1),"") | AI9: =COUNTIF(AC9:AH9,"B")+COUNTIF(AC9:AH9,"D")+COUNTIF(AC9:AH9,"S")+COUNTIF(AC9:AH9,"E") | AJ9: =IF(COUNTA(AC9:AH9)=0,"",IF(AI9<5,"Check",IF(COUNTIF(AC9:AH9,"E")>=4,"Gold",IF(COUNTIF(AC9:AH9,"E")+COUNTIF(AC9:AH9,"S")>=4,"Silver",IF(COUNTIF(AC9:AH9,"E")+COUNTIF(AC9:AH9,"S")+COUNTIF(AC9:AH9,"D")>=4,"Bronze","Participation"))))) | AK9: =IF(AND(ISNUMBER(T9),T9>=1,T9=MAX($T$2:$T$25)),"Y","")
A10: 9 | P10: =IF(COUNT(J10:O10)=0,"",ROUND(AVERAGE(J10:O10),1)) | R10: =IF(Q10="","",ROUND(Q10/12*100,0)) | T10: =IF(AND(ISNUMBER(I10),ISNUMBER(S10)),S10-I10,"") | AA10: =IF(COUNT(U10:Z10)=0,"",ROUND(AVERAGE(U10:Z10),1)) | AB10: =IF(AND(ISNUMBER(P10),ISNUMBER(AA10)),ROUND(AA10-P10,1),"") | AI10: =COUNTIF(AC10:AH10,"B")+COUNTIF(AC10:AH10,"D")+COUNTIF(AC10:AH10,"S")+COUNTIF(AC10:AH10,"E") | AJ10: =IF(COUNTA(AC10:AH10)=0,"",IF(AI10<5,"Check",IF(COUNTIF(AC10:AH10,"E")>=4,"Gold",IF(COUNTIF(AC10:AH10,"E")+COUNTIF(AC10:AH10,"S")>=4,"Silver",IF(COUNTIF(AC10:AH10,"E")+COUNTIF(AC10:AH10,"S")+COUNTIF(AC10:AH10,"D")>=4,"Bronze","Participation"))))) | AK10: =IF(AND(ISNUMBER(T10),T10>=1,T10=MAX($T$2:$T$25)),"Y","")
A11: 10 | P11: =IF(COUNT(J11:O11)=0,"",ROUND(AVERAGE(J11:O11),1)) | R11: =IF(Q11="","",ROUND(Q11/12*100,0)) | T11: =IF(AND(ISNUMBER(I11),ISNUMBER(S11)),S11-I11,"") | AA11: =IF(COUNT(U11:Z11)=0,"",ROUND(AVERAGE(U11:Z11),1)) | AB11: =IF(AND(ISNUMBER(P11),ISNUMBER(AA11)),ROUND(AA11-P11,1),"") | AI11: =COUNTIF(AC11:AH11,"B")+COUNTIF(AC11:AH11,"D")+COUNTIF(AC11:AH11,"S")+COUNTIF(AC11:AH11,"E") | AJ11: =IF(COUNTA(AC11:AH11)=0,"",IF(AI11<5,"Check",IF(COUNTIF(AC11:AH11,"E")>=4,"Gold",IF(COUNTIF(AC11:AH11,"E")+COUNTIF(AC11:AH11,"S")>=4,"Silver",IF(COUNTIF(AC11:AH11,"E")+COUNTIF(AC11:AH11,"S")+COUNTIF(AC11:AH11,"D")>=4,"Bronze","Participation"))))) | AK11: =IF(AND(ISNUMBER(T11),T11>=1,T11=MAX($T$2:$T$25)),"Y","")
A12: 11 | P12: =IF(COUNT(J12:O12)=0,"",ROUND(AVERAGE(J12:O12),1)) | R12: =IF(Q12="","",ROUND(Q12/12*100,0)) | T12: =IF(AND(ISNUMBER(I12),ISNUMBER(S12)),S12-I12,"") | AA12: =IF(COUNT(U12:Z12)=0,"",ROUND(AVERAGE(U12:Z12),1)) | AB12: =IF(AND(ISNUMBER(P12),ISNUMBER(AA12)),ROUND(AA12-P12,1),"") | AI12: =COUNTIF(AC12:AH12,"B")+COUNTIF(AC12:AH12,"D")+COUNTIF(AC12:AH12,"S")+COUNTIF(AC12:AH12,"E") | AJ12: =IF(COUNTA(AC12:AH12)=0,"",IF(AI12<5,"Check",IF(COUNTIF(AC12:AH12,"E")>=4,"Gold",IF(COUNTIF(AC12:AH12,"E")+COUNTIF(AC12:AH12,"S")>=4,"Silver",IF(COUNTIF(AC12:AH12,"E")+COUNTIF(AC12:AH12,"S")+COUNTIF(AC12:AH12,"D")>=4,"Bronze","Participation"))))) | AK12: =IF(AND(ISNUMBER(T12),T12>=1,T12=MAX($T$2:$T$25)),"Y","")
A13: 12 | P13: =IF(COUNT(J13:O13)=0,"",ROUND(AVERAGE(J13:O13),1)) | R13: =IF(Q13="","",ROUND(Q13/12*100,0)) | T13: =IF(AND(ISNUMBER(I13),ISNUMBER(S13)),S13-I13,"") | AA13: =IF(COUNT(U13:Z13)=0,"",ROUND(AVERAGE(U13:Z13),1)) | AB13: =IF(AND(ISNUMBER(P13),ISNUMBER(AA13)),ROUND(AA13-P13,1),"") | AI13: =COUNTIF(AC13:AH13,"B")+COUNTIF(AC13:AH13,"D")+COUNTIF(AC13:AH13,"S")+COUNTIF(AC13:AH13,"E") | AJ13: =IF(COUNTA(AC13:AH13)=0,"",IF(AI13<5,"Check",IF(COUNTIF(AC13:AH13,"E")>=4,"Gold",IF(COUNTIF(AC13:AH13,"E")+COUNTIF(AC13:AH13,"S")>=4,"Silver",IF(COUNTIF(AC13:AH13,"E")+COUNTIF(AC13:AH13,"S")+COUNTIF(AC13:AH13,"D")>=4,"Bronze","Participation"))))) | AK13: =IF(AND(ISNUMBER(T13),T13>=1,T13=MAX($T$2:$T$25)),"Y","")
... A25: 24 | P25: =IF(COUNT(J25:O25)=0,"",ROUND(AVERAGE(J25:O25),1)) | R25: =IF(Q25="","",ROUND(Q25/12*100,0)) | T25: =IF(AND(ISNUMBER(I25),ISNUMBER(S25)),S25-I25,"") | AA25: =IF(COUNT(U25:Z25)=0,"",ROUND(AVERAGE(U25:Z25),1)) | AB25: =IF(AND(ISNUMBER(P25),ISNUMBER(AA25)),ROUND(AA25-P25,1),"") | AI25: =COUNTIF(AC25:AH25,"B")+COUNTIF(AC25:AH25,"D")+COUNTIF(AC25:AH25,"S")+COUNTIF(AC25:AH25,"E") | AJ25: =IF(COUNTA(AC25:AH25)=0,"",IF(AI25<5,"Check",IF(COUNTIF(AC25:AH25,"E")>=4,"Gold",IF(COUNTIF(AC25:AH25,"E")+COUNTIF(AC25:AH25,"S")>=4,"Silver",IF(COUNTIF(AC25:AH25,"E")+COUNTIF(AC25:AH25,"S")+COUNTIF(AC25:AH25,"D")>=4,"Bronze","Participation"))))) | AK25: =IF(AND(ISNUMBER(T25),T25>=1,T25=MAX($T$2:$T$25)),"Y","")

Sheet Summary
A1: Class | B1: Students | C1: Mean W1 skills check (/20) | D1: Mean W5 checkpoint (/12) | E1: Mean W10 skills check (/20) | F1: Mean growth | G1: Mean W1 survey | H1: Mean W10 survey | I1: Change S1 | J1: Change S2 | K1: Change S3 | L1: Change S4 | M1: Change S5 | N1: Change S6 | O1: Gold | P1: Silver | Q1: Bronze | R1: Participation
A2: Y7_Class1 | B2: =COUNTA('Y7_Class1'!B2:B25) | C2: =IFERROR(ROUND(AVERAGE('Y7_Class1'!I2:I25),1),"") | D2: =IFERROR(ROUND(AVERAGE('Y7_Class1'!Q2:Q25),1),"") | E2: =IFERROR(ROUND(AVERAGE('Y7_Class1'!S2:S25),1),"") | F2: =IFERROR(ROUND(AVERAGE('Y7_Class1'!T2:T25),1),"") | G2: =IFERROR(ROUND(AVERAGE('Y7_Class1'!P2:P25),1),"") | H2: =IFERROR(ROUND(AVERAGE('Y7_Class1'!AA2:AA25),1),"") | I2: =IFERROR(ROUND(AVERAGE('Y7_Class1'!U2:U25)-AVERAGE('Y7_Class1'!J2:J25),1),"") | J2: =IFERROR(ROUND(AVERAGE('Y7_Class1'!V2:V25)-AVERAGE('Y7_Class1'!K2:K25),1),"") | K2: =IFERROR(ROUND(AVERAGE('Y7_Class1'!W2:W25)-AVERAGE('Y7_Class1'!L2:L25),1),"") | L2: =IFERROR(ROUND(AVERAGE('Y7_Class1'!X2:X25)-AVERAGE('Y7_Class1'!M2:M25),1),"") | M2: =IFERROR(ROUND(AVERAGE('Y7_Class1'!Y2:Y25)-AVERAGE('Y7_Class1'!N2:N25),1),"") | N2: =IFERROR(ROUND(AVERAGE('Y7_Class1'!Z2:Z25)-AVERAGE('Y7_Class1'!O2:O25),1),"") | O2: =COUNTIF('Y7_Class1'!AJ2:AJ25,"Gold") | P2: =COUNTIF('Y7_Class1'!AJ2:AJ25,"Silver") | Q2: =COUNTIF('Y7_Class1'!AJ2:AJ25,"Bronze") | R2: =COUNTIF('Y7_Class1'!AJ2:AJ25,"Participation")
A3: Y8_Class1 | B3: =COUNTA('Y8_Class1'!B2:B25) | C3: =IFERROR(ROUND(AVERAGE('Y8_Class1'!I2:I25),1),"") | D3: =IFERROR(ROUND(AVERAGE('Y8_Class1'!Q2:Q25),1),"") | E3: =IFERROR(ROUND(AVERAGE('Y8_Class1'!S2:S25),1),"") | F3: =IFERROR(ROUND(AVERAGE('Y8_Class1'!T2:T25),1),"") | G3: =IFERROR(ROUND(AVERAGE('Y8_Class1'!P2:P25),1),"") | H3: =IFERROR(ROUND(AVERAGE('Y8_Class1'!AA2:AA25),1),"") | I3: =IFERROR(ROUND(AVERAGE('Y8_Class1'!U2:U25)-AVERAGE('Y8_Class1'!J2:J25),1),"") | J3: =IFERROR(ROUND(AVERAGE('Y8_Class1'!V2:V25)-AVERAGE('Y8_Class1'!K2:K25),1),"") | K3: =IFERROR(ROUND(AVERAGE('Y8_Class1'!W2:W25)-AVERAGE('Y8_Class1'!L2:L25),1),"") | L3: =IFERROR(ROUND(AVERAGE('Y8_Class1'!X2:X25)-AVERAGE('Y8_Class1'!M2:M25),1),"") | M3: =IFERROR(ROUND(AVERAGE('Y8_Class1'!Y2:Y25)-AVERAGE('Y8_Class1'!N2:N25),1),"") | N3: =IFERROR(ROUND(AVERAGE('Y8_Class1'!Z2:Z25)-AVERAGE('Y8_Class1'!O2:O25),1),"") | O3: =COUNTIF('Y8_Class1'!AJ2:AJ25,"Gold") | P3: =COUNTIF('Y8_Class1'!AJ2:AJ25,"Silver") | Q3: =COUNTIF('Y8_Class1'!AJ2:AJ25,"Bronze") | R3: =COUNTIF('Y8_Class1'!AJ2:AJ25,"Participation")
A4: Y9_Class1 | B4: =COUNTA('Y9_Class1'!B2:B25) | C4: =IFERROR(ROUND(AVERAGE('Y9_Class1'!I2:I25),1),"") | D4: =IFERROR(ROUND(AVERAGE('Y9_Class1'!Q2:Q25),1),"") | E4: =IFERROR(ROUND(AVERAGE('Y9_Class1'!S2:S25),1),"") | F4: =IFERROR(ROUND(AVERAGE('Y9_Class1'!T2:T25),1),"") | G4: =IFERROR(ROUND(AVERAGE('Y9_Class1'!P2:P25),1),"") | H4: =IFERROR(ROUND(AVERAGE('Y9_Class1'!AA2:AA25),1),"") | I4: =IFERROR(ROUND(AVERAGE('Y9_Class1'!U2:U25)-AVERAGE('Y9_Class1'!J2:J25),1),"") | J4: =IFERROR(ROUND(AVERAGE('Y9_Class1'!V2:V25)-AVERAGE('Y9_Class1'!K2:K25),1),"") | K4: =IFERROR(ROUND(AVERAGE('Y9_Class1'!W2:W25)-AVERAGE('Y9_Class1'!L2:L25),1),"") | L4: =IFERROR(ROUND(AVERAGE('Y9_Class1'!X2:X25)-AVERAGE('Y9_Class1'!M2:M25),1),"") | M4: =IFERROR(ROUND(AVERAGE('Y9_Class1'!Y2:Y25)-AVERAGE('Y9_Class1'!N2:N25),1),"") | N4: =IFERROR(ROUND(AVERAGE('Y9_Class1'!Z2:Z25)-AVERAGE('Y9_Class1'!O2:O25),1),"") | O4: =COUNTIF('Y9_Class1'!AJ2:AJ25,"Gold") | P4: =COUNTIF('Y9_Class1'!AJ2:AJ25,"Silver") | Q4: =COUNTIF('Y9_Class1'!AJ2:AJ25,"Bronze") | R4: =COUNTIF('Y9_Class1'!AJ2:AJ25,"Participation")
A7: Means ignore blank cells, so absent students do not pull a class mean down. Survey changes compare whole-class means. Add a row for each extra class tab (copy row 2 and change the tab name in the formulas).

Sheet Question_analysis
A1: Y7_Class1: skills check marks by question
A2: No. | B2: Student name | C2: W1 Q1 | D2: W1 Q2 | E2: W1 Q3 | F2: W1 Q4 | G2: W1 Q5 | H2: W1 Q6 | I2: W1 Q7 | J2: W1 Q8 | K2: W1 Q9 | L2: W1 Q10 | M2: W1 total | N2: W10 Q1 | O2: W10 Q2 | P2: W10 Q3 | Q2: W10 Q4 | R2: W10 Q5 | S2: W10 Q6 | T2: W10 Q7 | U2: W10 Q8 | V2: W10 Q9 | W2: W10 Q10 | X2: W10 total
B3: Max marks | C3: 2 | D3: 1 | E3: 3 | F3: 2 | G3: 2 | H3: 3 | I3: 1 | J3: 2 | K3: 2 | L3: 2 | M3: 20 | N3: 2 | O3: 1 | P3: 3 | Q3: 2 | R3: 2 | S3: 3 | T3: 1 | U3: 2 | V3: 2 | W3: 2 | X3: 20
A4: ='Y7_Class1'!A2 | B4: =IF('Y7_Class1'!B2="","",'Y7_Class1'!B2) | M4: =IF(COUNT(C4:L4)=0,"",SUM(C4:L4)) | X4: =IF(COUNT(N4:W4)=0,"",SUM(N4:W4))
A5: ='Y7_Class1'!A3 | B5: =IF('Y7_Class1'!B3="","",'Y7_Class1'!B3) | M5: =IF(COUNT(C5:L5)=0,"",SUM(C5:L5)) | X5: =IF(COUNT(N5:W5)=0,"",SUM(N5:W5))
A6: ='Y7_Class1'!A4 | B6: =IF('Y7_Class1'!B4="","",'Y7_Class1'!B4) | M6: =IF(COUNT(C6:L6)=0,"",SUM(C6:L6)) | X6: =IF(COUNT(N6:W6)=0,"",SUM(N6:W6))
A7: ='Y7_Class1'!A5 | B7: =IF('Y7_Class1'!B5="","",'Y7_Class1'!B5) | M7: =IF(COUNT(C7:L7)=0,"",SUM(C7:L7)) | X7: =IF(COUNT(N7:W7)=0,"",SUM(N7:W7))
A8: ='Y7_Class1'!A6 | B8: =IF('Y7_Class1'!B6="","",'Y7_Class1'!B6) | M8: =IF(COUNT(C8:L8)=0,"",SUM(C8:L8)) | X8: =IF(COUNT(N8:W8)=0,"",SUM(N8:W8))
A9: ='Y7_Class1'!A7 | B9: =IF('Y7_Class1'!B7="","",'Y7_Class1'!B7) | M9: =IF(COUNT(C9:L9)=0,"",SUM(C9:L9)) | X9: =IF(COUNT(N9:W9)=0,"",SUM(N9:W9))
A10: ='Y7_Class1'!A8 | B10: =IF('Y7_Class1'!B8="","",'Y7_Class1'!B8) | M10: =IF(COUNT(C10:L10)=0,"",SUM(C10:L10)) | X10: =IF(COUNT(N10:W10)=0,"",SUM(N10:W10))
A11: ='Y7_Class1'!A9 | B11: =IF('Y7_Class1'!B9="","",'Y7_Class1'!B9) | M11: =IF(COUNT(C11:L11)=0,"",SUM(C11:L11)) | X11: =IF(COUNT(N11:W11)=0,"",SUM(N11:W11))
A12: ='Y7_Class1'!A10 | B12: =IF('Y7_Class1'!B10="","",'Y7_Class1'!B10) | M12: =IF(COUNT(C12:L12)=0,"",SUM(C12:L12)) | X12: =IF(COUNT(N12:W12)=0,"",SUM(N12:W12))
A13: ='Y7_Class1'!A11 | B13: =IF('Y7_Class1'!B11="","",'Y7_Class1'!B11) | M13: =IF(COUNT(C13:L13)=0,"",SUM(C13:L13)) | X13: =IF(COUNT(N13:W13)=0,"",SUM(N13:W13))
A14: ='Y7_Class1'!A12 | B14: =IF('Y7_Class1'!B12="","",'Y7_Class1'!B12) | M14: =IF(COUNT(C14:L14)=0,"",SUM(C14:L14)) | X14: =IF(COUNT(N14:W14)=0,"",SUM(N14:W14))
A15: ='Y7_Class1'!A13 | B15: =IF('Y7_Class1'!B13="","",'Y7_Class1'!B13) | M15: =IF(COUNT(C15:L15)=0,"",SUM(C15:L15)) | X15: =IF(COUNT(N15:W15)=0,"",SUM(N15:W15))
... A27: ='Y7_Class1'!A25 | B27: =IF('Y7_Class1'!B25="","",'Y7_Class1'!B25) | M27: =IF(COUNT(C27:L27)=0,"",SUM(C27:L27)) | X27: =IF(COUNT(N27:W27)=0,"",SUM(N27:W27))
B28: % of marks | C28: =IF(COUNT(C4:C27)=0,"",ROUND(SUM(C4:C27)/(COUNT(C4:C27)*C3)*100,0)) | D28: =IF(COUNT(D4:D27)=0,"",ROUND(SUM(D4:D27)/(COUNT(D4:D27)*D3)*100,0)) | E28: =IF(COUNT(E4:E27)=0,"",ROUND(SUM(E4:E27)/(COUNT(E4:E27)*E3)*100,0)) | F28: =IF(COUNT(F4:F27)=0,"",ROUND(SUM(F4:F27)/(COUNT(F4:F27)*F3)*100,0)) | G28: =IF(COUNT(G4:G27)=0,"",ROUND(SUM(G4:G27)/(COUNT(G4:G27)*G3)*100,0)) | H28: =IF(COUNT(H4:H27)=0,"",ROUND(SUM(H4:H27)/(COUNT(H4:H27)*H3)*100,0)) | I28: =IF(COUNT(I4:I27)=0,"",ROUND(SUM(I4:I27)/(COUNT(I4:I27)*I3)*100,0)) | J28: =IF(COUNT(J4:J27)=0,"",ROUND(SUM(J4:J27)/(COUNT(J4:J27)*J3)*100,0)) | ... L28: =IF(COUNT(L4:L27)=0,"",ROUND(SUM(L4:L27)/(COUNT(L4:L27)*L3)*100,0)) | N28: =IF(COUNT(N4:N27)=0,"",ROUND(SUM(N4:N27)/(COUNT(N4:N27)*N3)*100,0)) | O28: =IF(COUNT(O4:O27)=0,"",ROUND(SUM(O4:O27)/(COUNT(O4:O27)*O3)*100,0)) | P28: =IF(COUNT(P4:P27)=0,"",ROUND(SUM(P4:P27)/(COUNT(P4:P27)*P3)*100,0)) | Q28: =IF(COUNT(Q4:Q27)=0,"",ROUND(SUM(Q4:Q27)/(COUNT(Q4:Q27)*Q3)*100,0)) | R28: =IF(COUNT(R4:R27)=0,"",ROUND(SUM(R4:R27)/(COUNT(R4:R27)*R3)*100,0)) | S28: =IF(COUNT(S4:S27)=0,"",ROUND(SUM(S4:S27)/(COUNT(S4:S27)*S3)*100,0)) | T28: =IF(COUNT(T4:T27)=0,"",ROUND(SUM(T4:T27)/(COUNT(T4:T27)*T3)*100,0)) | U28: =IF(COUNT(U4:U27)=0,"",ROUND(SUM(U4:U27)/(COUNT(U4:U27)*U3)*100,0)) | ... W28: =IF(COUNT(W4:W27)=0,"",ROUND(SUM(W4:W27)/(COUNT(W4:W27)*W3)*100,0))
A31: Y8_Class1: skills check marks by question
A32: No. | B32: Student name | C32: W1 Q1 | D32: W1 Q2 | E32: W1 Q3 | F32: W1 Q4 | G32: W1 Q5 | H32: W1 Q6 | I32: W1 Q7 | J32: W1 Q8 | K32: W1 Q9 | L32: W1 Q10 | M32: W1 total | N32: W10 Q1 | O32: W10 Q2 | P32: W10 Q3 | Q32: W10 Q4 | R32: W10 Q5 | S32: W10 Q6 | T32: W10 Q7 | U32: W10 Q8 | V32: W10 Q9 | W32: W10 Q10 | X32: W10 total
B33: Max marks | C33: 2 | D33: 1 | E33: 3 | F33: 2 | G33: 2 | H33: 3 | I33: 1 | J33: 2 | K33: 2 | L33: 2 | M33: 20 | N33: 2 | O33: 1 | P33: 3 | Q33: 2 | R33: 2 | S33: 3 | T33: 1 | U33: 2 | V33: 2 | W33: 2 | X33: 20
A34: ='Y8_Class1'!A2 | B34: =IF('Y8_Class1'!B2="","",'Y8_Class1'!B2) | M34: =IF(COUNT(C34:L34)=0,"",SUM(C34:L34)) | X34: =IF(COUNT(N34:W34)=0,"",SUM(N34:W34))
A35: ='Y8_Class1'!A3 | B35: =IF('Y8_Class1'!B3="","",'Y8_Class1'!B3) | M35: =IF(COUNT(C35:L35)=0,"",SUM(C35:L35)) | X35: =IF(COUNT(N35:W35)=0,"",SUM(N35:W35))
A36: ='Y8_Class1'!A4 | B36: =IF('Y8_Class1'!B4="","",'Y8_Class1'!B4) | M36: =IF(COUNT(C36:L36)=0,"",SUM(C36:L36)) | X36: =IF(COUNT(N36:W36)=0,"",SUM(N36:W36))
A37: ='Y8_Class1'!A5 | B37: =IF('Y8_Class1'!B5="","",'Y8_Class1'!B5) | M37: =IF(COUNT(C37:L37)=0,"",SUM(C37:L37)) | X37: =IF(COUNT(N37:W37)=0,"",SUM(N37:W37))
A38: ='Y8_Class1'!A6 | B38: =IF('Y8_Class1'!B6="","",'Y8_Class1'!B6) | M38: =IF(COUNT(C38:L38)=0,"",SUM(C38:L38)) | X38: =IF(COUNT(N38:W38)=0,"",SUM(N38:W38))
A39: ='Y8_Class1'!A7 | B39: =IF('Y8_Class1'!B7="","",'Y8_Class1'!B7) | M39: =IF(COUNT(C39:L39)=0,"",SUM(C39:L39)) | X39: =IF(COUNT(N39:W39)=0,"",SUM(N39:W39))
A40: ='Y8_Class1'!A8 | B40: =IF('Y8_Class1'!B8="","",'Y8_Class1'!B8) | M40: =IF(COUNT(C40:L40)=0,"",SUM(C40:L40)) | X40: =IF(COUNT(N40:W40)=0,"",SUM(N40:W40))
A41: ='Y8_Class1'!A9 | B41: =IF('Y8_Class1'!B9="","",'Y8_Class1'!B9) | M41: =IF(COUNT(C41:L41)=0,"",SUM(C41:L41)) | X41: =IF(COUNT(N41:W41)=0,"",SUM(N41:W41))
A42: ='Y8_Class1'!A10 | B42: =IF('Y8_Class1'!B10="","",'Y8_Class1'!B10) | M42: =IF(COUNT(C42:L42)=0,"",SUM(C42:L42)) | X42: =IF(COUNT(N42:W42)=0,"",SUM(N42:W42))
A43: ='Y8_Class1'!A11 | B43: =IF('Y8_Class1'!B11="","",'Y8_Class1'!B11) | M43: =IF(COUNT(C43:L43)=0,"",SUM(C43:L43)) | X43: =IF(COUNT(N43:W43)=0,"",SUM(N43:W43))
A44: ='Y8_Class1'!A12 | B44: =IF('Y8_Class1'!B12="","",'Y8_Class1'!B12) | M44: =IF(COUNT(C44:L44)=0,"",SUM(C44:L44)) | X44: =IF(COUNT(N44:W44)=0,"",SUM(N44:W44))
A45: ='Y8_Class1'!A13 | B45: =IF('Y8_Class1'!B13="","",'Y8_Class1'!B13) | M45: =IF(COUNT(C45:L45)=0,"",SUM(C45:L45)) | X45: =IF(COUNT(N45:W45)=0,"",SUM(N45:W45))
... A57: ='Y8_Class1'!A25 | B57: =IF('Y8_Class1'!B25="","",'Y8_Class1'!B25) | M57: =IF(COUNT(C57:L57)=0,"",SUM(C57:L57)) | X57: =IF(COUNT(N57:W57)=0,"",SUM(N57:W57))
B58: % of marks | C58: =IF(COUNT(C34:C57)=0,"",ROUND(SUM(C34:C57)/(COUNT(C34:C57)*C33)*100,0)) | D58: =IF(COUNT(D34:D57)=0,"",ROUND(SUM(D34:D57)/(COUNT(D34:D57)*D33)*100,0)) | E58: =IF(COUNT(E34:E57)=0,"",ROUND(SUM(E34:E57)/(COUNT(E34:E57)*E33)*100,0)) | F58: =IF(COUNT(F34:F57)=0,"",ROUND(SUM(F34:F57)/(COUNT(F34:F57)*F33)*100,0)) | G58: =IF(COUNT(G34:G57)=0,"",ROUND(SUM(G34:G57)/(COUNT(G34:G57)*G33)*100,0)) | H58: =IF(COUNT(H34:H57)=0,"",ROUND(SUM(H34:H57)/(COUNT(H34:H57)*H33)*100,0)) | I58: =IF(COUNT(I34:I57)=0,"",ROUND(SUM(I34:I57)/(COUNT(I34:I57)*I33)*100,0)) | J58: =IF(COUNT(J34:J57)=0,"",ROUND(SUM(J34:J57)/(COUNT(J34:J57)*J33)*100,0)) | ... L58: =IF(COUNT(L34:L57)=0,"",ROUND(SUM(L34:L57)/(COUNT(L34:L57)*L33)*100,0)) | N58: =IF(COUNT(N34:N57)=0,"",ROUND(SUM(N34:N57)/(COUNT(N34:N57)*N33)*100,0)) | O58: =IF(COUNT(O34:O57)=0,"",ROUND(SUM(O34:O57)/(COUNT(O34:O57)*O33)*100,0)) | P58: =IF(COUNT(P34:P57)=0,"",ROUND(SUM(P34:P57)/(COUNT(P34:P57)*P33)*100,0)) | Q58: =IF(COUNT(Q34:Q57)=0,"",ROUND(SUM(Q34:Q57)/(COUNT(Q34:Q57)*Q33)*100,0)) | R58: =IF(COUNT(R34:R57)=0,"",ROUND(SUM(R34:R57)/(COUNT(R34:R57)*R33)*100,0)) | S58: =IF(COUNT(S34:S57)=0,"",ROUND(SUM(S34:S57)/(COUNT(S34:S57)*S33)*100,0)) | T58: =IF(COUNT(T34:T57)=0,"",ROUND(SUM(T34:T57)/(COUNT(T34:T57)*T33)*100,0)) | U58: =IF(COUNT(U34:U57)=0,"",ROUND(SUM(U34:U57)/(COUNT(U34:U57)*U33)*100,0)) | ... W58: =IF(COUNT(W34:W57)=0,"",ROUND(SUM(W34:W57)/(COUNT(W34:W57)*W33)*100,0))
A61: Y9_Class1: skills check marks by question
A62: No. | B62: Student name | C62: W1 Q1 | D62: W1 Q2 | E62: W1 Q3 | F62: W1 Q4 | G62: W1 Q5 | H62: W1 Q6 | I62: W1 Q7 | J62: W1 Q8 | K62: W1 Q9 | L62: W1 Q10 | M62: W1 total | N62: W10 Q1 | O62: W10 Q2 | P62: W10 Q3 | Q62: W10 Q4 | R62: W10 Q5 | S62: W10 Q6 | T62: W10 Q7 | U62: W10 Q8 | V62: W10 Q9 | W62: W10 Q10 | X62: W10 total
B63: Max marks | C63: 2 | D63: 1 | E63: 3 | F63: 2 | G63: 2 | H63: 3 | I63: 1 | J63: 2 | K63: 2 | L63: 2 | M63: 20 | N63: 2 | O63: 1 | P63: 3 | Q63: 2 | R63: 2 | S63: 3 | T63: 1 | U63: 2 | V63: 2 | W63: 2 | X63: 20
A64: ='Y9_Class1'!A2 | B64: =IF('Y9_Class1'!B2="","",'Y9_Class1'!B2) | M64: =IF(COUNT(C64:L64)=0,"",SUM(C64:L64)) | X64: =IF(COUNT(N64:W64)=0,"",SUM(N64:W64))
A65: ='Y9_Class1'!A3 | B65: =IF('Y9_Class1'!B3="","",'Y9_Class1'!B3) | M65: =IF(COUNT(C65:L65)=0,"",SUM(C65:L65)) | X65: =IF(COUNT(N65:W65)=0,"",SUM(N65:W65))
A66: ='Y9_Class1'!A4 | B66: =IF('Y9_Class1'!B4="","",'Y9_Class1'!B4) | M66: =IF(COUNT(C66:L66)=0,"",SUM(C66:L66)) | X66: =IF(COUNT(N66:W66)=0,"",SUM(N66:W66))
...

Sheet Lists
A1: Levels | B1: Roles | C1: Yes | D1: Band
A2: B | B2: Lead | C2: Y | D2: 1
A3: D | B3: Measurer | D3: 2
A4: S | B4: Recorder | D4: 3
A5: E | B5: Safety
A6: N | B6: Reporter
