Workbook

Sheet How_To_Use
B1: Admissions tracker, Years 1 to 10
B2: For the admission assessments of pack v3.1. One workbook for the whole admissions team.
B3: DEMO COPY: every candidate, number and score is fictional and for illustration only. Two rows are left incomplete on purpose so that you can see the Data check working. Demo bands are not worked out from the real band guides. Use Admissions_Tracker_v3.1.xlsx for real candidates.
B5: What it does
B6: Each year group has its own sheet (Year 1 to Year 10) with one row for each candidate. The Dashboard and Levels_Detail sheets count those rows and show where candidates are in the process, their English, maths and science levels, decisions, offers and support needs. You only ever type on the Year sheets.
B8: Using it, step by step
B9: 1. Go to the sheet for the year group the candidate has applied for. Type the candidate on the next empty row (rows 6 to 305).
B10: 2. Type in the white cells with blue text, from left to right, as the process moves on. Use the drop-downs. The sheet will not accept a score above the maximum shown in row 3.
B11: 3. Change the Status each time the candidate reaches the next stage (status table below). A candidate who is assessed but not yet decided stays at Assessed.
B12: 4. After the head of section has confirmed the decision: enter the recommendation, the support level and the dates from the final mark sheet, then set the status to Decision confirmed.
B13: 5. Check the Data check column. OK means the row is complete for its status. Anything else says what is missing. The Dashboard shows how many rows need checking.
B14: 6. Look at the Dashboard and Levels_Detail whenever you want the picture. They update by themselves; do not type on them.
... B17: Colour key
B18: Blue text on white | C18: Type here.
B19: Yellow, blue text, row 3 | C19: The maximum mark from the grading sheet for that year group. Change only if the grading sheet changes.
B20: Grey | C20: Not used in this year group (for example the reading paper in Years 1 to 3).
B21: Blue-grey, black text | C21: Calculated. Do not type.
B22: Red in Data check | C22: The row is incomplete for its status. Fix it.
B23: Band colours | C23: Orange and red tints mark the lower bands, green tints the higher bands, so that a row can be read at a glance.
B25: Status: what each stage means
B26: Applied | C26: Application received. No visit date yet.
B27: Visit booked | C27: Assessment visit arranged.
B28: Assessed | C28: The visit is done and the papers are marked. Waiting for the decision.
B29: Decision confirmed | C29: The head of section has confirmed the recommendation. The family has not been told yet.
B30: Family told | C30: The family has been told the outcome and given the assessment result and report.
B31: Enrolled | C31: An offer has been accepted and the student is joining.
B32: Withdrawn | C32: The family has withdrawn the application, or the school has closed it.
B34: Bands and ratings (full guide: 00_Admissions_Guide.md and each year's grading sheet)
B35: English, A to E | C35: A New to English, B Early acquisition, C Developing competence, D Competent, E Fluent.
B36: Maths and science, 1 to 4 | C36: 1 Well below expected, 2 Working towards, 3 Expected, 4 Greater depth.
B37: Suitability, 1 to 4 | C37: 1 Concern, 2 Some concern, 3 Good, 4 Strong. Enter the lowest rating.
B38: Recommendation | C38: Offer; Offer with English support; Offer with a learning plan; Further assessment before a decision; Unable to offer at this time.
B40: Column guide, with an example for a fictional Year 5 candidate
B41: Column | C41: Example | D41: What to enter | E41: Where it comes from
B42: Candidate number | C42: E05-0001 | D42: The number the school gives the candidate. Use it as the main identifier if the file is shared. | E42: Final mark sheet, top
B43: Name (or initials) | C43: Example Child | D43: Name or initials, as the school's data policy allows. | E43: Final mark sheet, top
B44: Date of birth | C44: 14/03/2016 | D44: Date of birth, day first. Used for age at assessment and the reading age gap. | E44: Final mark sheet, top
B45: Current school | C45: Example Bilingual School | D45: The school the student attends now. | E45: Final mark sheet, top
B46: Boarding (Y/N) | C46: N | D46: Y if the family has applied for boarding, otherwise N. | E46: Application form
B47: Date applied | C47: 01/09/2026 | D47: The day the application was received. | E47: Admissions record
...

Sheet Dashboard
B1: Admissions dashboard, Years 1 to 10
B2: Assessment pack v3.1. Every figure is counted from the Year 1 to Year 10 sheets and updates by itself. Do not type on this sheet.
B3: DEMO COPY: every candidate, number and score here is fictional, to show how the dashboard reads.
B5: CANDIDATES ON FILE | E5: ASSESSED OR LATER | H5: DECISIONS CONFIRMED | K5: OFFERS MADE
B6: =K26 -> 80 | E6: =SUM(E26:H26) -> 60 | H6: =C57 -> 45 | K6: =D57+E57+F57 -> 38
B7: ="of which "&I26&" withdrawn" -> of which 6 withdrawn | E7: =IF(K26=0,"",TEXT(SUM(E26:H26)/K26,"0%")&" of candidates on file") -> 75% of candidates on file | H7: =J57&" assessed, waiting for a decision" -> 15 assessed, waiting for a decision | K7: ="of which "&E57&" with English support" -> of which 31 with English support
B9: OFFER RATE | E9: FAMILIES NOT YET TOLD | H9: DAYS TO TELL THE FAMILY | K9: ROWS TO CHECK
B10: =IF(C57=0,"",(D57+E57+F57)/C57) -> 0.84444444 | E10: =K57 -> 10 | H10: =IFERROR(AVERAGE('Year 1'!$AO$6:$AO$1005,'Year 2'!$AO$6:$AO$1005,'Year 3'!$AO$6:$AO$1005,'Year 4'!$AO$6:$AO$1005,'Year 5'!$AO$6:$AO$1005,'Year 6'!$AO$6:$AO$1005,'Year 7'!$AO$6:$AO$1005,'Year 8'!$AO$6:$AO$1005,'Year 9'!$AO$6:$AO$1005,'Year 10'!$AO$6:$AO$1005),"") -> 6.7352941 | K10: =L26 -> 2
B11: ="offers out of decisions confirmed" -> offers out of decisions confirmed | E11: ="decided, family not yet told" -> decided, family not yet told | H11: ="average, assessment to family told" -> average, assessment to family told | K11: ="see Data check on the Year sheets" -> see Data check on the Year sheets
B13: 1. Where candidates are in the process
B14: Status is chosen on each Year sheet. 'No status' means a row has a name or number but no status yet.
B15: Year group | C15: Applied | D15: Visit booked | E15: Assessed | F15: Decision confirmed | G15: Family told | H15: Enrolled | I15: Withdrawn | J15: No status | K15: Total | L15: Rows to check
B16: Year 1 | C16: =COUNTIF('Year 1'!$J$6:$J$1005,C$15) -> 1 | D16: =COUNTIF('Year 1'!$J$6:$J$1005,D$15) -> 0 | E16: =COUNTIF('Year 1'!$J$6:$J$1005,E$15) -> 0 | F16: =COUNTIF('Year 1'!$J$6:$J$1005,F$15) -> 1 | G16: =COUNTIF('Year 1'!$J$6:$J$1005,G$15) -> 2 | H16: =COUNTIF('Year 1'!$J$6:$J$1005,H$15) -> 2 | I16: =COUNTIF('Year 1'!$J$6:$J$1005,I$15) -> 0 | J16: =K16-SUM(C16:I16) -> 0 | K16: =SUMPRODUCT((('Year 1'!$B$6:$B$1005<>"")+('Year 1'!$A$6:$A$1005<>"")>0)*1) -> 6 | L16: =SUMPRODUCT(('Year 1'!$AP$6:$AP$1005<>"")*('Year 1'!$AP$6:$AP$1005<>"OK")) -> 0
B17: Year 2 | C17: =COUNTIF('Year 2'!$J$6:$J$1005,C$15) -> 1 | D17: =COUNTIF('Year 2'!$J$6:$J$1005,D$15) -> 0 | E17: =COUNTIF('Year 2'!$J$6:$J$1005,E$15) -> 1 | F17: =COUNTIF('Year 2'!$J$6:$J$1005,F$15) -> 2 | G17: =COUNTIF('Year 2'!$J$6:$J$1005,G$15) -> 2 | H17: =COUNTIF('Year 2'!$J$6:$J$1005,H$15) -> 0 | I17: =COUNTIF('Year 2'!$J$6:$J$1005,I$15) -> 1 | J17: =K17-SUM(C17:I17) -> 0 | K17: =SUMPRODUCT((('Year 2'!$B$6:$B$1005<>"")+('Year 2'!$A$6:$A$1005<>"")>0)*1) -> 7 | L17: =SUMPRODUCT(('Year 2'!$AP$6:$AP$1005<>"")*('Year 2'!$AP$6:$AP$1005<>"OK")) -> 0
B18: Year 3 | C18: =COUNTIF('Year 3'!$J$6:$J$1005,C$15) -> 0 | D18: =COUNTIF('Year 3'!$J$6:$J$1005,D$15) -> 1 | E18: =COUNTIF('Year 3'!$J$6:$J$1005,E$15) -> 2 | F18: =COUNTIF('Year 3'!$J$6:$J$1005,F$15) -> 0 | G18: =COUNTIF('Year 3'!$J$6:$J$1005,G$15) -> 4 | H18: =COUNTIF('Year 3'!$J$6:$J$1005,H$15) -> 1 | I18: =COUNTIF('Year 3'!$J$6:$J$1005,I$15) -> 0 | J18: =K18-SUM(C18:I18) -> 0 | K18: =SUMPRODUCT((('Year 3'!$B$6:$B$1005<>"")+('Year 3'!$A$6:$A$1005<>"")>0)*1) -> 8 | L18: =SUMPRODUCT(('Year 3'!$AP$6:$AP$1005<>"")*('Year 3'!$AP$6:$AP$1005<>"OK")) -> 0
B19: Year 4 | C19: =COUNTIF('Year 4'!$J$6:$J$1005,C$15) -> 1 | D19: =COUNTIF('Year 4'!$J$6:$J$1005,D$15) -> 1 | E19: =COUNTIF('Year 4'!$J$6:$J$1005,E$15) -> 2 | F19: =COUNTIF('Year 4'!$J$6:$J$1005,F$15) -> 2 | G19: =COUNTIF('Year 4'!$J$6:$J$1005,G$15) -> 1 | H19: =COUNTIF('Year 4'!$J$6:$J$1005,H$15) -> 1 | I19: =COUNTIF('Year 4'!$J$6:$J$1005,I$15) -> 0 | J19: =K19-SUM(C19:I19) -> 0 | K19: =SUMPRODUCT((('Year 4'!$B$6:$B$1005<>"")+('Year 4'!$A$6:$A$1005<>"")>0)*1) -> 8 | L19: =SUMPRODUCT(('Year 4'!$AP$6:$AP$1005<>"")*('Year 4'!$AP$6:$AP$1005<>"OK")) -> 0
B20: Year 5 | C20: =COUNTIF('Year 5'!$J$6:$J$1005,C$15) -> 0 | D20: =COUNTIF('Year 5'!$J$6:$J$1005,D$15) -> 0 | E20: =COUNTIF('Year 5'!$J$6:$J$1005,E$15) -> 3 | F20: =COUNTIF('Year 5'!$J$6:$J$1005,F$15) -> 0 | G20: =COUNTIF('Year 5'!$J$6:$J$1005,G$15) -> 2 | H20: =COUNTIF('Year 5'!$J$6:$J$1005,H$15) -> 2 | I20: =COUNTIF('Year 5'!$J$6:$J$1005,I$15) -> 2 | J20: =K20-SUM(C20:I20) -> 0 | K20: =SUMPRODUCT((('Year 5'!$B$6:$B$1005<>"")+('Year 5'!$A$6:$A$1005<>"")>0)*1) -> 9 | L20: =SUMPRODUCT(('Year 5'!$AP$6:$AP$1005<>"")*('Year 5'!$AP$6:$AP$1005<>"OK")) -> 1
B21: Year 6 | C21: =COUNTIF('Year 6'!$J$6:$J$1005,C$15) -> 0 | D21: =COUNTIF('Year 6'!$J$6:$J$1005,D$15) -> 1 | E21: =COUNTIF('Year 6'!$J$6:$J$1005,E$15) -> 1 | F21: =COUNTIF('Year 6'!$J$6:$J$1005,F$15) -> 2 | G21: =COUNTIF('Year 6'!$J$6:$J$1005,G$15) -> 3 | H21: =COUNTIF('Year 6'!$J$6:$J$1005,H$15) -> 1 | I21: =COUNTIF('Year 6'!$J$6:$J$1005,I$15) -> 1 | J21: =K21-SUM(C21:I21) -> 0 | K21: =SUMPRODUCT((('Year 6'!$B$6:$B$1005<>"")+('Year 6'!$A$6:$A$1005<>"")>0)*1) -> 9 | L21: =SUMPRODUCT(('Year 6'!$AP$6:$AP$1005<>"")*('Year 6'!$AP$6:$AP$1005<>"OK")) -> 0
B22: Year 7 | C22: =COUNTIF('Year 7'!$J$6:$J$1005,C$15) -> 3 | D22: =COUNTIF('Year 7'!$J$6:$J$1005,D$15) -> 0 | E22: =COUNTIF('Year 7'!$J$6:$J$1005,E$15) -> 2 | F22: =COUNTIF('Year 7'!$J$6:$J$1005,F$15) -> 1 | G22: =COUNTIF('Year 7'!$J$6:$J$1005,G$15) -> 3 | H22: =COUNTIF('Year 7'!$J$6:$J$1005,H$15) -> 0 | I22: =COUNTIF('Year 7'!$J$6:$J$1005,I$15) -> 0 | J22: =K22-SUM(C22:I22) -> 0 | K22: =SUMPRODUCT((('Year 7'!$B$6:$B$1005<>"")+('Year 7'!$A$6:$A$1005<>"")>0)*1) -> 9 | L22: =SUMPRODUCT(('Year 7'!$AP$6:$AP$1005<>"")*('Year 7'!$AP$6:$AP$1005<>"OK")) -> 0
B23: Year 8 | C23: =COUNTIF('Year 8'!$J$6:$J$1005,C$15) -> 1 | D23: =COUNTIF('Year 8'!$J$6:$J$1005,D$15) -> 1 | E23: =COUNTIF('Year 8'!$J$6:$J$1005,E$15) -> 0 | F23: =COUNTIF('Year 8'!$J$6:$J$1005,F$15) -> 0 | G23: =COUNTIF('Year 8'!$J$6:$J$1005,G$15) -> 4 | H23: =COUNTIF('Year 8'!$J$6:$J$1005,H$15) -> 2 | I23: =COUNTIF('Year 8'!$J$6:$J$1005,I$15) -> 0 | J23: =K23-SUM(C23:I23) -> 0 | K23: =SUMPRODUCT((('Year 8'!$B$6:$B$1005<>"")+('Year 8'!$A$6:$A$1005<>"")>0)*1) -> 8 | L23: =SUMPRODUCT(('Year 8'!$AP$6:$AP$1005<>"")*('Year 8'!$AP$6:$AP$1005<>"OK")) -> 1
B24: Year 9 | C24: =COUNTIF('Year 9'!$J$6:$J$1005,C$15) -> 0 | D24: =COUNTIF('Year 9'!$J$6:$J$1005,D$15) -> 1 | E24: =COUNTIF('Year 9'!$J$6:$J$1005,E$15) -> 1 | F24: =COUNTIF('Year 9'!$J$6:$J$1005,F$15) -> 1 | G24: =COUNTIF('Year 9'!$J$6:$J$1005,G$15) -> 3 | H24: =COUNTIF('Year 9'!$J$6:$J$1005,H$15) -> 1 | I24: =COUNTIF('Year 9'!$J$6:$J$1005,I$15) -> 1 | J24: =K24-SUM(C24:I24) -> 0 | K24: =SUMPRODUCT((('Year 9'!$B$6:$B$1005<>"")+('Year 9'!$A$6:$A$1005<>"")>0)*1) -> 8 | L24: =SUMPRODUCT(('Year 9'!$AP$6:$AP$1005<>"")*('Year 9'!$AP$6:$AP$1005<>"OK")) -> 0
B25: Year 10 | C25: =COUNTIF('Year 10'!$J$6:$J$1005,C$15) -> 1 | D25: =COUNTIF('Year 10'!$J$6:$J$1005,D$15) -> 1 | E25: =COUNTIF('Year 10'!$J$6:$J$1005,E$15) -> 3 | F25: =COUNTIF('Year 10'!$J$6:$J$1005,F$15) -> 1 | G25: =COUNTIF('Year 10'!$J$6:$J$1005,G$15) -> 0 | H25: =COUNTIF('Year 10'!$J$6:$J$1005,H$15) -> 1 | I25: =COUNTIF('Year 10'!$J$6:$J$1005,I$15) -> 1 | J25: =K25-SUM(C25:I25) -> 0 | K25: =SUMPRODUCT((('Year 10'!$B$6:$B$1005<>"")+('Year 10'!$A$6:$A$1005<>"")>0)*1) -> 8 | L25: =SUMPRODUCT(('Year 10'!$AP$6:$AP$1005<>"")*('Year 10'!$AP$6:$AP$1005<>"OK")) -> 0
B26: All years | C26: =SUM(C16:C25) -> 8 | D26: =SUM(D16:D25) -> 6 | E26: =SUM(E16:E25) -> 15 | F26: =SUM(F16:F25) -> 10 | G26: =SUM(G16:G25) -> 24 | H26: =SUM(H16:H25) -> 11 | I26: =SUM(I16:I25) -> 6 | J26: =SUM(J16:J25) -> 0 | ... L26: =SUM(L16:L25) -> 2
B28: 2. Overall English band
B29: A New to English, B Early acquisition, C Developing competence, D Competent, E Fluent. Counts every candidate with a band entered.
B30: Year group | C30: A | D30: B | E30: C | F30: D | G30: E | H30: Banded | I30: A or B (share) | J30: D or E (share)
B31: Year 1 | C31: =COUNTIF('Year 1'!$V$6:$V$1005,C$30) -> 1 | D31: =COUNTIF('Year 1'!$V$6:$V$1005,D$30) -> 1 | E31: =COUNTIF('Year 1'!$V$6:$V$1005,E$30) -> 3 | F31: =COUNTIF('Year 1'!$V$6:$V$1005,F$30) -> 0 | G31: =COUNTIF('Year 1'!$V$6:$V$1005,G$30) -> 0 | H31: =SUM(C31:G31) -> 5 | I31: =IF(H31=0,"",(C31+D31)/H31) -> 0.4 | J31: =IF(H31=0,"",(F31+G31)/H31) -> 0
B32: Year 2 | C32: =COUNTIF('Year 2'!$V$6:$V$1005,C$30) -> 1 | D32: =COUNTIF('Year 2'!$V$6:$V$1005,D$30) -> 0 | E32: =COUNTIF('Year 2'!$V$6:$V$1005,E$30) -> 3 | F32: =COUNTIF('Year 2'!$V$6:$V$1005,F$30) -> 1 | G32: =COUNTIF('Year 2'!$V$6:$V$1005,G$30) -> 0 | H32: =SUM(C32:G32) -> 5 | I32: =IF(H32=0,"",(C32+D32)/H32) -> 0.2 | J32: =IF(H32=0,"",(F32+G32)/H32) -> 0.2
B33: Year 3 | C33: =COUNTIF('Year 3'!$V$6:$V$1005,C$30) -> 2 | D33: =COUNTIF('Year 3'!$V$6:$V$1005,D$30) -> 2 | E33: =COUNTIF('Year 3'!$V$6:$V$1005,E$30) -> 1 | F33: =COUNTIF('Year 3'!$V$6:$V$1005,F$30) -> 2 | G33: =COUNTIF('Year 3'!$V$6:$V$1005,G$30) -> 0 | H33: =SUM(C33:G33) -> 7 | I33: =IF(H33=0,"",(C33+D33)/H33) -> 0.57142857 | J33: =IF(H33=0,"",(F33+G33)/H33) -> 0.28571429
B34: Year 4 | C34: =COUNTIF('Year 4'!$V$6:$V$1005,C$30) -> 0 | D34: =COUNTIF('Year 4'!$V$6:$V$1005,D$30) -> 4 | E34: =COUNTIF('Year 4'!$V$6:$V$1005,E$30) -> 2 | F34: =COUNTIF('Year 4'!$V$6:$V$1005,F$30) -> 0 | G34: =COUNTIF('Year 4'!$V$6:$V$1005,G$30) -> 0 | H34: =SUM(C34:G34) -> 6 | I34: =IF(H34=0,"",(C34+D34)/H34) -> 0.66666667 | J34: =IF(H34=0,"",(F34+G34)/H34) -> 0
B35: Year 5 | C35: =COUNTIF('Year 5'!$V$6:$V$1005,C$30) -> 1 | D35: =COUNTIF('Year 5'!$V$6:$V$1005,D$30) -> 3 | E35: =COUNTIF('Year 5'!$V$6:$V$1005,E$30) -> 3 | F35: =COUNTIF('Year 5'!$V$6:$V$1005,F$30) -> 0 | G35: =COUNTIF('Year 5'!$V$6:$V$1005,G$30) -> 0 | H35: =SUM(C35:G35) -> 7 | I35: =IF(H35=0,"",(C35+D35)/H35) -> 0.57142857 | J35: =IF(H35=0,"",(F35+G35)/H35) -> 0
B36: Year 6 | C36: =COUNTIF('Year 6'!$V$6:$V$1005,C$30) -> 0 | D36: =COUNTIF('Year 6'!$V$6:$V$1005,D$30) -> 4 | E36: =COUNTIF('Year 6'!$V$6:$V$1005,E$30) -> 2 | F36: =COUNTIF('Year 6'!$V$6:$V$1005,F$30) -> 1 | G36: =COUNTIF('Year 6'!$V$6:$V$1005,G$30) -> 0 | H36: =SUM(C36:G36) -> 7 | I36: =IF(H36=0,"",(C36+D36)/H36) -> 0.57142857 | J36: =IF(H36=0,"",(F36+G36)/H36) -> 0.14285714
B37: Year 7 | C37: =COUNTIF('Year 7'!$V$6:$V$1005,C$30) -> 1 | D37: =COUNTIF('Year 7'!$V$6:$V$1005,D$30) -> 2 | E37: =COUNTIF('Year 7'!$V$6:$V$1005,E$30) -> 3 | F37: =COUNTIF('Year 7'!$V$6:$V$1005,F$30) -> 0 | G37: =COUNTIF('Year 7'!$V$6:$V$1005,G$30) -> 0 | H37: =SUM(C37:G37) -> 6 | I37: =IF(H37=0,"",(C37+D37)/H37) -> 0.5 | J37: =IF(H37=0,"",(F37+G37)/H37) -> 0
B38: Year 8 | C38: =COUNTIF('Year 8'!$V$6:$V$1005,C$30) -> 1 | D38: =COUNTIF('Year 8'!$V$6:$V$1005,D$30) -> 2 | E38: =COUNTIF('Year 8'!$V$6:$V$1005,E$30) -> 3 | F38: =COUNTIF('Year 8'!$V$6:$V$1005,F$30) -> 0 | G38: =COUNTIF('Year 8'!$V$6:$V$1005,G$30) -> 0 | H38: =SUM(C38:G38) -> 6 | I38: =IF(H38=0,"",(C38+D38)/H38) -> 0.5 | J38: =IF(H38=0,"",(F38+G38)/H38) -> 0
B39: Year 9 | C39: =COUNTIF('Year 9'!$V$6:$V$1005,C$30) -> 0 | D39: =COUNTIF('Year 9'!$V$6:$V$1005,D$30) -> 2 | E39: =COUNTIF('Year 9'!$V$6:$V$1005,E$30) -> 2 | F39: =COUNTIF('Year 9'!$V$6:$V$1005,F$30) -> 1 | G39: =COUNTIF('Year 9'!$V$6:$V$1005,G$30) -> 1 | H39: =SUM(C39:G39) -> 6 | I39: =IF(H39=0,"",(C39+D39)/H39) -> 0.33333333 | J39: =IF(H39=0,"",(F39+G39)/H39) -> 0.33333333
B40: Year 10 | C40: =COUNTIF('Year 10'!$V$6:$V$1005,C$30) -> 1 | D40: =COUNTIF('Year 10'!$V$6:$V$1005,D$30) -> 1 | E40: =COUNTIF('Year 10'!$V$6:$V$1005,E$30) -> 2 | F40: =COUNTIF('Year 10'!$V$6:$V$1005,F$30) -> 1 | G40: =COUNTIF('Year 10'!$V$6:$V$1005,G$30) -> 0 | H40: =SUM(C40:G40) -> 5 | I40: =IF(H40=0,"",(C40+D40)/H40) -> 0.4 | J40: =IF(H40=0,"",(F40+G40)/H40) -> 0.2
B41: All years | C41: =SUM(C31:C40) -> 8 | D41: =SUM(D31:D40) -> 21 | E41: =SUM(E31:E40) -> 24 | F41: =SUM(F31:F40) -> 6 | G41: =SUM(G31:G40) -> 1 | H41: =SUM(H31:H40) -> 60 | I41: =IF(H41=0,"",(C41+D41)/H41) -> 0.48333333 | J41: =IF(H41=0,"",(F41+G41)/H41) -> 0.11666667
B44: 3. Decisions and offers
B45: Counts candidates whose status is Decision confirmed, Family told or Enrolled. Offer rate is the three kinds of offer divided by decisions confirmed.
B46: Year group | C46: Decisions confirmed | D46: Offer | E46: Offer with English support | F46: Offer with a learning plan | G46: Further assessment before a decision | H46: Unable to offer at this time | I46: Offer rate | J46: Assessed, no decision yet | K46: Decided, family not yet told
...

Sheet Levels_Detail
B1: Levels in detail, Years 1 to 10
B2: Each English skill by year group, and average scores. Counted from the Year sheets; do not type on this sheet.
B3: DEMO COPY: every candidate, number and score here is fictional, to show how the dashboard reads.
B5: Share of candidates banded D or E, by skill
B6: Year group | C6: Listening | D6: Speaking | E6: Reading | F6: Reading aloud (indicative) | G6: Writing | H6: Overall English
B7: Year 1 | C7: =IFERROR((COUNTIF('Year 1'!$L$6:$L$1005,"D")+COUNTIF('Year 1'!$L$6:$L$1005,"E"))/COUNTA('Year 1'!$L$6:$L$1005),"") -> 0 | D7: =IFERROR((COUNTIF('Year 1'!$M$6:$M$1005,"D")+COUNTIF('Year 1'!$M$6:$M$1005,"E"))/COUNTA('Year 1'!$M$6:$M$1005),"") -> 0.2 | E7: =IFERROR((COUNTIF('Year 1'!$P$6:$P$1005,"D")+COUNTIF('Year 1'!$P$6:$P$1005,"E"))/COUNTA('Year 1'!$P$6:$P$1005),"") -> 0 | F7: =IFERROR((COUNTIF('Year 1'!$S$6:$S$1005,"D")+COUNTIF('Year 1'!$S$6:$S$1005,"E"))/COUNTA('Year 1'!$S$6:$S$1005),"") -> 1 | G7: =IFERROR((COUNTIF('Year 1'!$U$6:$U$1005,"D")+COUNTIF('Year 1'!$U$6:$U$1005,"E"))/COUNTA('Year 1'!$U$6:$U$1005),"") -> 0 | H7: =IFERROR((COUNTIF('Year 1'!$V$6:$V$1005,"D")+COUNTIF('Year 1'!$V$6:$V$1005,"E"))/COUNTA('Year 1'!$V$6:$V$1005),"") -> 0
B8: Year 2 | C8: =IFERROR((COUNTIF('Year 2'!$L$6:$L$1005,"D")+COUNTIF('Year 2'!$L$6:$L$1005,"E"))/COUNTA('Year 2'!$L$6:$L$1005),"") -> 0.6 | D8: =IFERROR((COUNTIF('Year 2'!$M$6:$M$1005,"D")+COUNTIF('Year 2'!$M$6:$M$1005,"E"))/COUNTA('Year 2'!$M$6:$M$1005),"") -> 0.4 | E8: =IFERROR((COUNTIF('Year 2'!$P$6:$P$1005,"D")+COUNTIF('Year 2'!$P$6:$P$1005,"E"))/COUNTA('Year 2'!$P$6:$P$1005),"") -> 0.2 | F8: =IFERROR((COUNTIF('Year 2'!$S$6:$S$1005,"D")+COUNTIF('Year 2'!$S$6:$S$1005,"E"))/COUNTA('Year 2'!$S$6:$S$1005),"") -> 0.8 | G8: =IFERROR((COUNTIF('Year 2'!$U$6:$U$1005,"D")+COUNTIF('Year 2'!$U$6:$U$1005,"E"))/COUNTA('Year 2'!$U$6:$U$1005),"") -> 0.2 | H8: =IFERROR((COUNTIF('Year 2'!$V$6:$V$1005,"D")+COUNTIF('Year 2'!$V$6:$V$1005,"E"))/COUNTA('Year 2'!$V$6:$V$1005),"") -> 0.2
B9: Year 3 | C9: =IFERROR((COUNTIF('Year 3'!$L$6:$L$1005,"D")+COUNTIF('Year 3'!$L$6:$L$1005,"E"))/COUNTA('Year 3'!$L$6:$L$1005),"") -> 0.28571429 | D9: =IFERROR((COUNTIF('Year 3'!$M$6:$M$1005,"D")+COUNTIF('Year 3'!$M$6:$M$1005,"E"))/COUNTA('Year 3'!$M$6:$M$1005),"") -> 0.14285714 | E9: =IFERROR((COUNTIF('Year 3'!$P$6:$P$1005,"D")+COUNTIF('Year 3'!$P$6:$P$1005,"E"))/COUNTA('Year 3'!$P$6:$P$1005),"") -> 0.28571429 | F9: =IFERROR((COUNTIF('Year 3'!$S$6:$S$1005,"D")+COUNTIF('Year 3'!$S$6:$S$1005,"E"))/COUNTA('Year 3'!$S$6:$S$1005),"") -> 0.42857143 | G9: =IFERROR((COUNTIF('Year 3'!$U$6:$U$1005,"D")+COUNTIF('Year 3'!$U$6:$U$1005,"E"))/COUNTA('Year 3'!$U$6:$U$1005),"") -> 0.28571429 | H9: =IFERROR((COUNTIF('Year 3'!$V$6:$V$1005,"D")+COUNTIF('Year 3'!$V$6:$V$1005,"E"))/COUNTA('Year 3'!$V$6:$V$1005),"") -> 0.28571429
B10: Year 4 | C10: =IFERROR((COUNTIF('Year 4'!$L$6:$L$1005,"D")+COUNTIF('Year 4'!$L$6:$L$1005,"E"))/COUNTA('Year 4'!$L$6:$L$1005),"") -> 0.16666667 | D10: =IFERROR((COUNTIF('Year 4'!$M$6:$M$1005,"D")+COUNTIF('Year 4'!$M$6:$M$1005,"E"))/COUNTA('Year 4'!$M$6:$M$1005),"") -> 0.16666667 | E10: =IFERROR((COUNTIF('Year 4'!$P$6:$P$1005,"D")+COUNTIF('Year 4'!$P$6:$P$1005,"E"))/COUNTA('Year 4'!$P$6:$P$1005),"") -> 0 | F10: =IFERROR((COUNTIF('Year 4'!$S$6:$S$1005,"D")+COUNTIF('Year 4'!$S$6:$S$1005,"E"))/COUNTA('Year 4'!$S$6:$S$1005),"") -> 0.33333333 | G10: =IFERROR((COUNTIF('Year 4'!$U$6:$U$1005,"D")+COUNTIF('Year 4'!$U$6:$U$1005,"E"))/COUNTA('Year 4'!$U$6:$U$1005),"") -> 0 | H10: =IFERROR((COUNTIF('Year 4'!$V$6:$V$1005,"D")+COUNTIF('Year 4'!$V$6:$V$1005,"E"))/COUNTA('Year 4'!$V$6:$V$1005),"") -> 0
B11: Year 5 | C11: =IFERROR((COUNTIF('Year 5'!$L$6:$L$1005,"D")+COUNTIF('Year 5'!$L$6:$L$1005,"E"))/COUNTA('Year 5'!$L$6:$L$1005),"") -> 0 | D11: =IFERROR((COUNTIF('Year 5'!$M$6:$M$1005,"D")+COUNTIF('Year 5'!$M$6:$M$1005,"E"))/COUNTA('Year 5'!$M$6:$M$1005),"") -> 0 | E11: =IFERROR((COUNTIF('Year 5'!$P$6:$P$1005,"D")+COUNTIF('Year 5'!$P$6:$P$1005,"E"))/COUNTA('Year 5'!$P$6:$P$1005),"") -> 0.14285714 | F11: =IFERROR((COUNTIF('Year 5'!$S$6:$S$1005,"D")+COUNTIF('Year 5'!$S$6:$S$1005,"E"))/COUNTA('Year 5'!$S$6:$S$1005),"") -> 0.28571429 | G11: =IFERROR((COUNTIF('Year 5'!$U$6:$U$1005,"D")+COUNTIF('Year 5'!$U$6:$U$1005,"E"))/COUNTA('Year 5'!$U$6:$U$1005),"") -> 0.14285714 | H11: =IFERROR((COUNTIF('Year 5'!$V$6:$V$1005,"D")+COUNTIF('Year 5'!$V$6:$V$1005,"E"))/COUNTA('Year 5'!$V$6:$V$1005),"") -> 0
B12: Year 6 | C12: =IFERROR((COUNTIF('Year 6'!$L$6:$L$1005,"D")+COUNTIF('Year 6'!$L$6:$L$1005,"E"))/COUNTA('Year 6'!$L$6:$L$1005),"") -> 0.14285714 | D12: =IFERROR((COUNTIF('Year 6'!$M$6:$M$1005,"D")+COUNTIF('Year 6'!$M$6:$M$1005,"E"))/COUNTA('Year 6'!$M$6:$M$1005),"") -> 0.14285714 | E12: =IFERROR((COUNTIF('Year 6'!$P$6:$P$1005,"D")+COUNTIF('Year 6'!$P$6:$P$1005,"E"))/COUNTA('Year 6'!$P$6:$P$1005),"") -> 0.14285714 | F12: =IFERROR((COUNTIF('Year 6'!$S$6:$S$1005,"D")+COUNTIF('Year 6'!$S$6:$S$1005,"E"))/COUNTA('Year 6'!$S$6:$S$1005),"") -> 0.71428571 | G12: =IFERROR((COUNTIF('Year 6'!$U$6:$U$1005,"D")+COUNTIF('Year 6'!$U$6:$U$1005,"E"))/COUNTA('Year 6'!$U$6:$U$1005),"") -> 0.14285714 | H12: =IFERROR((COUNTIF('Year 6'!$V$6:$V$1005,"D")+COUNTIF('Year 6'!$V$6:$V$1005,"E"))/COUNTA('Year 6'!$V$6:$V$1005),"") -> 0.14285714
B13: Year 7 | C13: =IFERROR((COUNTIF('Year 7'!$L$6:$L$1005,"D")+COUNTIF('Year 7'!$L$6:$L$1005,"E"))/COUNTA('Year 7'!$L$6:$L$1005),"") -> 0.16666667 | D13: =IFERROR((COUNTIF('Year 7'!$M$6:$M$1005,"D")+COUNTIF('Year 7'!$M$6:$M$1005,"E"))/COUNTA('Year 7'!$M$6:$M$1005),"") -> 0 | E13: =IFERROR((COUNTIF('Year 7'!$P$6:$P$1005,"D")+COUNTIF('Year 7'!$P$6:$P$1005,"E"))/COUNTA('Year 7'!$P$6:$P$1005),"") -> 0.16666667 | F13: =IFERROR((COUNTIF('Year 7'!$S$6:$S$1005,"D")+COUNTIF('Year 7'!$S$6:$S$1005,"E"))/COUNTA('Year 7'!$S$6:$S$1005),"") -> 0.83333333 | G13: =IFERROR((COUNTIF('Year 7'!$U$6:$U$1005,"D")+COUNTIF('Year 7'!$U$6:$U$1005,"E"))/COUNTA('Year 7'!$U$6:$U$1005),"") -> 0 | H13: =IFERROR((COUNTIF('Year 7'!$V$6:$V$1005,"D")+COUNTIF('Year 7'!$V$6:$V$1005,"E"))/COUNTA('Year 7'!$V$6:$V$1005),"") -> 0
B14: Year 8 | C14: =IFERROR((COUNTIF('Year 8'!$L$6:$L$1005,"D")+COUNTIF('Year 8'!$L$6:$L$1005,"E"))/COUNTA('Year 8'!$L$6:$L$1005),"") -> 0 | D14: =IFERROR((COUNTIF('Year 8'!$M$6:$M$1005,"D")+COUNTIF('Year 8'!$M$6:$M$1005,"E"))/COUNTA('Year 8'!$M$6:$M$1005),"") -> 0 | E14: =IFERROR((COUNTIF('Year 8'!$P$6:$P$1005,"D")+COUNTIF('Year 8'!$P$6:$P$1005,"E"))/COUNTA('Year 8'!$P$6:$P$1005),"") -> 0.33333333 | F14: =IFERROR((COUNTIF('Year 8'!$S$6:$S$1005,"D")+COUNTIF('Year 8'!$S$6:$S$1005,"E"))/COUNTA('Year 8'!$S$6:$S$1005),"") -> 0.66666667 | G14: =IFERROR((COUNTIF('Year 8'!$U$6:$U$1005,"D")+COUNTIF('Year 8'!$U$6:$U$1005,"E"))/COUNTA('Year 8'!$U$6:$U$1005),"") -> 0 | H14: =IFERROR((COUNTIF('Year 8'!$V$6:$V$1005,"D")+COUNTIF('Year 8'!$V$6:$V$1005,"E"))/COUNTA('Year 8'!$V$6:$V$1005),"") -> 0
B15: Year 9 | C15: =IFERROR((COUNTIF('Year 9'!$L$6:$L$1005,"D")+COUNTIF('Year 9'!$L$6:$L$1005,"E"))/COUNTA('Year 9'!$L$6:$L$1005),"") -> 0.33333333 | D15: =IFERROR((COUNTIF('Year 9'!$M$6:$M$1005,"D")+COUNTIF('Year 9'!$M$6:$M$1005,"E"))/COUNTA('Year 9'!$M$6:$M$1005),"") -> 0.33333333 | E15: =IFERROR((COUNTIF('Year 9'!$P$6:$P$1005,"D")+COUNTIF('Year 9'!$P$6:$P$1005,"E"))/COUNTA('Year 9'!$P$6:$P$1005),"") -> 0.33333333 | F15: =IFERROR((COUNTIF('Year 9'!$S$6:$S$1005,"D")+COUNTIF('Year 9'!$S$6:$S$1005,"E"))/COUNTA('Year 9'!$S$6:$S$1005),"") -> 0.83333333 | G15: =IFERROR((COUNTIF('Year 9'!$U$6:$U$1005,"D")+COUNTIF('Year 9'!$U$6:$U$1005,"E"))/COUNTA('Year 9'!$U$6:$U$1005),"") -> 0.33333333 | H15: =IFERROR((COUNTIF('Year 9'!$V$6:$V$1005,"D")+COUNTIF('Year 9'!$V$6:$V$1005,"E"))/COUNTA('Year 9'!$V$6:$V$1005),"") -> 0.33333333
B16: Year 10 | C16: =IFERROR((COUNTIF('Year 10'!$L$6:$L$1005,"D")+COUNTIF('Year 10'!$L$6:$L$1005,"E"))/COUNTA('Year 10'!$L$6:$L$1005),"") -> 0.2 | D16: =IFERROR((COUNTIF('Year 10'!$M$6:$M$1005,"D")+COUNTIF('Year 10'!$M$6:$M$1005,"E"))/COUNTA('Year 10'!$M$6:$M$1005),"") -> 0 | E16: =IFERROR((COUNTIF('Year 10'!$P$6:$P$1005,"D")+COUNTIF('Year 10'!$P$6:$P$1005,"E"))/COUNTA('Year 10'!$P$6:$P$1005),"") -> 0.2 | F16: =IFERROR((COUNTIF('Year 10'!$S$6:$S$1005,"D")+COUNTIF('Year 10'!$S$6:$S$1005,"E"))/COUNTA('Year 10'!$S$6:$S$1005),"") -> 0.8 | G16: =IFERROR((COUNTIF('Year 10'!$U$6:$U$1005,"D")+COUNTIF('Year 10'!$U$6:$U$1005,"E"))/COUNTA('Year 10'!$U$6:$U$1005),"") -> 0.2 | H16: =IFERROR((COUNTIF('Year 10'!$V$6:$V$1005,"D")+COUNTIF('Year 10'!$V$6:$V$1005,"E"))/COUNTA('Year 10'!$V$6:$V$1005),"") -> 0.2
B17: All years | C17: =IFERROR((COUNTIF('Year 1'!$L$6:$L$1005,"D")+COUNTIF('Year 1'!$L$6:$L$1005,"E")+COUNTIF('Year 2'!$L$6:$L$1005,"D")+COUNTIF('Year 2'!$L$6:$L$1005,"E")+COUNTIF('Year 3'!$L$6:$L$1005,"D")+COUNTIF('Year 3'!$L$6:$L$1005,"E")+COUNTIF('Year 4'!$L$6:$L$1005,"D")+COUNTIF('Year 4'!$L$6:$L$1005,"E")+COUNTIF('Year 5'!$L$6:$L$1005,"D")+COUNTIF('Year 5'!$L$6:$L$1005,"E")+COUNTIF('Year 6'!$L$6:$L$1005,"D")+COUNTIF('Year 6'!$L$6:$L$1005,"E")+COUNTIF('Year 7'!$L$6:$L$1005,"D")+COUNTIF('Year 7'!$L$6:$L$1005,"E")+COUNTIF('Year 8'!$L$6:$L$1005,"D")+COUNTIF('Year 8'!$L$6:$L$1005,"E")+COUNTIF('Year 9'!$L$6:$L$1005,"D")+COUNTIF('Year 9'!$L$6:$L$1005,"E")+COUNTIF('Year 10'!$L$6:$L$1005,"D")+COUNTIF('Year 10'!$L$6:$L$1005,"E"))/(COUNTA('Year 1'!$L$6:$L$1005)+COUNTA('Year 2'!$L$6:$L$1005)+COUNTA('Year 3'!$L$6:$L$1005)+COUNTA('Year 4'!$L$6:$L$1005)+COUNTA('Year 5'!$L$6:$L$1005)+COUNTA('Year 6'!$L$6:$L$1005)+COUNTA('Year 7'!$L$6:$L$1005)+COUNTA('Year 8'!$L$6:$L$1005)+COUNTA('Year 9'!$L$6:$L$1005)+COUNTA('Year 10'!$L$6:$L$1005)),"") -> 0.18333333 | D17: =IFERROR((COUNTIF('Year 1'!$M$6:$M$1005,"D")+COUNTIF('Year 1'!$M$6:$M$1005,"E")+COUNTIF('Year 2'!$M$6:$M$1005,"D")+COUNTIF('Year 2'!$M$6:$M$1005,"E")+COUNTIF('Year 3'!$M$6:$M$1005,"D")+COUNTIF('Year 3'!$M$6:$M$1005,"E")+COUNTIF('Year 4'!$M$6:$M$1005,"D")+COUNTIF('Year 4'!$M$6:$M$1005,"E")+COUNTIF('Year 5'!$M$6:$M$1005,"D")+COUNTIF('Year 5'!$M$6:$M$1005,"E")+COUNTIF('Year 6'!$M$6:$M$1005,"D")+COUNTIF('Year 6'!$M$6:$M$1005,"E")+COUNTIF('Year 7'!$M$6:$M$1005,"D")+COUNTIF('Year 7'!$M$6:$M$1005,"E")+COUNTIF('Year 8'!$M$6:$M$1005,"D")+COUNTIF('Year 8'!$M$6:$M$1005,"E")+COUNTIF('Year 9'!$M$6:$M$1005,"D")+COUNTIF('Year 9'!$M$6:$M$1005,"E")+COUNTIF('Year 10'!$M$6:$M$1005,"D")+COUNTIF('Year 10'!$M$6:$M$1005,"E"))/(COUNTA('Year 1'!$M$6:$M$1005)+COUNTA('Year 2'!$M$6:$M$1005)+COUNTA('Year 3'!$M$6:$M$1005)+COUNTA('Year 4'!$M$6:$M$1005)+COUNTA('Year 5'!$M$6:$M$1005)+COUNTA('Year 6'!$M$6:$M$1005)+COUNTA('Year 7'!$M$6:$M$1005)+COUNTA('Year 8'!$M$6:$M$1005)+COUNTA('Year 9'!$M$6:$M$1005)+COUNTA('Year 10'!$M$6:$M$1005)),"") -> 0.13559322 | E17: =IFERROR((COUNTIF('Year 1'!$P$6:$P$1005,"D")+COUNTIF('Year 1'!$P$6:$P$1005,"E")+COUNTIF('Year 2'!$P$6:$P$1005,"D")+COUNTIF('Year 2'!$P$6:$P$1005,"E")+COUNTIF('Year 3'!$P$6:$P$1005,"D")+COUNTIF('Year 3'!$P$6:$P$1005,"E")+COUNTIF('Year 4'!$P$6:$P$1005,"D")+COUNTIF('Year 4'!$P$6:$P$1005,"E")+COUNTIF('Year 5'!$P$6:$P$1005,"D")+COUNTIF('Year 5'!$P$6:$P$1005,"E")+COUNTIF('Year 6'!$P$6:$P$1005,"D")+COUNTIF('Year 6'!$P$6:$P$1005,"E")+COUNTIF('Year 7'!$P$6:$P$1005,"D")+COUNTIF('Year 7'!$P$6:$P$1005,"E")+COUNTIF('Year 8'!$P$6:$P$1005,"D")+COUNTIF('Year 8'!$P$6:$P$1005,"E")+COUNTIF('Year 9'!$P$6:$P$1005,"D")+COUNTIF('Year 9'!$P$6:$P$1005,"E")+COUNTIF('Year 10'!$P$6:$P$1005,"D")+COUNTIF('Year 10'!$P$6:$P$1005,"E"))/(COUNTA('Year 1'!$P$6:$P$1005)+COUNTA('Year 2'!$P$6:$P$1005)+COUNTA('Year 3'!$P$6:$P$1005)+COUNTA('Year 4'!$P$6:$P$1005)+COUNTA('Year 5'!$P$6:$P$1005)+COUNTA('Year 6'!$P$6:$P$1005)+COUNTA('Year 7'!$P$6:$P$1005)+COUNTA('Year 8'!$P$6:$P$1005)+COUNTA('Year 9'!$P$6:$P$1005)+COUNTA('Year 10'!$P$6:$P$1005)),"") -> 0.18333333 | F17: =IFERROR((COUNTIF('Year 1'!$S$6:$S$1005,"D")+COUNTIF('Year 1'!$S$6:$S$1005,"E")+COUNTIF('Year 2'!$S$6:$S$1005,"D")+COUNTIF('Year 2'!$S$6:$S$1005,"E")+COUNTIF('Year 3'!$S$6:$S$1005,"D")+COUNTIF('Year 3'!$S$6:$S$1005,"E")+COUNTIF('Year 4'!$S$6:$S$1005,"D")+COUNTIF('Year 4'!$S$6:$S$1005,"E")+COUNTIF('Year 5'!$S$6:$S$1005,"D")+COUNTIF('Year 5'!$S$6:$S$1005,"E")+COUNTIF('Year 6'!$S$6:$S$1005,"D")+COUNTIF('Year 6'!$S$6:$S$1005,"E")+COUNTIF('Year 7'!$S$6:$S$1005,"D")+COUNTIF('Year 7'!$S$6:$S$1005,"E")+COUNTIF('Year 8'!$S$6:$S$1005,"D")+COUNTIF('Year 8'!$S$6:$S$1005,"E")+COUNTIF('Year 9'!$S$6:$S$1005,"D")+COUNTIF('Year 9'!$S$6:$S$1005,"E")+COUNTIF('Year 10'!$S$6:$S$1005,"D")+COUNTIF('Year 10'!$S$6:$S$1005,"E"))/(COUNTA('Year 1'!$S$6:$S$1005)+COUNTA('Year 2'!$S$6:$S$1005)+COUNTA('Year 3'!$S$6:$S$1005)+COUNTA('Year 4'!$S$6:$S$1005)+COUNTA('Year 5'!$S$6:$S$1005)+COUNTA('Year 6'!$S$6:$S$1005)+COUNTA('Year 7'!$S$6:$S$1005)+COUNTA('Year 8'!$S$6:$S$1005)+COUNTA('Year 9'!$S$6:$S$1005)+COUNTA('Year 10'!$S$6:$S$1005)),"") -> 0.65 | G17: =IFERROR((COUNTIF('Year 1'!$U$6:$U$1005,"D")+COUNTIF('Year 1'!$U$6:$U$1005,"E")+COUNTIF('Year 2'!$U$6:$U$1005,"D")+COUNTIF('Year 2'!$U$6:$U$1005,"E")+COUNTIF('Year 3'!$U$6:$U$1005,"D")+COUNTIF('Year 3'!$U$6:$U$1005,"E")+COUNTIF('Year 4'!$U$6:$U$1005,"D")+COUNTIF('Year 4'!$U$6:$U$1005,"E")+COUNTIF('Year 5'!$U$6:$U$1005,"D")+COUNTIF('Year 5'!$U$6:$U$1005,"E")+COUNTIF('Year 6'!$U$6:$U$1005,"D")+COUNTIF('Year 6'!$U$6:$U$1005,"E")+COUNTIF('Year 7'!$U$6:$U$1005,"D")+COUNTIF('Year 7'!$U$6:$U$1005,"E")+COUNTIF('Year 8'!$U$6:$U$1005,"D")+COUNTIF('Year 8'!$U$6:$U$1005,"E")+COUNTIF('Year 9'!$U$6:$U$1005,"D")+COUNTIF('Year 9'!$U$6:$U$1005,"E")+COUNTIF('Year 10'!$U$6:$U$1005,"D")+COUNTIF('Year 10'!$U$6:$U$1005,"E"))/(COUNTA('Year 1'!$U$6:$U$1005)+COUNTA('Year 2'!$U$6:$U$1005)+COUNTA('Year 3'!$U$6:$U$1005)+COUNTA('Year 4'!$U$6:$U$1005)+COUNTA('Year 5'!$U$6:$U$1005)+COUNTA('Year 6'!$U$6:$U$1005)+COUNTA('Year 7'!$U$6:$U$1005)+COUNTA('Year 8'!$U$6:$U$1005)+COUNTA('Year 9'!$U$6:$U$1005)+COUNTA('Year 10'!$U$6:$U$1005)),"") -> 0.13333333 | H17: =IFERROR((COUNTIF('Year 1'!$V$6:$V$1005,"D")+COUNTIF('Year 1'!$V$6:$V$1005,"E")+COUNTIF('Year 2'!$V$6:$V$1005,"D")+COUNTIF('Year 2'!$V$6:$V$1005,"E")+COUNTIF('Year 3'!$V$6:$V$1005,"D")+COUNTIF('Year 3'!$V$6:$V$1005,"E")+COUNTIF('Year 4'!$V$6:$V$1005,"D")+COUNTIF('Year 4'!$V$6:$V$1005,"E")+COUNTIF('Year 5'!$V$6:$V$1005,"D")+COUNTIF('Year 5'!$V$6:$V$1005,"E")+COUNTIF('Year 6'!$V$6:$V$1005,"D")+COUNTIF('Year 6'!$V$6:$V$1005,"E")+COUNTIF('Year 7'!$V$6:$V$1005,"D")+COUNTIF('Year 7'!$V$6:$V$1005,"E")+COUNTIF('Year 8'!$V$6:$V$1005,"D")+COUNTIF('Year 8'!$V$6:$V$1005,"E")+COUNTIF('Year 9'!$V$6:$V$1005,"D")+COUNTIF('Year 9'!$V$6:$V$1005,"E")+COUNTIF('Year 10'!$V$6:$V$1005,"D")+COUNTIF('Year 10'!$V$6:$V$1005,"E"))/(COUNTA('Year 1'!$V$6:$V$1005)+COUNTA('Year 2'!$V$6:$V$1005)+COUNTA('Year 3'!$V$6:$V$1005)+COUNTA('Year 4'!$V$6:$V$1005)+COUNTA('Year 5'!$V$6:$V$1005)+COUNTA('Year 6'!$V$6:$V$1005)+COUNTA('Year 7'!$V$6:$V$1005)+COUNTA('Year 8'!$V$6:$V$1005)+COUNTA('Year 9'!$V$6:$V$1005)+COUNTA('Year 10'!$V$6:$V$1005)),"") -> 0.11666667
B19: Share of candidates banded A or B, by skill (the students who will need most English support)
B20: Year group | C20: Listening | D20: Speaking | E20: Reading | F20: Reading aloud (indicative) | G20: Writing | H20: Overall English
B21: Year 1 | C21: =IFERROR((COUNTIF('Year 1'!$L$6:$L$1005,"A")+COUNTIF('Year 1'!$L$6:$L$1005,"B"))/COUNTA('Year 1'!$L$6:$L$1005),"") -> 0.6 | D21: =IFERROR((COUNTIF('Year 1'!$M$6:$M$1005,"A")+COUNTIF('Year 1'!$M$6:$M$1005,"B"))/COUNTA('Year 1'!$M$6:$M$1005),"") -> 0.4 | E21: =IFERROR((COUNTIF('Year 1'!$P$6:$P$1005,"A")+COUNTIF('Year 1'!$P$6:$P$1005,"B"))/COUNTA('Year 1'!$P$6:$P$1005),"") -> 0.4 | F21: =IFERROR((COUNTIF('Year 1'!$S$6:$S$1005,"A")+COUNTIF('Year 1'!$S$6:$S$1005,"B"))/COUNTA('Year 1'!$S$6:$S$1005),"") -> 0 | G21: =IFERROR((COUNTIF('Year 1'!$U$6:$U$1005,"A")+COUNTIF('Year 1'!$U$6:$U$1005,"B"))/COUNTA('Year 1'!$U$6:$U$1005),"") -> 0.4 | H21: =IFERROR((COUNTIF('Year 1'!$V$6:$V$1005,"A")+COUNTIF('Year 1'!$V$6:$V$1005,"B"))/COUNTA('Year 1'!$V$6:$V$1005),"") -> 0.4
B22: Year 2 | C22: =IFERROR((COUNTIF('Year 2'!$L$6:$L$1005,"A")+COUNTIF('Year 2'!$L$6:$L$1005,"B"))/COUNTA('Year 2'!$L$6:$L$1005),"") -> 0.2 | D22: =IFERROR((COUNTIF('Year 2'!$M$6:$M$1005,"A")+COUNTIF('Year 2'!$M$6:$M$1005,"B"))/COUNTA('Year 2'!$M$6:$M$1005),"") -> 0.2 | E22: =IFERROR((COUNTIF('Year 2'!$P$6:$P$1005,"A")+COUNTIF('Year 2'!$P$6:$P$1005,"B"))/COUNTA('Year 2'!$P$6:$P$1005),"") -> 0.4 | F22: =IFERROR((COUNTIF('Year 2'!$S$6:$S$1005,"A")+COUNTIF('Year 2'!$S$6:$S$1005,"B"))/COUNTA('Year 2'!$S$6:$S$1005),"") -> 0 | G22: =IFERROR((COUNTIF('Year 2'!$U$6:$U$1005,"A")+COUNTIF('Year 2'!$U$6:$U$1005,"B"))/COUNTA('Year 2'!$U$6:$U$1005),"") -> 0.2 | H22: =IFERROR((COUNTIF('Year 2'!$V$6:$V$1005,"A")+COUNTIF('Year 2'!$V$6:$V$1005,"B"))/COUNTA('Year 2'!$V$6:$V$1005),"") -> 0.2
B23: Year 3 | C23: =IFERROR((COUNTIF('Year 3'!$L$6:$L$1005,"A")+COUNTIF('Year 3'!$L$6:$L$1005,"B"))/COUNTA('Year 3'!$L$6:$L$1005),"") -> 0.71428571 | D23: =IFERROR((COUNTIF('Year 3'!$M$6:$M$1005,"A")+COUNTIF('Year 3'!$M$6:$M$1005,"B"))/COUNTA('Year 3'!$M$6:$M$1005),"") -> 0.42857143 | E23: =IFERROR((COUNTIF('Year 3'!$P$6:$P$1005,"A")+COUNTIF('Year 3'!$P$6:$P$1005,"B"))/COUNTA('Year 3'!$P$6:$P$1005),"") -> 0.57142857 | F23: =IFERROR((COUNTIF('Year 3'!$S$6:$S$1005,"A")+COUNTIF('Year 3'!$S$6:$S$1005,"B"))/COUNTA('Year 3'!$S$6:$S$1005),"") -> 0.57142857 | G23: =IFERROR((COUNTIF('Year 3'!$U$6:$U$1005,"A")+COUNTIF('Year 3'!$U$6:$U$1005,"B"))/COUNTA('Year 3'!$U$6:$U$1005),"") -> 0.42857143 | H23: =IFERROR((COUNTIF('Year 3'!$V$6:$V$1005,"A")+COUNTIF('Year 3'!$V$6:$V$1005,"B"))/COUNTA('Year 3'!$V$6:$V$1005),"") -> 0.57142857
B24: Year 4 | C24: =IFERROR((COUNTIF('Year 4'!$L$6:$L$1005,"A")+COUNTIF('Year 4'!$L$6:$L$1005,"B"))/COUNTA('Year 4'!$L$6:$L$1005),"") -> 0.5 | D24: =IFERROR((COUNTIF('Year 4'!$M$6:$M$1005,"A")+COUNTIF('Year 4'!$M$6:$M$1005,"B"))/COUNTA('Year 4'!$M$6:$M$1005),"") -> 0.83333333 | E24: =IFERROR((COUNTIF('Year 4'!$P$6:$P$1005,"A")+COUNTIF('Year 4'!$P$6:$P$1005,"B"))/COUNTA('Year 4'!$P$6:$P$1005),"") -> 0.66666667 | F24: =IFERROR((COUNTIF('Year 4'!$S$6:$S$1005,"A")+COUNTIF('Year 4'!$S$6:$S$1005,"B"))/COUNTA('Year 4'!$S$6:$S$1005),"") -> 0.16666667 | G24: =IFERROR((COUNTIF('Year 4'!$U$6:$U$1005,"A")+COUNTIF('Year 4'!$U$6:$U$1005,"B"))/COUNTA('Year 4'!$U$6:$U$1005),"") -> 0.5 | H24: =IFERROR((COUNTIF('Year 4'!$V$6:$V$1005,"A")+COUNTIF('Year 4'!$V$6:$V$1005,"B"))/COUNTA('Year 4'!$V$6:$V$1005),"") -> 0.66666667
B25: Year 5 | C25: =IFERROR((COUNTIF('Year 5'!$L$6:$L$1005,"A")+COUNTIF('Year 5'!$L$6:$L$1005,"B"))/COUNTA('Year 5'!$L$6:$L$1005),"") -> 0.85714286 | D25: =IFERROR((COUNTIF('Year 5'!$M$6:$M$1005,"A")+COUNTIF('Year 5'!$M$6:$M$1005,"B"))/COUNTA('Year 5'!$M$6:$M$1005),"") -> 0.66666667 | E25: =IFERROR((COUNTIF('Year 5'!$P$6:$P$1005,"A")+COUNTIF('Year 5'!$P$6:$P$1005,"B"))/COUNTA('Year 5'!$P$6:$P$1005),"") -> 0.57142857 | F25: =IFERROR((COUNTIF('Year 5'!$S$6:$S$1005,"A")+COUNTIF('Year 5'!$S$6:$S$1005,"B"))/COUNTA('Year 5'!$S$6:$S$1005),"") -> 0.57142857 | G25: =IFERROR((COUNTIF('Year 5'!$U$6:$U$1005,"A")+COUNTIF('Year 5'!$U$6:$U$1005,"B"))/COUNTA('Year 5'!$U$6:$U$1005),"") -> 0.42857143 | H25: =IFERROR((COUNTIF('Year 5'!$V$6:$V$1005,"A")+COUNTIF('Year 5'!$V$6:$V$1005,"B"))/COUNTA('Year 5'!$V$6:$V$1005),"") -> 0.57142857
B26: Year 6 | C26: =IFERROR((COUNTIF('Year 6'!$L$6:$L$1005,"A")+COUNTIF('Year 6'!$L$6:$L$1005,"B"))/COUNTA('Year 6'!$L$6:$L$1005),"") -> 0.57142857 | D26: =IFERROR((COUNTIF('Year 6'!$M$6:$M$1005,"A")+COUNTIF('Year 6'!$M$6:$M$1005,"B"))/COUNTA('Year 6'!$M$6:$M$1005),"") -> 0.42857143 | E26: =IFERROR((COUNTIF('Year 6'!$P$6:$P$1005,"A")+COUNTIF('Year 6'!$P$6:$P$1005,"B"))/COUNTA('Year 6'!$P$6:$P$1005),"") -> 0.42857143 | F26: =IFERROR((COUNTIF('Year 6'!$S$6:$S$1005,"A")+COUNTIF('Year 6'!$S$6:$S$1005,"B"))/COUNTA('Year 6'!$S$6:$S$1005),"") -> 0 | G26: =IFERROR((COUNTIF('Year 6'!$U$6:$U$1005,"A")+COUNTIF('Year 6'!$U$6:$U$1005,"B"))/COUNTA('Year 6'!$U$6:$U$1005),"") -> 0.57142857 | H26: =IFERROR((COUNTIF('Year 6'!$V$6:$V$1005,"A")+COUNTIF('Year 6'!$V$6:$V$1005,"B"))/COUNTA('Year 6'!$V$6:$V$1005),"") -> 0.57142857
B27: Year 7 | C27: =IFERROR((COUNTIF('Year 7'!$L$6:$L$1005,"A")+COUNTIF('Year 7'!$L$6:$L$1005,"B"))/COUNTA('Year 7'!$L$6:$L$1005),"") -> 0.33333333 | D27: =IFERROR((COUNTIF('Year 7'!$M$6:$M$1005,"A")+COUNTIF('Year 7'!$M$6:$M$1005,"B"))/COUNTA('Year 7'!$M$6:$M$1005),"") -> 0.5 | E27: =IFERROR((COUNTIF('Year 7'!$P$6:$P$1005,"A")+COUNTIF('Year 7'!$P$6:$P$1005,"B"))/COUNTA('Year 7'!$P$6:$P$1005),"") -> 0.66666667 | F27: =IFERROR((COUNTIF('Year 7'!$S$6:$S$1005,"A")+COUNTIF('Year 7'!$S$6:$S$1005,"B"))/COUNTA('Year 7'!$S$6:$S$1005),"") -> 0.16666667 | G27: =IFERROR((COUNTIF('Year 7'!$U$6:$U$1005,"A")+COUNTIF('Year 7'!$U$6:$U$1005,"B"))/COUNTA('Year 7'!$U$6:$U$1005),"") -> 0.5 | H27: =IFERROR((COUNTIF('Year 7'!$V$6:$V$1005,"A")+COUNTIF('Year 7'!$V$6:$V$1005,"B"))/COUNTA('Year 7'!$V$6:$V$1005),"") -> 0.5
B28: Year 8 | C28: =IFERROR((COUNTIF('Year 8'!$L$6:$L$1005,"A")+COUNTIF('Year 8'!$L$6:$L$1005,"B"))/COUNTA('Year 8'!$L$6:$L$1005),"") -> 0.5 | D28: =IFERROR((COUNTIF('Year 8'!$M$6:$M$1005,"A")+COUNTIF('Year 8'!$M$6:$M$1005,"B"))/COUNTA('Year 8'!$M$6:$M$1005),"") -> 0.5 | E28: =IFERROR((COUNTIF('Year 8'!$P$6:$P$1005,"A")+COUNTIF('Year 8'!$P$6:$P$1005,"B"))/COUNTA('Year 8'!$P$6:$P$1005),"") -> 0.5 | F28: =IFERROR((COUNTIF('Year 8'!$S$6:$S$1005,"A")+COUNTIF('Year 8'!$S$6:$S$1005,"B"))/COUNTA('Year 8'!$S$6:$S$1005),"") -> 0.16666667 | G28: =IFERROR((COUNTIF('Year 8'!$U$6:$U$1005,"A")+COUNTIF('Year 8'!$U$6:$U$1005,"B"))/COUNTA('Year 8'!$U$6:$U$1005),"") -> 0.33333333 | H28: =IFERROR((COUNTIF('Year 8'!$V$6:$V$1005,"A")+COUNTIF('Year 8'!$V$6:$V$1005,"B"))/COUNTA('Year 8'!$V$6:$V$1005),"") -> 0.5
B29: Year 9 | C29: =IFERROR((COUNTIF('Year 9'!$L$6:$L$1005,"A")+COUNTIF('Year 9'!$L$6:$L$1005,"B"))/COUNTA('Year 9'!$L$6:$L$1005),"") -> 0.33333333 | D29: =IFERROR((COUNTIF('Year 9'!$M$6:$M$1005,"A")+COUNTIF('Year 9'!$M$6:$M$1005,"B"))/COUNTA('Year 9'!$M$6:$M$1005),"") -> 0.16666667 | E29: =IFERROR((COUNTIF('Year 9'!$P$6:$P$1005,"A")+COUNTIF('Year 9'!$P$6:$P$1005,"B"))/COUNTA('Year 9'!$P$6:$P$1005),"") -> 0.5 | F29: =IFERROR((COUNTIF('Year 9'!$S$6:$S$1005,"A")+COUNTIF('Year 9'!$S$6:$S$1005,"B"))/COUNTA('Year 9'!$S$6:$S$1005),"") -> 0 | G29: =IFERROR((COUNTIF('Year 9'!$U$6:$U$1005,"A")+COUNTIF('Year 9'!$U$6:$U$1005,"B"))/COUNTA('Year 9'!$U$6:$U$1005),"") -> 0.33333333 | H29: =IFERROR((COUNTIF('Year 9'!$V$6:$V$1005,"A")+COUNTIF('Year 9'!$V$6:$V$1005,"B"))/COUNTA('Year 9'!$V$6:$V$1005),"") -> 0.33333333
B30: Year 10 | C30: =IFERROR((COUNTIF('Year 10'!$L$6:$L$1005,"A")+COUNTIF('Year 10'!$L$6:$L$1005,"B"))/COUNTA('Year 10'!$L$6:$L$1005),"") -> 0.4 | D30: =IFERROR((COUNTIF('Year 10'!$M$6:$M$1005,"A")+COUNTIF('Year 10'!$M$6:$M$1005,"B"))/COUNTA('Year 10'!$M$6:$M$1005),"") -> 0.4 | E30: =IFERROR((COUNTIF('Year 10'!$P$6:$P$1005,"A")+COUNTIF('Year 10'!$P$6:$P$1005,"B"))/COUNTA('Year 10'!$P$6:$P$1005),"") -> 0.2 | F30: =IFERROR((COUNTIF('Year 10'!$S$6:$S$1005,"A")+COUNTIF('Year 10'!$S$6:$S$1005,"B"))/COUNTA('Year 10'!$S$6:$S$1005),"") -> 0.2 | G30: =IFERROR((COUNTIF('Year 10'!$U$6:$U$1005,"A")+COUNTIF('Year 10'!$U$6:$U$1005,"B"))/COUNTA('Year 10'!$U$6:$U$1005),"") -> 0.4 | H30: =IFERROR((COUNTIF('Year 10'!$V$6:$V$1005,"A")+COUNTIF('Year 10'!$V$6:$V$1005,"B"))/COUNTA('Year 10'!$V$6:$V$1005),"") -> 0.4
B31: All years | C31: =IFERROR((COUNTIF('Year 1'!$L$6:$L$1005,"A")+COUNTIF('Year 1'!$L$6:$L$1005,"B")+COUNTIF('Year 2'!$L$6:$L$1005,"A")+COUNTIF('Year 2'!$L$6:$L$1005,"B")+COUNTIF('Year 3'!$L$6:$L$1005,"A")+COUNTIF('Year 3'!$L$6:$L$1005,"B")+COUNTIF('Year 4'!$L$6:$L$1005,"A")+COUNTIF('Year 4'!$L$6:$L$1005,"B")+COUNTIF('Year 5'!$L$6:$L$1005,"A")+COUNTIF('Year 5'!$L$6:$L$1005,"B")+COUNTIF('Year 6'!$L$6:$L$1005,"A")+COUNTIF('Year 6'!$L$6:$L$1005,"B")+COUNTIF('Year 7'!$L$6:$L$1005,"A")+COUNTIF('Year 7'!$L$6:$L$1005,"B")+COUNTIF('Year 8'!$L$6:$L$1005,"A")+COUNTIF('Year 8'!$L$6:$L$1005,"B")+COUNTIF('Year 9'!$L$6:$L$1005,"A")+COUNTIF('Year 9'!$L$6:$L$1005,"B")+COUNTIF('Year 10'!$L$6:$L$1005,"A")+COUNTIF('Year 10'!$L$6:$L$1005,"B"))/(COUNTA('Year 1'!$L$6:$L$1005)+COUNTA('Year 2'!$L$6:$L$1005)+COUNTA('Year 3'!$L$6:$L$1005)+COUNTA('Year 4'!$L$6:$L$1005)+COUNTA('Year 5'!$L$6:$L$1005)+COUNTA('Year 6'!$L$6:$L$1005)+COUNTA('Year 7'!$L$6:$L$1005)+COUNTA('Year 8'!$L$6:$L$1005)+COUNTA('Year 9'!$L$6:$L$1005)+COUNTA('Year 10'!$L$6:$L$1005)),"") -> 0.51666667 | D31: =IFERROR((COUNTIF('Year 1'!$M$6:$M$1005,"A")+COUNTIF('Year 1'!$M$6:$M$1005,"B")+COUNTIF('Year 2'!$M$6:$M$1005,"A")+COUNTIF('Year 2'!$M$6:$M$1005,"B")+COUNTIF('Year 3'!$M$6:$M$1005,"A")+COUNTIF('Year 3'!$M$6:$M$1005,"B")+COUNTIF('Year 4'!$M$6:$M$1005,"A")+COUNTIF('Year 4'!$M$6:$M$1005,"B")+COUNTIF('Year 5'!$M$6:$M$1005,"A")+COUNTIF('Year 5'!$M$6:$M$1005,"B")+COUNTIF('Year 6'!$M$6:$M$1005,"A")+COUNTIF('Year 6'!$M$6:$M$1005,"B")+COUNTIF('Year 7'!$M$6:$M$1005,"A")+COUNTIF('Year 7'!$M$6:$M$1005,"B")+COUNTIF('Year 8'!$M$6:$M$1005,"A")+COUNTIF('Year 8'!$M$6:$M$1005,"B")+COUNTIF('Year 9'!$M$6:$M$1005,"A")+COUNTIF('Year 9'!$M$6:$M$1005,"B")+COUNTIF('Year 10'!$M$6:$M$1005,"A")+COUNTIF('Year 10'!$M$6:$M$1005,"B"))/(COUNTA('Year 1'!$M$6:$M$1005)+COUNTA('Year 2'!$M$6:$M$1005)+COUNTA('Year 3'!$M$6:$M$1005)+COUNTA('Year 4'!$M$6:$M$1005)+COUNTA('Year 5'!$M$6:$M$1005)+COUNTA('Year 6'!$M$6:$M$1005)+COUNTA('Year 7'!$M$6:$M$1005)+COUNTA('Year 8'!$M$6:$M$1005)+COUNTA('Year 9'!$M$6:$M$1005)+COUNTA('Year 10'!$M$6:$M$1005)),"") -> 0.45762712 | E31: =IFERROR((COUNTIF('Year 1'!$P$6:$P$1005,"A")+COUNTIF('Year 1'!$P$6:$P$1005,"B")+COUNTIF('Year 2'!$P$6:$P$1005,"A")+COUNTIF('Year 2'!$P$6:$P$1005,"B")+COUNTIF('Year 3'!$P$6:$P$1005,"A")+COUNTIF('Year 3'!$P$6:$P$1005,"B")+COUNTIF('Year 4'!$P$6:$P$1005,"A")+COUNTIF('Year 4'!$P$6:$P$1005,"B")+COUNTIF('Year 5'!$P$6:$P$1005,"A")+COUNTIF('Year 5'!$P$6:$P$1005,"B")+COUNTIF('Year 6'!$P$6:$P$1005,"A")+COUNTIF('Year 6'!$P$6:$P$1005,"B")+COUNTIF('Year 7'!$P$6:$P$1005,"A")+COUNTIF('Year 7'!$P$6:$P$1005,"B")+COUNTIF('Year 8'!$P$6:$P$1005,"A")+COUNTIF('Year 8'!$P$6:$P$1005,"B")+COUNTIF('Year 9'!$P$6:$P$1005,"A")+COUNTIF('Year 9'!$P$6:$P$1005,"B")+COUNTIF('Year 10'!$P$6:$P$1005,"A")+COUNTIF('Year 10'!$P$6:$P$1005,"B"))/(COUNTA('Year 1'!$P$6:$P$1005)+COUNTA('Year 2'!$P$6:$P$1005)+COUNTA('Year 3'!$P$6:$P$1005)+COUNTA('Year 4'!$P$6:$P$1005)+COUNTA('Year 5'!$P$6:$P$1005)+COUNTA('Year 6'!$P$6:$P$1005)+COUNTA('Year 7'!$P$6:$P$1005)+COUNTA('Year 8'!$P$6:$P$1005)+COUNTA('Year 9'!$P$6:$P$1005)+COUNTA('Year 10'!$P$6:$P$1005)),"") -> 0.5 | F31: =IFERROR((COUNTIF('Year 1'!$S$6:$S$1005,"A")+COUNTIF('Year 1'!$S$6:$S$1005,"B")+COUNTIF('Year 2'!$S$6:$S$1005,"A")+COUNTIF('Year 2'!$S$6:$S$1005,"B")+COUNTIF('Year 3'!$S$6:$S$1005,"A")+COUNTIF('Year 3'!$S$6:$S$1005,"B")+COUNTIF('Year 4'!$S$6:$S$1005,"A")+COUNTIF('Year 4'!$S$6:$S$1005,"B")+COUNTIF('Year 5'!$S$6:$S$1005,"A")+COUNTIF('Year 5'!$S$6:$S$1005,"B")+COUNTIF('Year 6'!$S$6:$S$1005,"A")+COUNTIF('Year 6'!$S$6:$S$1005,"B")+COUNTIF('Year 7'!$S$6:$S$1005,"A")+COUNTIF('Year 7'!$S$6:$S$1005,"B")+COUNTIF('Year 8'!$S$6:$S$1005,"A")+COUNTIF('Year 8'!$S$6:$S$1005,"B")+COUNTIF('Year 9'!$S$6:$S$1005,"A")+COUNTIF('Year 9'!$S$6:$S$1005,"B")+COUNTIF('Year 10'!$S$6:$S$1005,"A")+COUNTIF('Year 10'!$S$6:$S$1005,"B"))/(COUNTA('Year 1'!$S$6:$S$1005)+COUNTA('Year 2'!$S$6:$S$1005)+COUNTA('Year 3'!$S$6:$S$1005)+COUNTA('Year 4'!$S$6:$S$1005)+COUNTA('Year 5'!$S$6:$S$1005)+COUNTA('Year 6'!$S$6:$S$1005)+COUNTA('Year 7'!$S$6:$S$1005)+COUNTA('Year 8'!$S$6:$S$1005)+COUNTA('Year 9'!$S$6:$S$1005)+COUNTA('Year 10'!$S$6:$S$1005)),"") -> 0.2 | G31: =IFERROR((COUNTIF('Year 1'!$U$6:$U$1005,"A")+COUNTIF('Year 1'!$U$6:$U$1005,"B")+COUNTIF('Year 2'!$U$6:$U$1005,"A")+COUNTIF('Year 2'!$U$6:$U$1005,"B")+COUNTIF('Year 3'!$U$6:$U$1005,"A")+COUNTIF('Year 3'!$U$6:$U$1005,"B")+COUNTIF('Year 4'!$U$6:$U$1005,"A")+COUNTIF('Year 4'!$U$6:$U$1005,"B")+COUNTIF('Year 5'!$U$6:$U$1005,"A")+COUNTIF('Year 5'!$U$6:$U$1005,"B")+COUNTIF('Year 6'!$U$6:$U$1005,"A")+COUNTIF('Year 6'!$U$6:$U$1005,"B")+COUNTIF('Year 7'!$U$6:$U$1005,"A")+COUNTIF('Year 7'!$U$6:$U$1005,"B")+COUNTIF('Year 8'!$U$6:$U$1005,"A")+COUNTIF('Year 8'!$U$6:$U$1005,"B")+COUNTIF('Year 9'!$U$6:$U$1005,"A")+COUNTIF('Year 9'!$U$6:$U$1005,"B")+COUNTIF('Year 10'!$U$6:$U$1005,"A")+COUNTIF('Year 10'!$U$6:$U$1005,"B"))/(COUNTA('Year 1'!$U$6:$U$1005)+COUNTA('Year 2'!$U$6:$U$1005)+COUNTA('Year 3'!$U$6:$U$1005)+COUNTA('Year 4'!$U$6:$U$1005)+COUNTA('Year 5'!$U$6:$U$1005)+COUNTA('Year 6'!$U$6:$U$1005)+COUNTA('Year 7'!$U$6:$U$1005)+COUNTA('Year 8'!$U$6:$U$1005)+COUNTA('Year 9'!$U$6:$U$1005)+COUNTA('Year 10'!$U$6:$U$1005)),"") -> 0.41666667 | H31: =IFERROR((COUNTIF('Year 1'!$V$6:$V$1005,"A")+COUNTIF('Year 1'!$V$6:$V$1005,"B")+COUNTIF('Year 2'!$V$6:$V$1005,"A")+COUNTIF('Year 2'!$V$6:$V$1005,"B")+COUNTIF('Year 3'!$V$6:$V$1005,"A")+COUNTIF('Year 3'!$V$6:$V$1005,"B")+COUNTIF('Year 4'!$V$6:$V$1005,"A")+COUNTIF('Year 4'!$V$6:$V$1005,"B")+COUNTIF('Year 5'!$V$6:$V$1005,"A")+COUNTIF('Year 5'!$V$6:$V$1005,"B")+COUNTIF('Year 6'!$V$6:$V$1005,"A")+COUNTIF('Year 6'!$V$6:$V$1005,"B")+COUNTIF('Year 7'!$V$6:$V$1005,"A")+COUNTIF('Year 7'!$V$6:$V$1005,"B")+COUNTIF('Year 8'!$V$6:$V$1005,"A")+COUNTIF('Year 8'!$V$6:$V$1005,"B")+COUNTIF('Year 9'!$V$6:$V$1005,"A")+COUNTIF('Year 9'!$V$6:$V$1005,"B")+COUNTIF('Year 10'!$V$6:$V$1005,"A")+COUNTIF('Year 10'!$V$6:$V$1005,"B"))/(COUNTA('Year 1'!$V$6:$V$1005)+COUNTA('Year 2'!$V$6:$V$1005)+COUNTA('Year 3'!$V$6:$V$1005)+COUNTA('Year 4'!$V$6:$V$1005)+COUNTA('Year 5'!$V$6:$V$1005)+COUNTA('Year 6'!$V$6:$V$1005)+COUNTA('Year 7'!$V$6:$V$1005)+COUNTA('Year 8'!$V$6:$V$1005)+COUNTA('Year 9'!$V$6:$V$1005)+COUNTA('Year 10'!$V$6:$V$1005)),"") -> 0.48333333
B33: Average score as a percentage of the maximum
B34: Year group | C34: Listening | D34: Reading paper | E34: Writing | F34: Maths | G34: Science
B35: Year 1 | C35: =IFERROR(AVERAGE('Year 1'!$K$6:$K$1005)/'Year 1'!$K$3,"") -> 0.38 | D35: n/a | E35: =IFERROR(AVERAGE('Year 1'!$T$6:$T$1005)/'Year 1'!$T$3,"") -> 0.4 | F35: =IFERROR(AVERAGE('Year 1'!$W$6:$W$1005)/'Year 1'!$W$3,"") -> 0.50666667 | G35: n/a
B36: Year 2 | C36: =IFERROR(AVERAGE('Year 2'!$K$6:$K$1005)/'Year 2'!$K$3,"") -> 0.58 | D36: n/a | E36: =IFERROR(AVERAGE('Year 2'!$T$6:$T$1005)/'Year 2'!$T$3,"") -> 0.5125 | F36: =IFERROR(AVERAGE('Year 2'!$W$6:$W$1005)/'Year 2'!$W$3,"") -> 0.57 | G36: n/a
B37: Year 3 | C37: =IFERROR(AVERAGE('Year 3'!$K$6:$K$1005)/'Year 3'!$K$3,"") -> 0.42857143 | D37: n/a | E37: =IFERROR(AVERAGE('Year 3'!$T$6:$T$1005)/'Year 3'!$T$3,"") -> 0.51785714 | F37: =IFERROR(AVERAGE('Year 3'!$W$6:$W$1005)/'Year 3'!$W$3,"") -> 0.57142857 | G37: n/a
B38: Year 4 | C38: =IFERROR(AVERAGE('Year 4'!$K$6:$K$1005)/'Year 4'!$K$3,"") -> 0.4375 | D38: =IFERROR(AVERAGE('Year 4'!$O$6:$O$1005)/'Year 4'!$O$3,"") -> 0.38194444 | E38: =IFERROR(AVERAGE('Year 4'!$T$6:$T$1005)/'Year 4'!$T$3,"") -> 0.41666667 | F38: =IFERROR(AVERAGE('Year 4'!$W$6:$W$1005)/'Year 4'!$W$3,"") -> 0.49333333 | G38: n/a
B39: Year 5 | C39: =IFERROR(AVERAGE('Year 5'!$K$6:$K$1005)/'Year 5'!$K$3,"") -> 0.33928571 | D39: =IFERROR(AVERAGE('Year 5'!$O$6:$O$1005)/'Year 5'!$O$3,"") -> 0.4047619 | E39: =IFERROR(AVERAGE('Year 5'!$T$6:$T$1005)/'Year 5'!$T$3,"") -> 0.42857143 | F39: =IFERROR(AVERAGE('Year 5'!$W$6:$W$1005)/'Year 5'!$W$3,"") -> 0.54857143 | G39: =IFERROR(AVERAGE('Year 5'!$AA$6:$AA$1005)/'Year 5'!$AA$3,"") -> 0.47142857
B40: Year 6 | C40: =IFERROR(AVERAGE('Year 6'!$K$6:$K$1005)/'Year 6'!$K$3,"") -> 0.44642857 | D40: =IFERROR(AVERAGE('Year 6'!$O$6:$O$1005)/'Year 6'!$O$3,"") -> 0.45238095 | E40: =IFERROR(AVERAGE('Year 6'!$T$6:$T$1005)/'Year 6'!$T$3,"") -> 0.48214286 | F40: =IFERROR(AVERAGE('Year 6'!$W$6:$W$1005)/'Year 6'!$W$3,"") -> 0.46857143 | G40: =IFERROR(AVERAGE('Year 6'!$AA$6:$AA$1005)/'Year 6'!$AA$3,"") -> 0.51428571
B41: Year 7 | C41: =IFERROR(AVERAGE('Year 7'!$K$6:$K$1005)/'Year 7'!$K$3,"") -> 0.42708333 | D41: =IFERROR(AVERAGE('Year 7'!$O$6:$O$1005)/'Year 7'!$O$3,"") -> 0.42708333 | E41: =IFERROR(AVERAGE('Year 7'!$T$6:$T$1005)/'Year 7'!$T$3,"") -> 0.46875 | F41: =IFERROR(AVERAGE('Year 7'!$W$6:$W$1005)/'Year 7'!$W$3,"") -> 0.52222222 | G41: =IFERROR(AVERAGE('Year 7'!$AA$6:$AA$1005)/'Year 7'!$AA$3,"") -> 0.48333333
B42: Year 8 | C42: =IFERROR(AVERAGE('Year 8'!$K$6:$K$1005)/'Year 8'!$K$3,"") -> 0.42708333 | D42: =IFERROR(AVERAGE('Year 8'!$O$6:$O$1005)/'Year 8'!$O$3,"") -> 0.40625 | E42: =IFERROR(AVERAGE('Year 8'!$T$6:$T$1005)/'Year 8'!$T$3,"") -> 0.48958333 | F42: =IFERROR(AVERAGE('Year 8'!$W$6:$W$1005)/'Year 8'!$W$3,"") -> 0.51666667 | G42: =IFERROR(AVERAGE('Year 8'!$AA$6:$AA$1005)/'Year 8'!$AA$3,"") -> 0.46666667
B43: Year 9 | C43: =IFERROR(AVERAGE('Year 9'!$K$6:$K$1005)/'Year 9'!$K$3,"") -> 0.60416667 | D43: =IFERROR(AVERAGE('Year 9'!$O$6:$O$1005)/'Year 9'!$O$3,"") -> 0.55208333 | E43: =IFERROR(AVERAGE('Year 9'!$T$6:$T$1005)/'Year 9'!$T$3,"") -> 0.55208333 | F43: =IFERROR(AVERAGE('Year 9'!$W$6:$W$1005)/'Year 9'!$W$3,"") -> 0.62777778 | G43: =IFERROR(AVERAGE('Year 9'!$AA$6:$AA$1005)/'Year 9'!$AA$3,"") -> 0.58333333
...

Sheet Year 1
A1: Year 1 admissions tracker
A2: One row per candidate. Type in the white cells (blue text). Grey columns are not used in this year group. Blue-grey columns are calculated: do not type in them. Instructions: sheet How_To_Use.
B3: Maximum mark (Year 1 grading sheet) | K3: 10 | O3: not used | Q3: 72 | T3: 16 | W3: 15 | Y3: 3 | AA3: not used | AB3: not used
A4: Candidate | F4: Visit and status | K4: English | W4: Maths and science | AC4: Interview and follow-up | AG4: Decision and family | AM4: Calculated: do not type
A5: Candidate number | B5: Name (or initials) | C5: Date of birth | D5: Current school | E5: Boarding (Y/N) | F5: Date applied | G5: Date assessed | H5: Assessor (initials) | I5: Paper version sat | J5: Status | K5: Listening score | L5: Listening band | M5: Speaking band | N5: Early Reading Screen book band (Years 1 to 3) | O5: Reading paper score (Years 4 to 10) | P5: Reading band | Q5: Sentence reading points (of 72) | R5: Reading age (calculated) | S5: Reading aloud band (indicative) | T5: Writing score | U5: Writing band | V5: Overall English band | W5: Maths score | X5: Maths band (1 to 4) | Y5: Maths word problems score | Z5: English barrier in maths? | AA5: Science score | AB5: Science band (1 to 4) | AC5: Lowest suitability rating (1 to 4) | AD5: Learning needs follow-up (Y) | AE5: Wellbeing follow-up (Y) | AF5: Safeguarding referral made (Y) | AG5: Recommendation | AH5: English support level | AI5: Date decision confirmed | AJ5: Date family told | AK5: Date result and report given | AL5: Notes (no sensitive detail) | AM5: Age at assessment (months) | AN5: Reading age minus age (months) | AO5: Days from assessment to family told | AP5: Data check
A6: D01-001 | B6: Demo candidate Y01-01 | C6: 44221 | D6: Demo Bilingual School | E6: N | F6: 46276 | G6: 46310 | H6: EF | I6: v3.1 | J6: Enrolled | K6: 3 | L6: B | M6: B | N6: Pink | P6: B | Q6: 0 | R6: =IF(Q6="","",IF(Q6=0,"below 5:00",IF(Q6>=66,"16:00 or above",INT((60+2*Q6)/12)&":"&TEXT(MOD(60+2*Q6,12),"00")))) -> below 5:00 | S6: D | T6: 4 | U6: A | V6: B | W6: 7 | X6: 2 | Y6: 1 | AC6: 2 | AG6: Offer with English support | AH6: Timetabled support lessons | AI6: 46314 | AJ6: 46316 | AK6: 46316 | AM6: =IF(OR(C6="",G6=""),"",IFERROR(DATEDIF(C6,G6,"m"),"")) -> 68 | AN6: =IF(OR(Q6="",AM6=""),"",60+2*Q6-AM6) -> -8 | AO6: =IF(OR(G6="",AJ6=""),"",AJ6-G6) -> 6 | AP6: =IF(AND(A6="",B6=""),"",IF(J6="","Status needed",IF(OR(J6="Applied",J6="Visit booked",J6="Withdrawn"),"OK",IF(G6="","Date assessed needed",IF(C6="","Date of birth needed",IF(COUNTA(L6,M6,P6,U6,V6,X6)<6,"Band missing",IF(AND(OR(J6="Decision confirmed",J6="Family told",J6="Enrolled"),AG6=""),"Recommendation needed",IF(AND(OR(J6="Family told",J6="Enrolled"),AJ6=""),"Date family told needed","OK")))))))) -> OK
A7: D01-002 | B7: Demo candidate Y01-02 | C7: 44150 | D7: Demo International Kindergarten | E7: N | F7: 46263 | G7: 46276 | H7: EF | I7: v3.1 | J7: Decision confirmed | K7: 5 | L7: C | M7: C | N7: Red | P7: C | Q7: 11 | R7: =IF(Q7="","",IF(Q7=0,"below 5:00",IF(Q7>=66,"16:00 or above",INT((60+2*Q7)/12)&":"&TEXT(MOD(60+2*Q7,12),"00")))) -> 6:10 | S7: E | T7: 9 | U7: C | V7: C | W7: 11 | X7: 3 | Y7: 2 | AC7: 2 | AG7: Offer with English support | AH7: In-class support and monitoring | AI7: 46282 | AM7: =IF(OR(C7="",G7=""),"",IFERROR(DATEDIF(C7,G7,"m"),"")) -> 69 | AN7: =IF(OR(Q7="",AM7=""),"",60+2*Q7-AM7) -> 13 | AO7: =IF(OR(G7="",AJ7=""),"",AJ7-G7) | AP7: =IF(AND(A7="",B7=""),"",IF(J7="","Status needed",IF(OR(J7="Applied",J7="Visit booked",J7="Withdrawn"),"OK",IF(G7="","Date assessed needed",IF(C7="","Date of birth needed",IF(COUNTA(L7,M7,P7,U7,V7,X7)<6,"Band missing",IF(AND(OR(J7="Decision confirmed",J7="Family told",J7="Enrolled"),AG7=""),"Recommendation needed",IF(AND(OR(J7="Family told",J7="Enrolled"),AJ7=""),"Date family told needed","OK")))))))) -> OK
A8: D01-003 | B8: Demo candidate Y01-03 | C8: 44350 | D8: Demo Local Primary | E8: N | F8: 46273 | G8: 46307 | H8: EF | I8: v3.1 | J8: Enrolled | K8: 2 | L8: A | M8: A | N8: Not yet Pink | P8: A | Q8: 0 | R8: =IF(Q8="","",IF(Q8=0,"below 5:00",IF(Q8>=66,"16:00 or above",INT((60+2*Q8)/12)&":"&TEXT(MOD(60+2*Q8,12),"00")))) -> below 5:00 | S8: E | T8: 3 | U8: A | V8: A | W8: 9 | X8: 3 | Y8: 2 | AC8: 2 | AG8: Offer with English support | AH8: Intensive (new to English) | AI8: 46312 | AJ8: 46314 | AK8: 46314 | AM8: =IF(OR(C8="",G8=""),"",IFERROR(DATEDIF(C8,G8,"m"),"")) -> 64 | AN8: =IF(OR(Q8="",AM8=""),"",60+2*Q8-AM8) -> -4 | AO8: =IF(OR(G8="",AJ8=""),"",AJ8-G8) -> 7 | AP8: =IF(AND(A8="",B8=""),"",IF(J8="","Status needed",IF(OR(J8="Applied",J8="Visit booked",J8="Withdrawn"),"OK",IF(G8="","Date assessed needed",IF(C8="","Date of birth needed",IF(COUNTA(L8,M8,P8,U8,V8,X8)<6,"Band missing",IF(AND(OR(J8="Decision confirmed",J8="Family told",J8="Enrolled"),AG8=""),"Recommendation needed",IF(AND(OR(J8="Family told",J8="Enrolled"),AJ8=""),"Date family told needed","OK")))))))) -> OK
A9: D01-004 | B9: Demo candidate Y01-04 | C9: 44190 | D9: Demo International Kindergarten | E9: Y | F9: 46270 | G9: 46297 | H9: EF | I9: v3.1 | J9: Family told | K9: 5 | L9: C | M9: D | N9: Red | P9: C | Q9: 17 | R9: =IF(Q9="","",IF(Q9=0,"below 5:00",IF(Q9>=66,"16:00 or above",INT((60+2*Q9)/12)&":"&TEXT(MOD(60+2*Q9,12),"00")))) -> 7:10 | S9: E | T9: 7 | U9: C | V9: C | W9: 7 | X9: 2 | Y9: 2 | AC9: 3 | AD9: Y | AG9: Offer with English support | AH9: In-class support and monitoring | AI9: 46302 | AJ9: 46306 | AK9: 46306 | AM9: =IF(OR(C9="",G9=""),"",IFERROR(DATEDIF(C9,G9,"m"),"")) -> 69 | AN9: =IF(OR(Q9="",AM9=""),"",60+2*Q9-AM9) -> 25 | AO9: =IF(OR(G9="",AJ9=""),"",AJ9-G9) -> 9 | AP9: =IF(AND(A9="",B9=""),"",IF(J9="","Status needed",IF(OR(J9="Applied",J9="Visit booked",J9="Withdrawn"),"OK",IF(G9="","Date assessed needed",IF(C9="","Date of birth needed",IF(COUNTA(L9,M9,P9,U9,V9,X9)<6,"Band missing",IF(AND(OR(J9="Decision confirmed",J9="Family told",J9="Enrolled"),AG9=""),"Recommendation needed",IF(AND(OR(J9="Family told",J9="Enrolled"),AJ9=""),"Date family told needed","OK")))))))) -> OK
A10: D01-005 | B10: Demo candidate Y01-05 | C10: 44202 | D10: Demo Local Primary | E10: N | F10: 46297 | G10: 46307 | H10: CD | I10: v3.1 | J10: Family told | K10: 4 | L10: B | M10: C | N10: Red | P10: C | Q10: 6 | R10: =IF(Q10="","",IF(Q10=0,"below 5:00",IF(Q10>=66,"16:00 or above",INT((60+2*Q10)/12)&":"&TEXT(MOD(60+2*Q10,12),"00")))) -> 6:00 | S10: E | T10: 9 | U10: C | V10: C | W10: 4 | X10: 1 | Y10: 0 | AC10: 1 | AG10: Further assessment before a decision | AI10: 46312 | AJ10: 46315 | AK10: 46315 | AL10: Demo note: parents asked about the boarding timetable. | AM10: =IF(OR(C10="",G10=""),"",IFERROR(DATEDIF(C10,G10,"m"),"")) -> 69 | AN10: =IF(OR(Q10="",AM10=""),"",60+2*Q10-AM10) -> 3 | AO10: =IF(OR(G10="",AJ10=""),"",AJ10-G10) -> 8 | AP10: =IF(AND(A10="",B10=""),"",IF(J10="","Status needed",IF(OR(J10="Applied",J10="Visit booked",J10="Withdrawn"),"OK",IF(G10="","Date assessed needed",IF(C10="","Date of birth needed",IF(COUNTA(L10,M10,P10,U10,V10,X10)<6,"Band missing",IF(AND(OR(J10="Decision confirmed",J10="Family told",J10="Enrolled"),AG10=""),"Recommendation needed",IF(AND(OR(J10="Family told",J10="Enrolled"),AJ10=""),"Date family told needed","OK")))))))) -> OK
A11: D01-006 | B11: Demo candidate Y01-06 | C11: 44104 | D11: Demo Bilingual School | E11: N | F11: 46294 | I11: v3.1 | J11: Applied | R11: =IF(Q11="","",IF(Q11=0,"below 5:00",IF(Q11>=66,"16:00 or above",INT((60+2*Q11)/12)&":"&TEXT(MOD(60+2*Q11,12),"00")))) | AM11: =IF(OR(C11="",G11=""),"",IFERROR(DATEDIF(C11,G11,"m"),"")) | AN11: =IF(OR(Q11="",AM11=""),"",60+2*Q11-AM11) | AO11: =IF(OR(G11="",AJ11=""),"",AJ11-G11) | AP11: =IF(AND(A11="",B11=""),"",IF(J11="","Status needed",IF(OR(J11="Applied",J11="Visit booked",J11="Withdrawn"),"OK",IF(G11="","Date assessed needed",IF(C11="","Date of birth needed",IF(COUNTA(L11,M11,P11,U11,V11,X11)<6,"Band missing",IF(AND(OR(J11="Decision confirmed",J11="Family told",J11="Enrolled"),AG11=""),"Recommendation needed",IF(AND(OR(J11="Family told",J11="Enrolled"),AJ11=""),"Date family told needed","OK")))))))) -> OK
R12: =IF(Q12="","",IF(Q12=0,"below 5:00",IF(Q12>=66,"16:00 or above",INT((60+2*Q12)/12)&":"&TEXT(MOD(60+2*Q12,12),"00")))) | AM12: =IF(OR(C12="",G12=""),"",IFERROR(DATEDIF(C12,G12,"m"),"")) | AN12: =IF(OR(Q12="",AM12=""),"",60+2*Q12-AM12) | AO12: =IF(OR(G12="",AJ12=""),"",AJ12-G12) | AP12: =IF(AND(A12="",B12=""),"",IF(J12="","Status needed",IF(OR(J12="Applied",J12="Visit booked",J12="Withdrawn"),"OK",IF(G12="","Date assessed needed",IF(C12="","Date of birth needed",IF(COUNTA(L12,M12,P12,U12,V12,X12)<6,"Band missing",IF(AND(OR(J12="Decision confirmed",J12="Family told",J12="Enrolled"),AG12=""),"Recommendation needed",IF(AND(OR(J12="Family told",J12="Enrolled"),AJ12=""),"Date family told needed","OK"))))))))
R13: =IF(Q13="","",IF(Q13=0,"below 5:00",IF(Q13>=66,"16:00 or above",INT((60+2*Q13)/12)&":"&TEXT(MOD(60+2*Q13,12),"00")))) | AM13: =IF(OR(C13="",G13=""),"",IFERROR(DATEDIF(C13,G13,"m"),"")) | AN13: =IF(OR(Q13="",AM13=""),"",60+2*Q13-AM13) | AO13: =IF(OR(G13="",AJ13=""),"",AJ13-G13) | AP13: =IF(AND(A13="",B13=""),"",IF(J13="","Status needed",IF(OR(J13="Applied",J13="Visit booked",J13="Withdrawn"),"OK",IF(G13="","Date assessed needed",IF(C13="","Date of birth needed",IF(COUNTA(L13,M13,P13,U13,V13,X13)<6,"Band missing",IF(AND(OR(J13="Decision confirmed",J13="Family told",J13="Enrolled"),AG13=""),"Recommendation needed",IF(AND(OR(J13="Family told",J13="Enrolled"),AJ13=""),"Date family told needed","OK"))))))))
R14: =IF(Q14="","",IF(Q14=0,"below 5:00",IF(Q14>=66,"16:00 or above",INT((60+2*Q14)/12)&":"&TEXT(MOD(60+2*Q14,12),"00")))) | AM14: =IF(OR(C14="",G14=""),"",IFERROR(DATEDIF(C14,G14,"m"),"")) | AN14: =IF(OR(Q14="",AM14=""),"",60+2*Q14-AM14) | AO14: =IF(OR(G14="",AJ14=""),"",AJ14-G14) | AP14: =IF(AND(A14="",B14=""),"",IF(J14="","Status needed",IF(OR(J14="Applied",J14="Visit booked",J14="Withdrawn"),"OK",IF(G14="","Date assessed needed",IF(C14="","Date of birth needed",IF(COUNTA(L14,M14,P14,U14,V14,X14)<6,"Band missing",IF(AND(OR(J14="Decision confirmed",J14="Family told",J14="Enrolled"),AG14=""),"Recommendation needed",IF(AND(OR(J14="Family told",J14="Enrolled"),AJ14=""),"Date family told needed","OK"))))))))
